Workbook

Sheet Cover
A1: Rewards & Benefits Analytics Dashboard
A2: McKinsey-style executive view using live formulas, pivots, and all employee records.
A4: CONTENTS | B4: DESCRIPTION
A5: Rewards Dashboard | B5: Interactive executive dashboard with filters, KPI cards, charts, benchmarking table, and narrative insights.
A6: Employee Data | B6: Source employee table used for the live dashboard calculations.
A7: Rewards & Benefits Allocation | B7: Existing pivot allocation view used as a validation source for premium and high-cost totals.
A8: Gender Pay Equity | B8: Existing gender pay pivot analysis referenced in the pay-gap visualization.
A9: Basic Analysis | B9: Existing pivot-table workbook analysis supporting the dashboard.
A10: Dashboard Data | B10: Hidden helper sheet with live formulas feeding dashboard charts.

Sheet Rewards Dashboard
A1: Rewards operations dashboard
A2: Interactive rewards, benefits, pay equity and benchmarking view — change filters to refresh KPIs, charts and table.
A3: Location | B3: All | C3: Gender | D3: All | E3: Department | F3: All | H3: Source: Demo Data created with 492 rows | J3: Source: Demo Data created with 492 rows
A5: Headcount | D5: Avg salary | G5: Total premium | J5: High-cost %
A6: =GETPIVOTDATA("[Measures].[Headcount]",#REF!) -> #REF! | D6: =GETPIVOTDATA("[Measures].[Average Salary]",#REF!) -> #REF! | G6: =GETPIVOTDATA("[Measures].[Total Monthly Premium Cost]",#REF!) -> #REF! | J6: =GETPIVOTDATA("[Measures].[High-Cost Employee %]",#REF!) -> #REF!
A10: AVG PREMIUM BY DEPARTMENT X LOCATION | H10: PLAN MIX BY TIER
A27: HEADCOUNT BY DEPARTMENT | H27: GENDER PAY GAP BY SALARY BAND
A44: BENCHMARKING SUBMISSION VIEW
A45: Department | B45: Location | C45: Avg salary | D45: Avg premium | E45: Headcount | F45: High-cost % | H45: Story in brief: High-cost employees are defined as employees with monthly premiums over ₹7,000. Under this threshold, high-premium benefit combinations are the main cost concentration. Use the filters above to isolate a city, gender, or department; every KPI, chart and benchmarking row recalculates from the employee-level source table.
A46: ='Helper Sheet'!H50 -> #NAME? | B46: ='Helper Sheet'!I50 -> #NAME? | C46: ='Helper Sheet'!J50 -> #NAME? | D46: ='Helper Sheet'!K50 -> #NAME? | E46: ='Helper Sheet'!L50 -> #NAME? | F46: ='Helper Sheet'!M50 -> #NAME?
A47: ='Helper Sheet'!H51 -> #NAME? | B47: ='Helper Sheet'!I51 -> #NAME? | C47: ='Helper Sheet'!J51 -> #NAME? | D47: ='Helper Sheet'!K51 -> #NAME? | E47: ='Helper Sheet'!L51 -> #NAME? | F47: ='Helper Sheet'!M51 -> #NAME?
A48: ='Helper Sheet'!H52 -> #NAME? | B48: ='Helper Sheet'!I52 -> #NAME? | C48: ='Helper Sheet'!J52 -> #NAME? | D48: ='Helper Sheet'!K52 -> #NAME? | E48: ='Helper Sheet'!L52 -> #NAME? | F48: ='Helper Sheet'!M52 -> #NAME?
A49: ='Helper Sheet'!H53 -> #NAME? | B49: ='Helper Sheet'!I53 -> #NAME? | C49: ='Helper Sheet'!J53 -> #NAME? | D49: ='Helper Sheet'!K53 -> #NAME? | E49: ='Helper Sheet'!L53 -> #NAME? | F49: ='Helper Sheet'!M53 -> #NAME?
A50: ='Helper Sheet'!H54 -> #NAME? | B50: ='Helper Sheet'!I54 -> #NAME? | C50: ='Helper Sheet'!J54 -> #NAME? | D50: ='Helper Sheet'!K54 -> #NAME? | E50: ='Helper Sheet'!L54 -> #NAME? | F50: ='Helper Sheet'!M54 -> #NAME?
A51: ='Helper Sheet'!H55 -> #NAME? | B51: ='Helper Sheet'!I55 -> #NAME? | C51: ='Helper Sheet'!J55 -> #NAME? | D51: ='Helper Sheet'!K55 -> #NAME? | E51: ='Helper Sheet'!L55 -> #NAME? | F51: ='Helper Sheet'!M55 -> #NAME?
A56: RAW DATA TABLE
A57: Raw data table: the dashboard is powered by `Employee Data` rows with validated Location, Department, Gender, Insurance tier and Corporate Benefit Plan fields. The hidden `Dashboard Data` helper sheet holds live formulas that feed the charts; source records remain on the original data sheet.

Sheet Helper Sheet
A1: Locations | B1: Genders | C1: Departments | D1: Tiers | E1: Plans | F1: Salary Bands
A2: All | B2: All | C2: All | D2: Bronze | E2: Individual | F2: Junior
A3: Bengaluru | B3: Female | C3: Finance | D3: Silver | E3: Family Floater | F3: Mid
A4: Gurugram | B4: Male | C4: HR | D4: Gold | E4: Parents Included | F4: Senior
A5: Hyderabad | B5: Transgender | C5: Operations | F5: Lead
A6: Noida | C6: Sales
C7: Tech
A11: Department | B11: Bengaluru | C11: Gurugram | D11: Hyderabad | E11: Noida
A12: Finance | B12: =IF(OR('Rewards Dashboard'!$B$3="All",'Rewards Dashboard'!$B$3=B$11),IF(OR('Rewards Dashboard'!$F$3="All",'Rewards Dashboard'!$F$3=$A12),IFERROR(AVERAGEIFS('Employee Data'!$I$2:$I$493,'Employee Data'!$D$2:$D$493,$A12,'Employee Data'!$E$2:$E$493,B$11,'Employee Data'!$C$2:$C$493,IF('Rewards Dashboard'!$D$3="All","*",'Rewards Dashboard'!$D$3)),NA()),NA()),NA()) -> 4927.2727 | C12: =IF(OR('Rewards Dashboard'!$B$3="All",'Rewards Dashboard'!$B$3=C$11),IF(OR('Rewards Dashboard'!$F$3="All",'Rewards Dashboard'!$F$3=$A12),IFERROR(AVERAGEIFS('Employee Data'!$I$2:$I$493,'Employee Data'!$D$2:$D$493,$A12,'Employee Data'!$E$2:$E$493,C$11,'Employee Data'!$C$2:$C$493,IF('Rewards Dashboard'!$D$3="All","*",'Rewards Dashboard'!$D$3)),NA()),NA()),NA()) -> 5190.9091 | D12: =IF(OR('Rewards Dashboard'!$B$3="All",'Rewards Dashboard'!$B$3=D$11),IF(OR('Rewards Dashboard'!$F$3="All",'Rewards Dashboard'!$F$3=$A12),IFERROR(AVERAGEIFS('Employee Data'!$I$2:$I$493,'Employee Data'!$D$2:$D$493,$A12,'Employee Data'!$E$2:$E$493,D$11,'Employee Data'!$C$2:$C$493,IF('Rewards Dashboard'!$D$3="All","*",'Rewards Dashboard'!$D$3)),NA()),NA()),NA()) -> 5944.8276 | E12: =IF(OR('Rewards Dashboard'!$B$3="All",'Rewards Dashboard'!$B$3=E$11),IF(OR('Rewards Dashboard'!$F$3="All",'Rewards Dashboard'!$F$3=$A12),IFERROR(AVERAGEIFS('Employee Data'!$I$2:$I$493,'Employee Data'!$D$2:$D$493,$A12,'Employee Data'!$E$2:$E$493,E$11,'Employee Data'!$C$2:$C$493,IF('Rewards Dashboard'!$D$3="All","*",'Rewards Dashboard'!$D$3)),NA()),NA()),NA()) -> 5785.4167
A13: HR | B13: =IF(OR('Rewards Dashboard'!$B$3="All",'Rewards Dashboard'!$B$3=B$11),IF(OR('Rewards Dashboard'!$F$3="All",'Rewards Dashboard'!$F$3=$A13),IFERROR(AVERAGEIFS('Employee Data'!$I$2:$I$493,'Employee Data'!$D$2:$D$493,$A13,'Employee Data'!$E$2:$E$493,B$11,'Employee Data'!$C$2:$C$493,IF('Rewards Dashboard'!$D$3="All","*",'Rewards Dashboard'!$D$3)),NA()),NA()),NA()) -> 5489.4737 | C13: =IF(OR('Rewards Dashboard'!$B$3="All",'Rewards Dashboard'!$B$3=C$11),IF(OR('Rewards Dashboard'!$F$3="All",'Rewards Dashboard'!$F$3=$A13),IFERROR(AVERAGEIFS('Employee Data'!$I$2:$I$493,'Employee Data'!$D$2:$D$493,$A13,'Employee Data'!$E$2:$E$493,C$11,'Employee Data'!$C$2:$C$493,IF('Rewards Dashboard'!$D$3="All","*",'Rewards Dashboard'!$D$3)),NA()),NA()),NA()) -> 5064.2857 | D13: =IF(OR('Rewards Dashboard'!$B$3="All",'Rewards Dashboard'!$B$3=D$11),IF(OR('Rewards Dashboard'!$F$3="All",'Rewards Dashboard'!$F$3=$A13),IFERROR(AVERAGEIFS('Employee Data'!$I$2:$I$493,'Employee Data'!$D$2:$D$493,$A13,'Employee Data'!$E$2:$E$493,D$11,'Employee Data'!$C$2:$C$493,IF('Rewards Dashboard'!$D$3="All","*",'Rewards Dashboard'!$D$3)),NA()),NA()),NA()) -> 4819.2308 | E13: =IF(OR('Rewards Dashboard'!$B$3="All",'Rewards Dashboard'!$B$3=E$11),IF(OR('Rewards Dashboard'!$F$3="All",'Rewards Dashboard'!$F$3=$A13),IFERROR(AVERAGEIFS('Employee Data'!$I$2:$I$493,'Employee Data'!$D$2:$D$493,$A13,'Employee Data'!$E$2:$E$493,E$11,'Employee Data'!$C$2:$C$493,IF('Rewards Dashboard'!$D$3="All","*",'Rewards Dashboard'!$D$3)),NA()),NA()),NA()) -> 4577.2727
A14: Operations | B14: =IF(OR('Rewards Dashboard'!$B$3="All",'Rewards Dashboard'!$B$3=B$11),IF(OR('Rewards Dashboard'!$F$3="All",'Rewards Dashboard'!$F$3=$A14),IFERROR(AVERAGEIFS('Employee Data'!$I$2:$I$493,'Employee Data'!$D$2:$D$493,$A14,'Employee Data'!$E$2:$E$493,B$11,'Employee Data'!$C$2:$C$493,IF('Rewards Dashboard'!$D$3="All","*",'Rewards Dashboard'!$D$3)),NA()),NA()),NA()) -> 4192.1053 | C14: =IF(OR('Rewards Dashboard'!$B$3="All",'Rewards Dashboard'!$B$3=C$11),IF(OR('Rewards Dashboard'!$F$3="All",'Rewards Dashboard'!$F$3=$A14),IFERROR(AVERAGEIFS('Employee Data'!$I$2:$I$493,'Employee Data'!$D$2:$D$493,$A14,'Employee Data'!$E$2:$E$493,C$11,'Employee Data'!$C$2:$C$493,IF('Rewards Dashboard'!$D$3="All","*",'Rewards Dashboard'!$D$3)),NA()),NA()),NA()) -> 5490.7407 | D14: =IF(OR('Rewards Dashboard'!$B$3="All",'Rewards Dashboard'!$B$3=D$11),IF(OR('Rewards Dashboard'!$F$3="All",'Rewards Dashboard'!$F$3=$A14),IFERROR(AVERAGEIFS('Employee Data'!$I$2:$I$493,'Employee Data'!$D$2:$D$493,$A14,'Employee Data'!$E$2:$E$493,D$11,'Employee Data'!$C$2:$C$493,IF('Rewards Dashboard'!$D$3="All","*",'Rewards Dashboard'!$D$3)),NA()),NA()),NA()) -> 5475 | E14: =IF(OR('Rewards Dashboard'!$B$3="All",'Rewards Dashboard'!$B$3=E$11),IF(OR('Rewards Dashboard'!$F$3="All",'Rewards Dashboard'!$F$3=$A14),IFERROR(AVERAGEIFS('Employee Data'!$I$2:$I$493,'Employee Data'!$D$2:$D$493,$A14,'Employee Data'!$E$2:$E$493,E$11,'Employee Data'!$C$2:$C$493,IF('Rewards Dashboard'!$D$3="All","*",'Rewards Dashboard'!$D$3)),NA()),NA()),NA()) -> 5140
A15: Sales | B15: =IF(OR('Rewards Dashboard'!$B$3="All",'Rewards Dashboard'!$B$3=B$11),IF(OR('Rewards Dashboard'!$F$3="All",'Rewards Dashboard'!$F$3=$A15),IFERROR(AVERAGEIFS('Employee Data'!$I$2:$I$493,'Employee Data'!$D$2:$D$493,$A15,'Employee Data'!$E$2:$E$493,B$11,'Employee Data'!$C$2:$C$493,IF('Rewards Dashboard'!$D$3="All","*",'Rewards Dashboard'!$D$3)),NA()),NA()),NA()) -> 5430 | C15: =IF(OR('Rewards Dashboard'!$B$3="All",'Rewards Dashboard'!$B$3=C$11),IF(OR('Rewards Dashboard'!$F$3="All",'Rewards Dashboard'!$F$3=$A15),IFERROR(AVERAGEIFS('Employee Data'!$I$2:$I$493,'Employee Data'!$D$2:$D$493,$A15,'Employee Data'!$E$2:$E$493,C$11,'Employee Data'!$C$2:$C$493,IF('Rewards Dashboard'!$D$3="All","*",'Rewards Dashboard'!$D$3)),NA()),NA()),NA()) -> 6062 | D15: =IF(OR('Rewards Dashboard'!$B$3="All",'Rewards Dashboard'!$B$3=D$11),IF(OR('Rewards Dashboard'!$F$3="All",'Rewards Dashboard'!$F$3=$A15),IFERROR(AVERAGEIFS('Employee Data'!$I$2:$I$493,'Employee Data'!$D$2:$D$493,$A15,'Employee Data'!$E$2:$E$493,D$11,'Employee Data'!$C$2:$C$493,IF('Rewards Dashboard'!$D$3="All","*",'Rewards Dashboard'!$D$3)),NA()),NA()),NA()) -> 5268.5714 | E15: =IF(OR('Rewards Dashboard'!$B$3="All",'Rewards Dashboard'!$B$3=E$11),IF(OR('Rewards Dashboard'!$F$3="All",'Rewards Dashboard'!$F$3=$A15),IFERROR(AVERAGEIFS('Employee Data'!$I$2:$I$493,'Employee Data'!$D$2:$D$493,$A15,'Employee Data'!$E$2:$E$493,E$11,'Employee Data'!$C$2:$C$493,IF('Rewards Dashboard'!$D$3="All","*",'Rewards Dashboard'!$D$3)),NA()),NA()),NA()) -> 5293.75
A16: Tech | B16: =IF(OR('Rewards Dashboard'!$B$3="All",'Rewards Dashboard'!$B$3=B$11),IF(OR('Rewards Dashboard'!$F$3="All",'Rewards Dashboard'!$F$3=$A16),IFERROR(AVERAGEIFS('Employee Data'!$I$2:$I$493,'Employee Data'!$D$2:$D$493,$A16,'Employee Data'!$E$2:$E$493,B$11,'Employee Data'!$C$2:$C$493,IF('Rewards Dashboard'!$D$3="All","*",'Rewards Dashboard'!$D$3)),NA()),NA()),NA()) -> 5174 | C16: =IF(OR('Rewards Dashboard'!$B$3="All",'Rewards Dashboard'!$B$3=C$11),IF(OR('Rewards Dashboard'!$F$3="All",'Rewards Dashboard'!$F$3=$A16),IFERROR(AVERAGEIFS('Employee Data'!$I$2:$I$493,'Employee Data'!$D$2:$D$493,$A16,'Employee Data'!$E$2:$E$493,C$11,'Employee Data'!$C$2:$C$493,IF('Rewards Dashboard'!$D$3="All","*",'Rewards Dashboard'!$D$3)),NA()),NA()),NA()) -> 5066 | D16: =IF(OR('Rewards Dashboard'!$B$3="All",'Rewards Dashboard'!$B$3=D$11),IF(OR('Rewards Dashboard'!$F$3="All",'Rewards Dashboard'!$F$3=$A16),IFERROR(AVERAGEIFS('Employee Data'!$I$2:$I$493,'Employee Data'!$D$2:$D$493,$A16,'Employee Data'!$E$2:$E$493,D$11,'Employee Data'!$C$2:$C$493,IF('Rewards Dashboard'!$D$3="All","*",'Rewards Dashboard'!$D$3)),NA()),NA()),NA()) -> 4591.6667 | E16: =IF(OR('Rewards Dashboard'!$B$3="All",'Rewards Dashboard'!$B$3=E$11),IF(OR('Rewards Dashboard'!$F$3="All",'Rewards Dashboard'!$F$3=$A16),IFERROR(AVERAGEIFS('Employee Data'!$I$2:$I$493,'Employee Data'!$D$2:$D$493,$A16,'Employee Data'!$E$2:$E$493,E$11,'Employee Data'!$C$2:$C$493,IF('Rewards Dashboard'!$D$3="All","*",'Rewards Dashboard'!$D$3)),NA()),NA()),NA()) -> 5511.1111
A21: Insurance tier | B21: Headcount
A22: Bronze | B22: {=SUMPRODUCT(--('Employee Data'!$A$2:$A$493<>""),--(('Rewards Dashboard'!$B$3="All")+('Employee Data'!$E$2:$E$493='Rewards Dashboard'!$B$3)>0),--(('Rewards Dashboard'!$D$3="All")+('Employee Data'!$C$2:$C$493='Rewards Dashboard'!$D$3)>0),--(('Rewards Dashboard'!$F$3="All")+('Employee Data'!$D$2:$D$493='Rewards Dashboard'!$F$3)>0),--('Employee Data'!$H$2:$H$493=A22))} -> 59
A23: Silver | B23: {=SUMPRODUCT(--('Employee Data'!$A$2:$A$493<>""),--(('Rewards Dashboard'!$B$3="All")+('Employee Data'!$E$2:$E$493='Rewards Dashboard'!$B$3)>0),--(('Rewards Dashboard'!$D$3="All")+('Employee Data'!$C$2:$C$493='Rewards Dashboard'!$D$3)>0),--(('Rewards Dashboard'!$F$3="All")+('Employee Data'!$D$2:$D$493='Rewards Dashboard'!$F$3)>0),--('Employee Data'!$H$2:$H$493=A23))} -> 217
A24: Gold | B24: {=SUMPRODUCT(--('Employee Data'!$A$2:$A$493<>""),--(('Rewards Dashboard'!$B$3="All")+('Employee Data'!$E$2:$E$493='Rewards Dashboard'!$B$3)>0),--(('Rewards Dashboard'!$D$3="All")+('Employee Data'!$C$2:$C$493='Rewards Dashboard'!$D$3)>0),--(('Rewards Dashboard'!$F$3="All")+('Employee Data'!$D$2:$D$493='Rewards Dashboard'!$F$3)>0),--('Employee Data'!$H$2:$H$493=A24))} -> 216
A29: Department | B29: Headcount
A30: Finance | B30: {=IF(OR('Rewards Dashboard'!$F$3="All",'Rewards Dashboard'!$F$3=A30),SUMPRODUCT(--('Employee Data'!$A$2:$A$493<>""),--(('Rewards Dashboard'!$B$3="All")+('Employee Data'!$E$2:$E$493='Rewards Dashboard'!$B$3)>0),--(('Rewards Dashboard'!$D$3="All")+('Employee Data'!$C$2:$C$493='Rewards Dashboard'!$D$3)>0),--('Employee Data'!$D$2:$D$493=A30)),NA())} -> 97
A31: HR | B31: {=IF(OR('Rewards Dashboard'!$F$3="All",'Rewards Dashboard'!$F$3=A31),SUMPRODUCT(--('Employee Data'!$A$2:$A$493<>""),--(('Rewards Dashboard'!$B$3="All")+('Employee Data'!$E$2:$E$493='Rewards Dashboard'!$B$3)>0),--(('Rewards Dashboard'!$D$3="All")+('Employee Data'!$C$2:$C$493='Rewards Dashboard'!$D$3)>0),--('Employee Data'!$D$2:$D$493=A31)),NA())} -> 88
A32: Operations | B32: {=IF(OR('Rewards Dashboard'!$F$3="All",'Rewards Dashboard'!$F$3=A32),SUMPRODUCT(--('Employee Data'!$A$2:$A$493<>""),--(('Rewards Dashboard'!$B$3="All")+('Employee Data'!$E$2:$E$493='Rewards Dashboard'!$B$3)>0),--(('Rewards Dashboard'!$D$3="All")+('Employee Data'!$C$2:$C$493='Rewards Dashboard'!$D$3)>0),--('Employee Data'!$D$2:$D$493=A32)),NA())} -> 97
A33: Sales | B33: {=IF(OR('Rewards Dashboard'!$F$3="All",'Rewards Dashboard'!$F$3=A33),SUMPRODUCT(--('Employee Data'!$A$2:$A$493<>""),--(('Rewards Dashboard'!$B$3="All")+('Employee Data'!$E$2:$E$493='Rewards Dashboard'!$B$3)>0),--(('Rewards Dashboard'!$D$3="All")+('Employee Data'!$C$2:$C$493='Rewards Dashboard'!$D$3)>0),--('Employee Data'!$D$2:$D$493=A33)),NA())} -> 109
A34: Tech | B34: {=IF(OR('Rewards Dashboard'!$F$3="All",'Rewards Dashboard'!$F$3=A34),SUMPRODUCT(--('Employee Data'!$A$2:$A$493<>""),--(('Rewards Dashboard'!$B$3="All")+('Employee Data'!$E$2:$E$493='Rewards Dashboard'!$B$3)>0),--(('Rewards Dashboard'!$D$3="All")+('Employee Data'!$C$2:$C$493='Rewards Dashboard'!$D$3)>0),--('Employee Data'!$D$2:$D$493=A34)),NA())} -> 101
A39: Salary band | B39: Gap (M-F)
A40: =#REF! -> #REF! | B40: =#REF! -> #REF!
A41: =#REF! -> #REF! | B41: =#REF! -> #REF!
A42: =#REF! -> #REF! | B42: =#REF! -> #REF!
A43: =#REF! -> #REF! | B43: =#REF! -> #REF!
A49: Department | B49: Location | C49: Avg salary | D49: Avg premium | E49: Headcount | F49: High-cost % | H49: Department | I49: Location | J49: Avg salary | K49: Avg premium | L49: Headcount | M49: High-cost %
A50: Finance | B50: Bengaluru | C50: {=IFERROR(SUMPRODUCT('Employee Data'!$F$2:$F$493,--('Employee Data'!$A$2:$A$493<>""),--(('Rewards Dashboard'!$B$3="All")+('Employee Data'!$E$2:$E$493='Rewards Dashboard'!$B$3)>0),--(('Rewards Dashboard'!$D$3="All")+('Employee Data'!$C$2:$C$493='Rewards Dashboard'!$D$3)>0),--(('Rewards Dashboard'!$F$3="All")+('Employee Data'!$D$2:$D$493='Rewards Dashboard'!$F$3)>0),--('Employee Data'!$D$2:$D$493=A50),--('Employee Data'!$E$2:$E$493=B50))/SUMPRODUCT(--('Employee Data'!$A$2:$A$493<>""),--(('Rewards Dashboard'!$B$3="All")+('Employee Data'!$E$2:$E$493='Rewards Dashboard'!$B$3)>0),--(('Rewards Dashboard'!$D$3="All")+('Employee Data'!$C$2:$C$493='Rewards Dashboard'!$D$3)>0),--(('Rewards Dashboard'!$F$3="All")+('Employee Data'!$D$2:$D$493='Rewards Dashboard'!$F$3)>0),--('Employee Data'!$D$2:$D$493=A50),--('Employee Data'!$E$2:$E$493=B50)),0)} -> 121773.86 | D50: {=IFERROR(SUMPRODUCT('Employee Data'!$I$2:$I$493,--('Employee Data'!$A$2:$A$493<>""),--(('Rewards Dashboard'!$B$3="All")+('Employee Data'!$E$2:$E$493='Rewards Dashboard'!$B$3)>0),--(('Rewards Dashboard'!$D$3="All")+('Employee Data'!$C$2:$C$493='Rewards Dashboard'!$D$3)>0),--(('Rewards Dashboard'!$F$3="All")+('Employee Data'!$D$2:$D$493='Rewards Dashboard'!$F$3)>0),--('Employee Data'!$D$2:$D$493=A50),--('Employee Data'!$E$2:$E$493=B50))/SUMPRODUCT(--('Employee Data'!$A$2:$A$493<>""),--(('Rewards Dashboard'!$B$3="All")+('Employee Data'!$E$2:$E$493='Rewards Dashboard'!$B$3)>0),--(('Rewards Dashboard'!$D$3="All")+('Employee Data'!$C$2:$C$493='Rewards Dashboard'!$D$3)>0),--(('Rewards Dashboard'!$F$3="All")+('Employee Data'!$D$2:$D$493='Rewards Dashboard'!$F$3)>0),--('Employee Data'!$D$2:$D$493=A50),--('Employee Data'!$E$2:$E$493=B50)),0)} -> 4927.2727 | E50: {=SUMPRODUCT(--('Employee Data'!$A$2:$A$493<>""),--(('Rewards Dashboard'!$B$3="All")+('Employee Data'!$E$2:$E$493='Rewards Dashboard'!$B$3)>0),--(('Rewards Dashboard'!$D$3="All")+('Employee Data'!$C$2:$C$493='Rewards Dashboard'!$D$3)>0),--(('Rewards Dashboard'!$F$3="All")+('Employee Data'!$D$2:$D$493='Rewards Dashboard'!$F$3)>0),--('Employee Data'!$D$2:$D$493=A50),--('Employee Data'!$E$2:$E$493=B50))} -> 22 | F50: {=IFERROR(SUMPRODUCT(--('Employee Data'!$I$2:$I$493>7000),--('Employee Data'!$A$2:$A$493<>""),--(('Rewards Dashboard'!$B$3="All")+('Employee Data'!$E$2:$E$493='Rewards Dashboard'!$B$3)>0),--(('Rewards Dashboard'!$D$3="All")+('Employee Data'!$C$2:$C$493='Rewards Dashboard'!$D$3)>0),--(('Rewards Dashboard'!$F$3="All")+('Employee Data'!$D$2:$D$493='Rewards Dashboard'!$F$3)>0),--('Employee Data'!$D$2:$D$493=A50),--('Employee Data'!$E$2:$E$493=B50))/E50,0)} -> 0.18181818 | H50: {=_xlfn.take(_xlfn.sortby(_xlfn._xlws.filter($A$50:$F$69,$E$50:$E$69>0),_xlfn._xlws.filter($F$50:$F$69,$E$50:$E$69>0),-1,_xlfn._xlws.filter($D$50:$D$69,$E$50:$E$69>0),-1),6)} -> #NAME? | I50: #NAME? | J50: #NAME? | K50: #NAME? | L50: #NAME? | M50: #NAME?
A51: HR | B51: Bengaluru | C51: {=IFERROR(SUMPRODUCT('Employee Data'!$F$2:$F$493,--('Employee Data'!$A$2:$A$493<>""),--(('Rewards Dashboard'!$B$3="All")+('Employee Data'!$E$2:$E$493='Rewards Dashboard'!$B$3)>0),--(('Rewards Dashboard'!$D$3="All")+('Employee Data'!$C$2:$C$493='Rewards Dashboard'!$D$3)>0),--(('Rewards Dashboard'!$F$3="All")+('Employee Data'!$D$2:$D$493='Rewards Dashboard'!$F$3)>0),--('Employee Data'!$D$2:$D$493=A51),--('Employee Data'!$E$2:$E$493=B51))/SUMPRODUCT(--('Employee Data'!$A$2:$A$493<>""),--(('Rewards Dashboard'!$B$3="All")+('Employee Data'!$E$2:$E$493='Rewards Dashboard'!$B$3)>0),--(('Rewards Dashboard'!$D$3="All")+('Employee Data'!$C$2:$C$493='Rewards Dashboard'!$D$3)>0),--(('Rewards Dashboard'!$F$3="All")+('Employee Data'!$D$2:$D$493='Rewards Dashboard'!$F$3)>0),--('Employee Data'!$D$2:$D$493=A51),--('Employee Data'!$E$2:$E$493=B51)),0)} -> 137245.47 | D51: {=IFERROR(SUMPRODUCT('Employee Data'!$I$2:$I$493,--('Employee Data'!$A$2:$A$493<>""),--(('Rewards Dashboard'!$B$3="All")+('Employee Data'!$E$2:$E$493='Rewards Dashboard'!$B$3)>0),--(('Rewards Dashboard'!$D$3="All")+('Employee Data'!$C$2:$C$493='Rewards Dashboard'!$D$3)>0),--(('Rewards Dashboard'!$F$3="All")+('Employee Data'!$D$2:$D$493='Rewards Dashboard'!$F$3)>0),--('Employee Data'!$D$2:$D$493=A51),--('Employee Data'!$E$2:$E$493=B51))/SUMPRODUCT(--('Employee Data'!$A$2:$A$493<>""),--(('Rewards Dashboard'!$B$3="All")+('Employee Data'!$E$2:$E$493='Rewards Dashboard'!$B$3)>0),--(('Rewards Dashboard'!$D$3="All")+('Employee Data'!$C$2:$C$493='Rewards Dashboard'!$D$3)>0),--(('Rewards Dashboard'!$F$3="All")+('Employee Data'!$D$2:$D$493='Rewards Dashboard'!$F$3)>0),--('Employee Data'!$D$2:$D$493=A51),--('Employee Data'!$E$2:$E$493=B51)),0)} -> 5489.4737 | E51: {=SUMPRODUCT(--('Employee Data'!$A$2:$A$493<>""),--(('Rewards Dashboard'!$B$3="All")+('Employee Data'!$E$2:$E$493='Rewards Dashboard'!$B$3)>0),--(('Rewards Dashboard'!$D$3="All")+('Employee Data'!$C$2:$C$493='Rewards Dashboard'!$D$3)>0),--(('Rewards Dashboard'!$F$3="All")+('Employee Data'!$D$2:$D$493='Rewards Dashboard'!$F$3)>0),--('Employee Data'!$D$2:$D$493=A51),--('Employee Data'!$E$2:$E$493=B51))} -> 19 | F51: {=IFERROR(SUMPRODUCT(--('Employee Data'!$I$2:$I$493>7000),--('Employee Data'!$A$2:$A$493<>""),--(('Rewards Dashboard'!$B$3="All")+('Employee Data'!$E$2:$E$493='Rewards Dashboard'!$B$3)>0),--(('Rewards Dashboard'!$D$3="All")+('Employee Data'!$C$2:$C$493='Rewards Dashboard'!$D$3)>0),--(('Rewards Dashboard'!$F$3="All")+('Employee Data'!$D$2:$D$493='Rewards Dashboard'!$F$3)>0),--('Employee Data'!$D$2:$D$493=A51),--('Employee Data'!$E$2:$E$493=B51))/E51,0)} -> 0.26315789 | H51: #NAME? | I51: #NAME? | J51: #NAME? | K51: #NAME? | L51: #NAME? | M51: #NAME?
A52: Operations | B52: Bengaluru | C52: {=IFERROR(SUMPRODUCT('Employee Data'!$F$2:$F$493,--('Employee Data'!$A$2:$A$493<>""),--(('Rewards Dashboard'!$B$3="All")+('Employee Data'!$E$2:$E$493='Rewards Dashboard'!$B$3)>0),--(('Rewards Dashboard'!$D$3="All")+('Employee Data'!$C$2:$C$493='Rewards Dashboard'!$D$3)>0),--(('Rewards Dashboard'!$F$3="All")+('Employee Data'!$D$2:$D$493='Rewards Dashboard'!$F$3)>0),--('Employee Data'!$D$2:$D$493=A52),--('Employee Data'!$E$2:$E$493=B52))/SUMPRODUCT(--('Employee Data'!$A$2:$A$493<>""),--(('Rewards Dashboard'!$B$3="All")+('Employee Data'!$E$2:$E$493='Rewards Dashboard'!$B$3)>0),--(('Rewards Dashboard'!$D$3="All")+('Employee Data'!$C$2:$C$493='Rewards Dashboard'!$D$3)>0),--(('Rewards Dashboard'!$F$3="All")+('Employee Data'!$D$2:$D$493='Rewards Dashboard'!$F$3)>0),--('Employee Data'!$D$2:$D$493=A52),--('Employee Data'!$E$2:$E$493=B52)),0)} -> 148077.74 | D52: {=IFERROR(SUMPRODUCT('Employee Data'!$I$2:$I$493,--('Employee Data'!$A$2:$A$493<>""),--(('Rewards Dashboard'!$B$3="All")+('Employee Data'!$E$2:$E$493='Rewards Dashboard'!$B$3)>0),--(('Rewards Dashboard'!$D$3="All")+('Employee Data'!$C$2:$C$493='Rewards Dashboard'!$D$3)>0),--(('Rewards Dashboard'!$F$3="All")+('Employee Data'!$D$2:$D$493='Rewards Dashboard'!$F$3)>0),--('Employee Data'!$D$2:$D$493=A52),--('Employee Data'!$E$2:$E$493=B52))/SUMPRODUCT(--('Employee Data'!$A$2:$A$493<>""),--(('Rewards Dashboard'!$B$3="All")+('Employee Data'!$E$2:$E$493='Rewards Dashboard'!$B$3)>0),--(('Rewards Dashboard'!$D$3="All")+('Employee Data'!$C$2:$C$493='Rewards Dashboard'!$D$3)>0),--(('Rewards Dashboard'!$F$3="All")+('Employee Data'!$D$2:$D$493='Rewards Dashboard'!$F$3)>0),--('Employee Data'!$D$2:$D$493=A52),--('Employee Data'!$E$2:$E$493=B52)),0)} -> 4192.1053 | E52: {=SUMPRODUCT(--('Employee Data'!$A$2:$A$493<>""),--(('Rewards Dashboard'!$B$3="All")+('Employee Data'!$E$2:$E$493='Rewards Dashboard'!$B$3)>0),--(('Rewards Dashboard'!$D$3="All")+('Employee Data'!$C$2:$C$493='Rewards Dashboard'!$D$3)>0),--(('Rewards Dashboard'!$F$3="All")+('Employee Data'!$D$2:$D$493='Rewards Dashboard'!$F$3)>0),--('Employee Data'!$D$2:$D$493=A52),--('Employee Data'!$E$2:$E$493=B52))} -> 19 | F52: {=IFERROR(SUMPRODUCT(--('Employee Data'!$I$2:$I$493>7000),--('Employee Data'!$A$2:$A$493<>""),--(('Rewards Dashboard'!$B$3="All")+('Employee Data'!$E$2:$E$493='Rewards Dashboard'!$B$3)>0),--(('Rewards Dashboard'!$D$3="All")+('Employee Data'!$C$2:$C$493='Rewards Dashboard'!$D$3)>0),--(('Rewards Dashboard'!$F$3="All")+('Employee Data'!$D$2:$D$493='Rewards Dashboard'!$F$3)>0),--('Employee Data'!$D$2:$D$493=A52),--('Employee Data'!$E$2:$E$493=B52))/E52,0)} -> 0.21052632 | H52: #NAME? | I52: #NAME? | J52: #NAME? | K52: #NAME? | L52: #NAME? | M52: #NAME?
A53: Sales | B53: Bengaluru | C53: {=IFERROR(SUMPRODUCT('Employee Data'!$F$2:$F$493,--('Employee Data'!$A$2:$A$493<>""),--(('Rewards Dashboard'!$B$3="All")+('Employee Data'!$E$2:$E$493='Rewards Dashboard'!$B$3)>0),--(('Rewards Dashboard'!$D$3="All")+('Employee Data'!$C$2:$C$493='Rewards Dashboard'!$D$3)>0),--(('Rewards Dashboard'!$F$3="All")+('Employee Data'!$D$2:$D$493='Rewards Dashboard'!$F$3)>0),--('Employee Data'!$D$2:$D$493=A53),--('Employee Data'!$E$2:$E$493=B53))/SUMPRODUCT(--('Employee Data'!$A$2:$A$493<>""),--(('Rewards Dashboard'!$B$3="All")+('Employee Data'!$E$2:$E$493='Rewards Dashboard'!$B$3)>0),--(('Rewards Dashboard'!$D$3="All")+('Employee Data'!$C$2:$C$493='Rewards Dashboard'!$D$3)>0),--(('Rewards Dashboard'!$F$3="All")+('Employee Data'!$D$2:$D$493='Rewards Dashboard'!$F$3)>0),--('Employee Data'!$D$2:$D$493=A53),--('Employee Data'!$E$2:$E$493=B53)),0)} -> 125504.2 | D53: {=IFERROR(SUMPRODUCT('Employee Data'!$I$2:$I$493,--('Employee Data'!$A$2:$A$493<>""),--(('Rewards Dashboard'!$B$3="All")+('Employee Data'!$E$2:$E$493='Rewards Dashboard'!$B$3)>0),--(('Rewards Dashboard'!$D$3="All")+('Employee Data'!$C$2:$C$493='Rewards Dashboard'!$D$3)>0),--(('Rewards Dashboard'!$F$3="All")+('Employee Data'!$D$2:$D$493='Rewards Dashboard'!$F$3)>0),--('Employee Data'!$D$2:$D$493=A53),--('Employee Data'!$E$2:$E$493=B53))/SUMPRODUCT(--('Employee Data'!$A$2:$A$493<>""),--(('Rewards Dashboard'!$B$3="All")+('Employee Data'!$E$2:$E$493='Rewards Dashboard'!$B$3)>0),--(('Rewards Dashboard'!$D$3="All")+('Employee Data'!$C$2:$C$493='Rewards Dashboard'!$D$3)>0),--(('Rewards Dashboard'!$F$3="All")+('Employee Data'!$D$2:$D$493='Rewards Dashboard'!$F$3)>0),--('Employee Data'!$D$2:$D$493=A53),--('Employee Data'!$E$2:$E$493=B53)),0)} -> 5430 | E53: {=SUMPRODUCT(--('Employee Data'!$A$2:$A$493<>""),--(('Rewards Dashboard'!$B$3="All")+('Employee Data'!$E$2:$E$493='Rewards Dashboard'!$B$3)>0),--(('Rewards Dashboard'!$D$3="All")+('Employee Data'!$C$2:$C$493='Rewards Dashboard'!$D$3)>0),--(('Rewards Dashboard'!$F$3="All")+('Employee Data'!$D$2:$D$493='Rewards Dashboard'!$F$3)>0),--('Employee Data'!$D$2:$D$493=A53),--('Employee Data'!$E$2:$E$493=B53))} -> 25 | F53: {=IFERROR(SUMPRODUCT(--('Employee Data'!$I$2:$I$493>7000),--('Employee Data'!$A$2:$A$493<>""),--(('Rewards Dashboard'!$B$3="All")+('Employee Data'!$E$2:$E$493='Rewards Dashboard'!$B$3)>0),--(('Rewards Dashboard'!$D$3="All")+('Employee Data'!$C$2:$C$493='Rewards Dashboard'!$D$3)>0),--(('Rewards Dashboard'!$F$3="All")+('Employee Data'!$D$2:$D$493='Rewards Dashboard'!$F$3)>0),--('Employee Data'!$D$2:$D$493=A53),--('Employee Data'!$E$2:$E$493=B53))/E53,0)} -> 0.2 | H53: #NAME? | I53: #NAME? | J53: #NAME? | K53: #NAME? | L53: #NAME? | M53: #NAME?
A54: Tech | B54: Bengaluru | C54: {=IFERROR(SUMPRODUCT('Employee Data'!$F$2:$F$493,--('Employee Data'!$A$2:$A$493<>""),--(('Rewards Dashboard'!$B$3="All")+('Employee Data'!$E$2:$E$493='Rewards Dashboard'!$B$3)>0),--(('Rewards Dashboard'!$D$3="All")+('Employee Data'!$C$2:$C$493='Rewards Dashboard'!$D$3)>0),--(('Rewards Dashboard'!$F$3="All")+('Employee Data'!$D$2:$D$493='Rewards Dashboard'!$F$3)>0),--('Employee Data'!$D$2:$D$493=A54),--('Employee Data'!$E$2:$E$493=B54))/SUMPRODUCT(--('Employee Data'!$A$2:$A$493<>""),--(('Rewards Dashboard'!$B$3="All")+('Employee Data'!$E$2:$E$493='Rewards Dashboard'!$B$3)>0),--(('Rewards Dashboard'!$D$3="All")+('Employee Data'!$C$2:$C$493='Rewards Dashboard'!$D$3)>0),--(('Rewards Dashboard'!$F$3="All")+('Employee Data'!$D$2:$D$493='Rewards Dashboard'!$F$3)>0),--('Employee Data'!$D$2:$D$493=A54),--('Employee Data'!$E$2:$E$493=B54)),0)} -> 128991.12 | D54: {=IFERROR(SUMPRODUCT('Employee Data'!$I$2:$I$493,--('Employee Data'!$A$2:$A$493<>""),--(('Rewards Dashboard'!$B$3="All")+('Employee Data'!$E$2:$E$493='Rewards Dashboard'!$B$3)>0),--(('Rewards Dashboard'!$D$3="All")+('Employee Data'!$C$2:$C$493='Rewards Dashboard'!$D$3)>0),--(('Rewards Dashboard'!$F$3="All")+('Employee Data'!$D$2:$D$493='Rewards Dashboard'!$F$3)>0),--('Employee Data'!$D$2:$D$493=A54),--('Employee Data'!$E$2:$E$493=B54))/SUMPRODUCT(--('Employee Data'!$A$2:$A$493<>""),--(('Rewards Dashboard'!$B$3="All")+('Employee Data'!$E$2:$E$493='Rewards Dashboard'!$B$3)>0),--(('Rewards Dashboard'!$D$3="All")+('Employee Data'!$C$2:$C$493='Rewards Dashboard'!$D$3)>0),--(('Rewards Dashboard'!$F$3="All")+('Employee Data'!$D$2:$D$493='Rewards Dashboard'!$F$3)>0),--('Employee Data'!$D$2:$D$493=A54),--('Employee Data'!$E$2:$E$493=B54)),0)} -> 5174 | E54: {=SUMPRODUCT(--('Employee Data'!$A$2:$A$493<>""),--(('Rewards Dashboard'!$B$3="All")+('Employee Data'!$E$2:$E$493='Rewards Dashboard'!$B$3)>0),--(('Rewards Dashboard'!$D$3="All")+('Employee Data'!$C$2:$C$493='Rewards Dashboard'!$D$3)>0),--(('Rewards Dashboard'!$F$3="All")+('Employee Data'!$D$2:$D$493='Rewards Dashboard'!$F$3)>0),--('Employee Data'!$D$2:$D$493=A54),--('Employee Data'!$E$2:$E$493=B54))} -> 25 | F54: {=IFERROR(SUMPRODUCT(--('Employee Data'!$I$2:$I$493>7000),--('Employee Data'!$A$2:$A$493<>""),--(('Rewards Dashboard'!$B$3="All")+('Employee Data'!$E$2:$E$493='Rewards Dashboard'!$B$3)>0),--(('Rewards Dashboard'!$D$3="All")+('Employee Data'!$C$2:$C$493='Rewards Dashboard'!$D$3)>0),--(('Rewards Dashboard'!$F$3="All")+('Employee Data'!$D$2:$D$493='Rewards Dashboard'!$F$3)>0),--('Employee Data'!$D$2:$D$493=A54),--('Employee Data'!$E$2:$E$493=B54))/E54,0)} -> 0.16 | H54: #NAME? | I54: #NAME? | J54: #NAME? | K54: #NAME? | L54: #NAME? | M54: #NAME?
A55: Finance | B55: Gurugram | C55: {=IFERROR(SUMPRODUCT('Employee Data'!$F$2:$F$493,--('Employee Data'!$A$2:$A$493<>""),--(('Rewards Dashboard'!$B$3="All")+('Employee Data'!$E$2:$E$493='Rewards Dashboard'!$B$3)>0),--(('Rewards Dashboard'!$D$3="All")+('Employee Data'!$C$2:$C$493='Rewards Dashboard'!$D$3)>0),--(('Rewards Dashboard'!$F$3="All")+('Employee Data'!$D$2:$D$493='Rewards Dashboard'!$F$3)>0),--('Employee Data'!$D$2:$D$493=A55),--('Employee Data'!$E$2:$E$493=B55))/SUMPRODUCT(--('Employee Data'!$A$2:$A$493<>""),--(('Rewards Dashboard'!$B$3="All")+('Employee Data'!$E$2:$E$493='Rewards Dashboard'!$B$3)>0),--(('Rewards Dashboard'!$D$3="All")+('Employee Data'!$C$2:$C$493='Rewards Dashboard'!$D$3)>0),--(('Rewards Dashboard'!$F$3="All")+('Employee Data'!$D$2:$D$493='Rewards Dashboard'!$F$3)>0),--('Employee Data'!$D$2:$D$493=A55),--('Employee Data'!$E$2:$E$493=B55)),0)} -> 118022.5 | D55: {=IFERROR(SUMPRODUCT('Employee Data'!$I$2:$I$493,--('Employee Data'!$A$2:$A$493<>""),--(('Rewards Dashboard'!$B$3="All")+('Employee Data'!$E$2:$E$493='Rewards Dashboard'!$B$3)>0),--(('Rewards Dashboard'!$D$3="All")+('Employee Data'!$C$2:$C$493='Rewards Dashboard'!$D$3)>0),--(('Rewards Dashboard'!$F$3="All")+('Employee Data'!$D$2:$D$493='Rewards Dashboard'!$F$3)>0),--('Employee Data'!$D$2:$D$493=A55),--('Employee Data'!$E$2:$E$493=B55))/SUMPRODUCT(--('Employee Data'!$A$2:$A$493<>""),--(('Rewards Dashboard'!$B$3="All")+('Employee Data'!$E$2:$E$493='Rewards Dashboard'!$B$3)>0),--(('Rewards Dashboard'!$D$3="All")+('Employee Data'!$C$2:$C$493='Rewards Dashboard'!$D$3)>0),--(('Rewards Dashboard'!$F$3="All")+('Employee Data'!$D$2:$D$493='Rewards Dashboard'!$F$3)>0),--('Employee Data'!$D$2:$D$493=A55),--('Employee Data'!$E$2:$E$493=B55)),0)} -> 5190.9091 | E55: {=SUMPRODUCT(--('Employee Data'!$A$2:$A$493<>""),--(('Rewards Dashboard'!$B$3="All")+('Employee Data'!$E$2:$E$493='Rewards Dashboard'!$B$3)>0),--(('Rewards Dashboard'!$D$3="All")+('Employee Data'!$C$2:$C$493='Rewards Dashboard'!$D$3)>0),--(('Rewards Dashboard'!$F$3="All")+('Employee Data'!$D$2:$D$493='Rewards Dashboard'!$F$3)>0),--('Employee Data'!$D$2:$D$493=A55),--('Employee Data'!$E$2:$E$493=B55))} -> 22 | F55: {=IFERROR(SUMPRODUCT(--('Employee Data'!$I$2:$I$493>7000),--('Employee Data'!$A$2:$A$493<>""),--(('Rewards Dashboard'!$B$3="All")+('Employee Data'!$E$2:$E$493='Rewards Dashboard'!$B$3)>0),--(('Rewards Dashboard'!$D$3="All")+('Employee Data'!$C$2:$C$493='Rewards Dashboard'!$D$3)>0),--(('Rewards Dashboard'!$F$3="All")+('Employee Data'!$D$2:$D$493='Rewards Dashboard'!$F$3)>0),--('Employee Data'!$D$2:$D$493=A55),--('Employee Data'!$E$2:$E$493=B55))/E55,0)} -> 0.22727273 | H55: #NAME? | I55: #NAME? | J55: #NAME? | K55: #NAME? | L55: #NAME? | M55: #NAME?
A56: HR | B56: Gurugram | C56: {=IFERROR(SUMPRODUCT('Employee Data'!$F$2:$F$493,--('Employee Data'!$A$2:$A$493<>""),--(('Rewards Dashboard'!$B$3="All")+('Employee Data'!$E$2:$E$493='Rewards Dashboard'!$B$3)>0),--(('Rewards Dashboard'!$D$3="All")+('Employee Data'!$C$2:$C$493='Rewards Dashboard'!$D$3)>0),--(('Rewards Dashboard'!$F$3="All")+('Employee Data'!$D$2:$D$493='Rewards Dashboard'!$F$3)>0),--('Employee Data'!$D$2:$D$493=A56),--('Employee Data'!$E$2:$E$493=B56))/SUMPRODUCT(--('Employee Data'!$A$2:$A$493<>""),--(('Rewards Dashboard'!$B$3="All")+('Employee Data'!$E$2:$E$493='Rewards Dashboard'!$B$3)>0),--(('Rewards Dashboard'!$D$3="All")+('Employee Data'!$C$2:$C$493='Rewards Dashboard'!$D$3)>0),--(('Rewards Dashboard'!$F$3="All")+('Employee Data'!$D$2:$D$493='Rewards Dashboard'!$F$3)>0),--('Employee Data'!$D$2:$D$493=A56),--('Employee Data'!$E$2:$E$493=B56)),0)} -> 139907.29 | D56: {=IFERROR(SUMPRODUCT('Employee Data'!$I$2:$I$493,--('Employee Data'!$A$2:$A$493<>""),--(('Rewards Dashboard'!$B$3="All")+('Employee Data'!$E$2:$E$493='Rewards Dashboard'!$B$3)>0),--(('Rewards Dashboard'!$D$3="All")+('Employee Data'!$C$2:$C$493='Rewards Dashboard'!$D$3)>0),--(('Rewards Dashboard'!$F$3="All")+('Employee Data'!$D$2:$D$493='Rewards Dashboard'!$F$3)>0),--('Employee Data'!$D$2:$D$493=A56),--('Employee Data'!$E$2:$E$493=B56))/SUMPRODUCT(--('Employee Data'!$A$2:$A$493<>""),--(('Rewards Dashboard'!$B$3="All")+('Employee Data'!$E$2:$E$493='Rewards Dashboard'!$B$3)>0),--(('Rewards Dashboard'!$D$3="All")+('Employee Data'!$C$2:$C$493='Rewards Dashboard'!$D$3)>0),--(('Rewards Dashboard'!$F$3="All")+('Employee Data'!$D$2:$D$493='Rewards Dashboard'!$F$3)>0),--('Employee Data'!$D$2:$D$493=A56),--('Employee Data'!$E$2:$E$493=B56)),0)} -> 5064.2857 | E56: {=SUMPRODUCT(--('Employee Data'!$A$2:$A$493<>""),--(('Rewards Dashboard'!$B$3="All")+('Employee Data'!$E$2:$E$493='Rewards Dashboard'!$B$3)>0),--(('Rewards Dashboard'!$D$3="All")+('Employee Data'!$C$2:$C$493='Rewards Dashboard'!$D$3)>0),--(('Rewards Dashboard'!$F$3="All")+('Employee Data'!$D$2:$D$493='Rewards Dashboard'!$F$3)>0),--('Employee Data'!$D$2:$D$493=A56),--('Employee Data'!$E$2:$E$493=B56))} -> 21 | F56: {=IFERROR(SUMPRODUCT(--('Employee Data'!$I$2:$I$493>7000),--('Employee Data'!$A$2:$A$493<>""),--(('Rewards Dashboard'!$B$3="All")+('Employee Data'!$E$2:$E$493='Rewards Dashboard'!$B$3)>0),--(('Rewards Dashboard'!$D$3="All")+('Employee Data'!$C$2:$C$493='Rewards Dashboard'!$D$3)>0),--(('Rewards Dashboard'!$F$3="All")+('Employee Data'!$D$2:$D$493='Rewards Dashboard'!$F$3)>0),--('Employee Data'!$D$2:$D$493=A56),--('Employee Data'!$E$2:$E$493=B56))/E56,0)} -> 0.19047619
A57: Operations | B57: Gurugram | C57: {=IFERROR(SUMPRODUCT('Employee Data'!$F$2:$F$493,--('Employee Data'!$A$2:$A$493<>""),--(('Rewards Dashboard'!$B$3="All")+('Employee Data'!$E$2:$E$493='Rewards Dashboard'!$B$3)>0),--(('Rewards Dashboard'!$D$3="All")+('Employee Data'!$C$2:$C$493='Rewards Dashboard'!$D$3)>0),--(('Rewards Dashboard'!$F$3="All")+('Employee Data'!$D$2:$D$493='Rewards Dashboard'!$F$3)>0),--('Employee Data'!$D$2:$D$493=A57),--('Employee Data'!$E$2:$E$493=B57))/SUMPRODUCT(--('Employee Data'!$A$2:$A$493<>""),--(('Rewards Dashboard'!$B$3="All")+('Employee Data'!$E$2:$E$493='Rewards Dashboard'!$B$3)>0),--(('Rewards Dashboard'!$D$3="All")+('Employee Data'!$C$2:$C$493='Rewards Dashboard'!$D$3)>0),--(('Rewards Dashboard'!$F$3="All")+('Employee Data'!$D$2:$D$493='Rewards Dashboard'!$F$3)>0),--('Employee Data'!$D$2:$D$493=A57),--('Employee Data'!$E$2:$E$493=B57)),0)} -> 129313.89 | D57: {=IFERROR(SUMPRODUCT('Employee Data'!$I$2:$I$493,--('Employee Data'!$A$2:$A$493<>""),--(('Rewards Dashboard'!$B$3="All")+('Employee Data'!$E$2:$E$493='Rewards Dashboard'!$B$3)>0),--(('Rewards Dashboard'!$D$3="All")+('Employee Data'!$C$2:$C$493='Rewards Dashboard'!$D$3)>0),--(('Rewards Dashboard'!$F$3="All")+('Employee Data'!$D$2:$D$493='Rewards Dashboard'!$F$3)>0),--('Employee Data'!$D$2:$D$493=A57),--('Employee Data'!$E$2:$E$493=B57))/SUMPRODUCT(--('Employee Data'!$A$2:$A$493<>""),--(('Rewards Dashboard'!$B$3="All")+('Employee Data'!$E$2:$E$493='Rewards Dashboard'!$B$3)>0),--(('Rewards Dashboard'!$D$3="All")+('Employee Data'!$C$2:$C$493='Rewards Dashboard'!$D$3)>0),--(('Rewards Dashboard'!$F$3="All")+('Employee Data'!$D$2:$D$493='Rewards Dashboard'!$F$3)>0),--('Employee Data'!$D$2:$D$493=A57),--('Employee Data'!$E$2:$E$493=B57)),0)} -> 5490.7407 | E57: {=SUMPRODUCT(--('Employee Data'!$A$2:$A$493<>""),--(('Rewards Dashboard'!$B$3="All")+('Employee Data'!$E$2:$E$493='Rewards Dashboard'!$B$3)>0),--(('Rewards Dashboard'!$D$3="All")+('Employee Data'!$C$2:$C$493='Rewards Dashboard'!$D$3)>0),--(('Rewards Dashboard'!$F$3="All")+('Employee Data'!$D$2:$D$493='Rewards Dashboard'!$F$3)>0),--('Employee Data'!$D$2:$D$493=A57),--('Employee Data'!$E$2:$E$493=B57))} -> 27 | F57: {=IFERROR(SUMPRODUCT(--('Employee Data'!$I$2:$I$493>7000),--('Employee Data'!$A$2:$A$493<>""),--(('Rewards Dashboard'!$B$3="All")+('Employee Data'!$E$2:$E$493='Rewards Dashboard'!$B$3)>0),--(('Rewards Dashboard'!$D$3="All")+('Employee Data'!$C$2:$C$493='Rewards Dashboard'!$D$3)>0),--(('Rewards Dashboard'!$F$3="All")+('Employee Data'!$D$2:$D$493='Rewards Dashboard'!$F$3)>0),--('Employee Data'!$D$2:$D$493=A57),--('Employee Data'!$E$2:$E$493=B57))/E57,0)} -> 0.25925926
A58: Sales | B58: Gurugram | C58: {=IFERROR(SUMPRODUCT('Employee Data'!$F$2:$F$493,--('Employee Data'!$A$2:$A$493<>""),--(('Rewards Dashboard'!$B$3="All")+('Employee Data'!$E$2:$E$493='Rewards Dashboard'!$B$3)>0),--(('Rewards Dashboard'!$D$3="All")+('Employee Data'!$C$2:$C$493='Rewards Dashboard'!$D$3)>0),--(('Rewards Dashboard'!$F$3="All")+('Employee Data'!$D$2:$D$493='Rewards Dashboard'!$F$3)>0),--('Employee Data'!$D$2:$D$493=A58),--('Employee Data'!$E$2:$E$493=B58))/SUMPRODUCT(--('Employee Data'!$A$2:$A$493<>""),--(('Rewards Dashboard'!$B$3="All")+('Employee Data'!$E$2:$E$493='Rewards Dashboard'!$B$3)>0),--(('Rewards Dashboard'!$D$3="All")+('Employee Data'!$C$2:$C$493='Rewards Dashboard'!$D$3)>0),--(('Rewards Dashboard'!$F$3="All")+('Employee Data'!$D$2:$D$493='Rewards Dashboard'!$F$3)>0),--('Employee Data'!$D$2:$D$493=A58),--('Employee Data'!$E$2:$E$493=B58)),0)} -> 113461.64 | D58: {=IFERROR(SUMPRODUCT('Employee Data'!$I$2:$I$493,--('Employee Data'!$A$2:$A$493<>""),--(('Rewards Dashboard'!$B$3="All")+('Employee Data'!$E$2:$E$493='Rewards Dashboard'!$B$3)>0),--(('Rewards Dashboard'!$D$3="All")+('Employee Data'!$C$2:$C$493='Rewards Dashboard'!$D$3)>0),--(('Rewards Dashboard'!$F$3="All")+('Employee Data'!$D$2:$D$493='Rewards Dashboard'!$F$3)>0),--('Employee Data'!$D$2:$D$493=A58),--('Employee Data'!$E$2:$E$493=B58))/SUMPRODUCT(--('Employee Data'!$A$2:$A$493<>""),--(('Rewards Dashboard'!$B$3="All")+('Employee Data'!$E$2:$E$493='Rewards Dashboard'!$B$3)>0),--(('Rewards Dashboard'!$D$3="All")+('Employee Data'!$C$2:$C$493='Rewards Dashboard'!$D$3)>0),--(('Rewards Dashboard'!$F$3="All")+('Employee Data'!$D$2:$D$493='Rewards Dashboard'!$F$3)>0),--('Employee Data'!$D$2:$D$493=A58),--('Employee Data'!$E$2:$E$493=B58)),0)} -> 6062 | E58: {=SUMPRODUCT(--('Employee Data'!$A$2:$A$493<>""),--(('Rewards Dashboard'!$B$3="All")+('Employee Data'!$E$2:$E$493='Rewards Dashboard'!$B$3)>0),--(('Rewards Dashboard'!$D$3="All")+('Employee Data'!$C$2:$C$493='Rewards Dashboard'!$D$3)>0),--(('Rewards Dashboard'!$F$3="All")+('Employee Data'!$D$2:$D$493='Rewards Dashboard'!$F$3)>0),--('Employee Data'!$D$2:$D$493=A58),--('Employee Data'!$E$2:$E$493=B58))} -> 25 | F58: {=IFERROR(SUMPRODUCT(--('Employee Data'!$I$2:$I$493>7000),--('Employee Data'!$A$2:$A$493<>""),--(('Rewards Dashboard'!$B$3="All")+('Employee Data'!$E$2:$E$493='Rewards Dashboard'!$B$3)>0),--(('Rewards Dashboard'!$D$3="All")+('Employee Data'!$C$2:$C$493='Rewards Dashboard'!$D$3)>0),--(('Rewards Dashboard'!$F$3="All")+('Employee Data'!$D$2:$D$493='Rewards Dashboard'!$F$3)>0),--('Employee Data'!$D$2:$D$493=A58),--('Employee Data'!$E$2:$E$493=B58))/E58,0)} -> 0.32
A59: Tech | B59: Gurugram | C59: {=IFERROR(SUMPRODUCT('Employee Data'!$F$2:$F$493,--('Employee Data'!$A$2:$A$493<>""),--(('Rewards Dashboard'!$B$3="All")+('Employee Data'!$E$2:$E$493='Rewards Dashboard'!$B$3)>0),--(('Rewards Dashboard'!$D$3="All")+('Employee Data'!$C$2:$C$493='Rewards Dashboard'!$D$3)>0),--(('Rewards Dashboard'!$F$3="All")+('Employee Data'!$D$2:$D$493='Rewards Dashboard'!$F$3)>0),--('Employee Data'!$D$2:$D$493=A59),--('Employee Data'!$E$2:$E$493=B59))/SUMPRODUCT(--('Employee Data'!$A$2:$A$493<>""),--(('Rewards Dashboard'!$B$3="All")+('Employee Data'!$E$2:$E$493='Rewards Dashboard'!$B$3)>0),--(('Rewards Dashboard'!$D$3="All")+('Employee Data'!$C$2:$C$493='Rewards Dashboard'!$D$3)>0),--(('Rewards Dashboard'!$F$3="All")+('Employee Data'!$D$2:$D$493='Rewards Dashboard'!$F$3)>0),--('Employee Data'!$D$2:$D$493=A59),--('Employee Data'!$E$2:$E$493=B59)),0)} -> 131479.08 | D59: {=IFERROR(SUMPRODUCT('Employee Data'!$I$2:$I$493,--('Employee Data'!$A$2:$A$493<>""),--(('Rewards Dashboard'!$B$3="All")+('Employee Data'!$E$2:$E$493='Rewards Dashboard'!$B$3)>0),--(('Rewards Dashboard'!$D$3="All")+('Employee Data'!$C$2:$C$493='Rewards Dashboard'!$D$3)>0),--(('Rewards Dashboard'!$F$3="All")+('Employee Data'!$D$2:$D$493='Rewards Dashboard'!$F$3)>0),--('Employee Data'!$D$2:$D$493=A59),--('Employee Data'!$E$2:$E$493=B59))/SUMPRODUCT(--('Employee Data'!$A$2:$A$493<>""),--(('Rewards Dashboard'!$B$3="All")+('Employee Data'!$E$2:$E$493='Rewards Dashboard'!$B$3)>0),--(('Rewards Dashboard'!$D$3="All")+('Employee Data'!$C$2:$C$493='Rewards Dashboard'!$D$3)>0),--(('Rewards Dashboard'!$F$3="All")+('Employee Data'!$D$2:$D$493='Rewards Dashboard'!$F$3)>0),--('Employee Data'!$D$2:$D$493=A59),--('Employee Data'!$E$2:$E$493=B59)),0)} -> 5066 | E59: {=SUMPRODUCT(--('Employee Data'!$A$2:$A$493<>""),--(('Rewards Dashboard'!$B$3="All")+('Employee Data'!$E$2:$E$493='Rewards Dashboard'!$B$3)>0),--(('Rewards Dashboard'!$D$3="All")+('Employee Data'!$C$2:$C$493='Rewards Dashboard'!$D$3)>0),--(('Rewards Dashboard'!$F$3="All")+('Employee Data'!$D$2:$D$493='Rewards Dashboard'!$F$3)>0),--('Employee Data'!$D$2:$D$493=A59),--('Employee Data'!$E$2:$E$493=B59))} -> 25 | F59: {=IFERROR(SUMPRODUCT(--('Employee Data'!$I$2:$I$493>7000),--('Employee Data'!$A$2:$A$493<>""),--(('Rewards Dashboard'!$B$3="All")+('Employee Data'!$E$2:$E$493='Rewards Dashboard'!$B$3)>0),--(('Rewards Dashboard'!$D$3="All")+('Employee Data'!$C$2:$C$493='Rewards Dashboard'!$D$3)>0),--(('Rewards Dashboard'!$F$3="All")+('Employee Data'!$D$2:$D$493='Rewards Dashboard'!$F$3)>0),--('Employee Data'!$D$2:$D$493=A59),--('Employee Data'!$E$2:$E$493=B59))/E59,0)} -> 0.2
A60: Finance | B60: Hyderabad | C60: {=IFERROR(SUMPRODUCT('Employee Data'!$F$2:$F$493,--('Employee Data'!$A$2:$A$493<>""),--(('Rewards Dashboard'!$B$3="All")+('Employee Data'!$E$2:$E$493='Rewards Dashboard'!$B$3)>0),--(('Rewards Dashboard'!$D$3="All")+('Employee Data'!$C$2:$C$493='Rewards Dashboard'!$D$3)>0),--(('Rewards Dashboard'!$F$3="All")+('Employee Data'!$D$2:$D$493='Rewards Dashboard'!$F$3)>0),--('Employee Data'!$D$2:$D$493=A60),--('Employee Data'!$E$2:$E$493=B60))/SUMPRODUCT(--('Employee Data'!$A$2:$A$493<>""),--(('Rewards Dashboard'!$B$3="All")+('Employee Data'!$E$2:$E$493='Rewards Dashboard'!$B$3)>0),--(('Rewards Dashboard'!$D$3="All")+('Employee Data'!$C$2:$C$493='Rewards Dashboard'!$D$3)>0),--(('Rewards Dashboard'!$F$3="All")+('Employee Data'!$D$2:$D$493='Rewards Dashboard'!$F$3)>0),--('Employee Data'!$D$2:$D$493=A60),--('Employee Data'!$E$2:$E$493=B60)),0)} -> 132462.28 | D60: {=IFERROR(SUMPRODUCT('Employee Data'!$I$2:$I$493,--('Employee Data'!$A$2:$A$493<>""),--(('Rewards Dashboard'!$B$3="All")+('Employee Data'!$E$2:$E$493='Rewards Dashboard'!$B$3)>0),--(('Rewards Dashboard'!$D$3="All")+('Employee Data'!$C$2:$C$493='Rewards Dashboard'!$D$3)>0),--(('Rewards Dashboard'!$F$3="All")+('Employee Data'!$D$2:$D$493='Rewards Dashboard'!$F$3)>0),--('Employee Data'!$D$2:$D$493=A60),--('Employee Data'!$E$2:$E$493=B60))/SUMPRODUCT(--('Employee Data'!$A$2:$A$493<>""),--(('Rewards Dashboard'!$B$3="All")+('Employee Data'!$E$2:$E$493='Rewards Dashboard'!$B$3)>0),--(('Rewards Dashboard'!$D$3="All")+('Employee Data'!$C$2:$C$493='Rewards Dashboard'!$D$3)>0),--(('Rewards Dashboard'!$F$3="All")+('Employee Data'!$D$2:$D$493='Rewards Dashboard'!$F$3)>0),--('Employee Data'!$D$2:$D$493=A60),--('Employee Data'!$E$2:$E$493=B60)),0)} -> 5944.8276 | E60: {=SUMPRODUCT(--('Employee Data'!$A$2:$A$493<>""),--(('Rewards Dashboard'!$B$3="All")+('Employee Data'!$E$2:$E$493='Rewards Dashboard'!$B$3)>0),--(('Rewards Dashboard'!$D$3="All")+('Employee Data'!$C$2:$C$493='Rewards Dashboard'!$D$3)>0),--(('Rewards Dashboard'!$F$3="All")+('Employee Data'!$D$2:$D$493='Rewards Dashboard'!$F$3)>0),--('Employee Data'!$D$2:$D$493=A60),--('Employee Data'!$E$2:$E$493=B60))} -> 29 | F60: {=IFERROR(SUMPRODUCT(--('Employee Data'!$I$2:$I$493>7000),--('Employee Data'!$A$2:$A$493<>""),--(('Rewards Dashboard'!$B$3="All")+('Employee Data'!$E$2:$E$493='Rewards Dashboard'!$B$3)>0),--(('Rewards Dashboard'!$D$3="All")+('Employee Data'!$C$2:$C$493='Rewards Dashboard'!$D$3)>0),--(('Rewards Dashboard'!$F$3="All")+('Employee Data'!$D$2:$D$493='Rewards Dashboard'!$F$3)>0),--('Employee Data'!$D$2:$D$493=A60),--('Employee Data'!$E$2:$E$493=B60))/E60,0)} -> 0.34482759
...

Sheet Employee Data
A1: Employee ID | B1: Full Name | C1: Gender | D1: Department | E1: Location | F1: Monthly Base Salary (INR) | G1: Corporate Benefit Plan | H1: Insurance tier | I1: Monthly Premiums | J1: Salary Bracket | K1: Salary Tier | L1: Vendor Survey Job Code | M1: Vendor Global Group Name | O1: Min | P1: =MIN(F:F) -> 37116 | Q1: Max | R1: =MAX(F:F) -> 233215
A2: Emp1011 | B2: Philip Dias | C2: Male | D2: Operations | E2: Hyderabad | F2: 99610 | G2: Family Floater | H2: Gold | I2: 6750 | J2: Between 50k and 200k | K2: Mid | L2: IN-OPS-02 | M2: Core Operations Specialist | O2: Range of Salary | P2: =R1-P1 -> 196099
A3: Emp1337 | B3: Kaif Pathan | C3: Male | D3: Operations | E3: Gurugram | F3: 99367 | G3: Family Floater | H3: Gold | I3: 6750 | J3: Between 50k and 200k | K3: Mid | L3: IN-OPS-02 | M3: Core Operations Specialist | O3: IQR | P3: =_xlfn.QUARTILE.INC(Indian_Employee_Data[Monthly Base Salary (INR)],1) - _xlfn.QUARTILE.INC(Indian_Employee_Data[Monthly Base Salary (INR)],) -> 45195.5
A4: Emp1399 | B4: Karma Lepcha | C4: Male | D4: Operations | E4: Hyderabad | F4: 96746 | G4: Parents Included | H4: Gold | I4: 9000 | J4: Between 50k and 200k | K4: Mid | L4: IN-OPS-02 | M4: Core Operations Specialist | O4: Outlier check | P4: Lower bound | Q4: Upper Bound
A5: Emp1358 | B5: Nongthombam Nongthombam | C5: Male | D5: Operations | E5: Noida | F5: 98251 | G5: Parents Included | H5: Gold | I5: 9000 | J5: Between 50k and 200k | K5: Mid | L5: IN-OPS-02 | M5: Core Operations Specialist | P5: =_xlfn.QUARTILE.INC(Indian_Employee_Data[Monthly Base Salary (INR)],1) - (1.5*$P$3) -> 14518.25 | Q5: =_xlfn.QUARTILE.INC(Indian_Employee_Data[Monthly Base Salary (INR)],3) - (1.5*$P$3) -> 110957.25
A6: Emp1396 | B6: Kersi Anand | C6: Male | D6: Sales | E6: Bengaluru | F6: 101272 | G6: Family Floater | H6: Gold | I6: 6750 | J6: Between 50k and 200k | K6: Mid | L6: IN-SLS-01 | M6: Field Sales Execution | P6: No Low Outliers | Q6: High Outliers Exist
A7: Emp1382 | B7: Gursharan Dhaliwal | C7: Male | D7: Finance | E7: Noida | F7: 100499 | G7: Family Floater | H7: Gold | I7: 6750 | J7: Between 50k and 200k | K7: Mid | L7: IN-FIN-03 | M7: Corporate Finance Core
A8: Emp1446 | B8: Harish Pandey | C8: Male | D8: Operations | E8: Hyderabad | F8: 90404 | G8: Family Floater | H8: Gold | I8: 6750 | J8: Between 50k and 200k | K8: Mid | L8: IN-OPS-02 | M8: Core Operations Specialist
A9: Emp1271 | B9: Mebandari Nongsiej | C9: Male | D9: Finance | E9: Gurugram | F9: 105546 | G9: Family Floater | H9: Gold | I9: 6750 | J9: Between 50k and 200k | K9: Mid | L9: IN-FIN-03 | M9: Corporate Finance Core
A10: Emp1324 | B10: Jaspreet Brar | C10: Male | D10: HR | E10: Hyderabad | F10: 90364 | G10: Parents Included | H10: Gold | I10: 9000 | J10: Between 50k and 200k | K10: Mid | L10: IN-HR-02 | M10: Corporate Talent Admin
A11: Emp1219 | B11: Dipika Sarma | C11: Male | D11: Operations | E11: Hyderabad | F11: 92434 | G11: Parents Included | H11: Gold | I11: 9000 | J11: Between 50k and 200k | K11: Mid | L11: IN-OPS-02 | M11: Core Operations Specialist
A12: Emp1230 | B12: Kulwinder Randhawa | C12: Male | D12: Tech | E12: Hyderabad | F12: 92813 | G12: Parents Included | H12: Gold | I12: 9000 | J12: Between 50k and 200k | K12: Mid | L12: IN-TECH-04 | M12: High-Value Technical Core
A13: Emp1020 | B13: Bhavesh Kapoor | C13: Male | D13: HR | E13: Hyderabad | F13: 106272 | G13: Family Floater | H13: Gold | I13: 6750 | J13: Between 50k and 200k | K13: Mid | L13: IN-HR-02 | M13: Corporate Talent Admin
A14: Emp1395 | B14: Kumar Raman | C14: Male | D14: Sales | E14: Hyderabad | F14: 116159 | G14: Family Floater | H14: Gold | I14: 6750 | J14: Between 50k and 200k | K14: Mid | L14: IN-SLS-01 | M14: Field Sales Execution
A15: Emp1421 | B15: Anand Krishnan | C15: Male | D15: HR | E15: Gurugram | F15: 116677 | G15: Parents Included | H15: Gold | I15: 9000 | J15: Between 50k and 200k | K15: Mid | L15: IN-HR-02 | M15: Corporate Talent Admin
A16: Emp1471 | B16: Arif Hashmi | C16: Male | D16: Operations | E16: Hyderabad | F16: 116757 | G16: Family Floater | H16: Gold | I16: 6750 | J16: Between 50k and 200k | K16: Mid | L16: IN-OPS-02 | M16: Core Operations Specialist
A17: Emp1198 | B17: Gopal Nair | C17: Male | D17: Sales | E17: Gurugram | F17: 117422 | G17: Parents Included | H17: Gold | I17: 9000 | J17: Between 50k and 200k | K17: Mid | L17: IN-SLS-01 | M17: Field Sales Execution
A18: Emp1484 | B18: Saroja Raman | C18: Male | D18: Finance | E18: Gurugram | F18: 89082 | G18: Parents Included | H18: Gold | I18: 9000 | J18: Between 50k and 200k | K18: Mid | L18: IN-FIN-03 | M18: Corporate Finance Core
... A493: Emp1499 | B493: Devi Krishnan | C493: Female | D493: Sales | E493: Hyderabad | F493: 37116 | G493: Family Floater | H493: Gold | I493: 6750 | J493: Under 50k | K493: Junior | L493: IN-SLS-01 | M493: Field Sales Execution
