Workbook
Name Slicer_Department: #N/A
Name Slicer_Gender: #N/A
Name Slicer_Location: #N/A

Sheet Cover
A1: Rewards & Benefits Analytics Dashboard
A2: McKinsey-style executive view using live formulas, pivots, and all employee records.
A4: CONTENTS | B4: DESCRIPTION
A5: Rewards Dashboard | B5: Interactive executive dashboard with filters, KPI cards, charts, benchmarking table, and narrative insights.
A6: Employee Data | B6: Source employee table used for the live dashboard calculations.
A7: Main Pivot Table Sheet | B7: Existing pivot to view analysis in one shot.
A8: Rewards & Benefits Allocation | B8: Existing pivot allocation view used as a validation source for premium and high-cost totals.
A9: Gender Pay Equity | B9: Existing gender pay pivot analysis referenced in the pay-gap visualization.
A10: Basic Analysis | B10: Existing pivot-table workbook analysis supporting the dashboard.
A11: Dashboard Data | B11: Hidden helper sheet with live formulas feeding dashboard charts.

Sheet Rewards Dashboard
A1: Rewards operations dashboard
A2: Interactive rewards, benefits, pay equity and benchmarking view — change filters to refresh KPIs, charts and table.
A3: Location | B3: All | C3: Gender | D3: All | E3: Department | F3: All | H3: Source: Demo Data created with 492 rows | J3: Source: Demo Data created with 492 rows
A5: Headcount | D5: Avg salary | G5: Total premium | J5: High-cost %
A6: =GETPIVOTDATA("[Measures].[Headcount]",'Rewards & Benefits Allocation'!$A$1) -> 492 | D6: =GETPIVOTDATA("[Measures].[Average Salary]",'Rewards & Benefits Allocation'!$A$1) -> 130673.85 | G6: =GETPIVOTDATA("[Measures].[Total Monthly Premium Cost]",'Rewards & Benefits Allocation'!$A$1) -> 2583000 | J6: =GETPIVOTDATA("[Measures].[High-Cost Employee %]",'Rewards & Benefits Allocation'!$A$1) -> 0.23373984
A10: AVG PREMIUM BY DEPARTMENT X LOCATION | H10: PLAN MIX BY TIER
A27: HEADCOUNT BY DEPARTMENT | H27: GENDER PAY GAP BY SALARY BAND
A44: BENCHMARKING SUBMISSION VIEW
A45: Department | B45: Location | C45: Avg salary | D45: Avg premium | E45: Headcount | F45: High-cost % | H45: Story in brief: High-cost employees are defined as employees with monthly premiums over ₹7,000. Under this threshold, high-premium benefit combinations are the main cost concentration. Use the filters above to isolate a city, gender, or department; every KPI, chart and benchmarking row recalculates from the employee-level source table.
A46: ='Helper Sheet'!H50 -> Finance | B46: ='Helper Sheet'!I50 -> Hyderabad | C46: ='Helper Sheet'!J50 -> 132462.28 | D46: ='Helper Sheet'!K50 -> 5944.8276 | E46: ='Helper Sheet'!L50 -> 29 | F46: ='Helper Sheet'!M50 -> 0.34482759
A47: ='Helper Sheet'!H51 -> Sales | B47: ='Helper Sheet'!I51 -> Gurugram | C47: ='Helper Sheet'!J51 -> 113461.64 | D47: ='Helper Sheet'!K51 -> 6062 | E47: ='Helper Sheet'!L51 -> 25 | F47: ='Helper Sheet'!M51 -> 0.32
A48: ='Helper Sheet'!H52 -> Operations | B48: ='Helper Sheet'!I52 -> Hyderabad | C48: ='Helper Sheet'!J52 -> 116854.31 | D48: ='Helper Sheet'!K52 -> 5475 | E48: ='Helper Sheet'!L52 -> 26 | F48: ='Helper Sheet'!M52 -> 0.30769231
A49: ='Helper Sheet'!H53 -> Sales | B49: ='Helper Sheet'!I53 -> Noida | C49: ='Helper Sheet'!J53 -> 141647.96 | D49: ='Helper Sheet'!K53 -> 5293.75 | E49: ='Helper Sheet'!L53 -> 24 | F49: ='Helper Sheet'!M53 -> 0.29166667
A50: ='Helper Sheet'!H54 -> HR | B50: ='Helper Sheet'!I54 -> Bengaluru | C50: ='Helper Sheet'!J54 -> 137245.47 | D50: ='Helper Sheet'!K54 -> 5489.4737 | E50: ='Helper Sheet'!L54 -> 19 | F50: ='Helper Sheet'!M54 -> 0.26315789
A51: ='Helper Sheet'!H55 -> Operations | B51: ='Helper Sheet'!I55 -> Gurugram | C51: ='Helper Sheet'!J55 -> 129313.89 | D51: ='Helper Sheet'!K55 -> 5490.7407 | E51: ='Helper Sheet'!L55 -> 27 | F51: ='Helper Sheet'!M55 -> 0.25925926
A56: RAW DATA TABLE
A57: Raw data table: the dashboard is powered by `Employee Data` rows with validated Location, Department, Gender, Insurance tier and Corporate Benefit Plan fields. The hidden `Dashboard Data` helper sheet holds live formulas that feed the charts; source records remain on the original data sheet.

Sheet Main Pivot Table Sheet
A1: High-Cost Employee % | B1: Location | H1: Vendor Global Group Name | I1: Vendor Survey Job Code | J1: Total Monthly Premium Cost | K1: High-Cost Employee % | L1: Headcount | M1: Average Salary
A2: Department | B2: Bengaluru | C2: Gurugram | D2: Hyderabad | E2: Noida | F2: Grand Total | H2: Core Operations Specialist | I2: IN-OPS-02 | J2: 498750 | K2: 0.2371134 | L2: 97 | M2: 130534.66
A3: Finance | B3: 0.18181818 | C3: 0.22727273 | D3: 0.34482759 | E3: 0.25 | F3: 0.25773196 | H3: Corporate Finance Core | I3: IN-FIN-03 | J3: 533850 | K3: 0.25773196 | L3: 97 | M3: 132946.18
A4: HR | B4: 0.26315789 | C4: 0.19047619 | D4: 0.19230769 | E4: 0.18181818 | F4: 0.20454545 | H4: Corporate Talent Admin | I4: IN-HR-02 | J4: 436650 | K4: 0.20454545 | L4: 88 | M4: 138284.89
A5: Operations | B5: 0.21052632 | C5: 0.25925926 | D5: 0.30769231 | E5: 0.16 | F5: 0.2371134 | H5: Field Sales Execution | I5: IN-SLS-01 | J5: 598750 | K5: 0.25688073 | L5: 109 | M5: 121449.4
A6: Sales | B6: 0.2 | C6: 0.32 | D6: 0.22857143 | E6: 0.29166667 | F6: 0.25688073 | H6: High-Value Technical Core | I6: IN-TECH-04 | J6: 515000 | K6: 0.20792079 | L6: 101 | M6: 131948.91
A7: Tech | B7: 0.16 | C7: 0.2 | D7: 0.25 | E7: 0.22222222 | F7: 0.20792079 | H7: Grand Total | J7: 2583000 | K7: 0.23373984 | L7: 492 | M7: 130673.85
A8: Grand Total | B8: 0.2 | C8: 0.24166667 | D8: 0.26428571 | E8: 0.22131148 | F8: 0.23373984
H9: Insurance Tier | I9: Count of Insurance tier | K9: Benefit Plan | L9: Count
A10: Avg monthly salary | B10: Gender | E10: Note: The Transgender group is too small for standalone statistical comparison and is excluded from the gender pay analysis below — noted here as a scope limitation, not an omission. | H10: Bronze | I10: 59 | K10: Family Floater | L10: 208
A11: Salary Band | B11: Female | C11: Male | D11: Gap (M-F) | H11: Gold | I11: 216 | K11: Individual | L11: 170
A12: Junior | B12: 58605.621 | C12: 60047.345 | D12: =C12-B12 -> 1441.7236 | H12: Silver | I12: 217 | K12: Parents Included | L12: 114
A13: Mid | B13: 106884.82 | C13: 105455.64 | D13: =C13-B13 -> -1429.1764 | H13: Grand Total | I13: 492 | K13: Grand Total | L13: 492
A14: Senior | B14: 151651.42 | C14: 155421.52 | D14: =C14-B14 -> 3770.0924
A15: Lead | B15: 206596.59 | C15: 204081.45 | D15: =C15-B15 -> -2515.1422 | H15: Insurance Tier | I15: Total Monthly Premium Cost
A16: Grand Total | B16: 124037.14 | C16: 136236.83 | D16: =C16-B16 -> 12199.691 | H16: Family Floater | I16: 1148700
H17: Individual | I17: 405800
H18: Parents Included | I18: 1028500
H19: Grand Total | I19: 2583000

Sheet Helper Sheet
A1: Locations | B1: Genders | C1: Departments | D1: Tiers | E1: Plans | F1: Salary Bands
A2: All | B2: All | C2: All | D2: Bronze | E2: Individual | F2: Junior
A3: Bengaluru | B3: Female | C3: Finance | D3: Silver | E3: Family Floater | F3: Mid
A4: Gurugram | B4: Male | C4: HR | D4: Gold | E4: Parents Included | F4: Senior
A5: Hyderabad | B5: Transgender | C5: Operations | F5: Lead
A6: Noida | C6: Sales
C7: Tech
A11: Department | B11: Bengaluru | C11: Gurugram | D11: Hyderabad | E11: Noida
A12: Finance | B12: =IF(OR('Rewards Dashboard'!$B$3="All",'Rewards Dashboard'!$B$3=B$11),IF(OR('Rewards Dashboard'!$F$3="All",'Rewards Dashboard'!$F$3=$A12),IFERROR(AVERAGEIFS('Employee Data'!$I$2:$I$493,'Employee Data'!$D$2:$D$493,$A12,'Employee Data'!$E$2:$E$493,B$11,'Employee Data'!$C$2:$C$493,IF('Rewards Dashboard'!$D$3="All","*",'Rewards Dashboard'!$D$3)),NA()),NA()),NA()) -> 4927.2727 | C12: =IF(OR('Rewards Dashboard'!$B$3="All",'Rewards Dashboard'!$B$3=C$11),IF(OR('Rewards Dashboard'!$F$3="All",'Rewards Dashboard'!$F$3=$A12),IFERROR(AVERAGEIFS('Employee Data'!$I$2:$I$493,'Employee Data'!$D$2:$D$493,$A12,'Employee Data'!$E$2:$E$493,C$11,'Employee Data'!$C$2:$C$493,IF('Rewards Dashboard'!$D$3="All","*",'Rewards Dashboard'!$D$3)),NA()),NA()),NA()) -> 5190.9091 | D12: =IF(OR('Rewards Dashboard'!$B$3="All",'Rewards Dashboard'!$B$3=D$11),IF(OR('Rewards Dashboard'!$F$3="All",'Rewards Dashboard'!$F$3=$A12),IFERROR(AVERAGEIFS('Employee Data'!$I$2:$I$493,'Employee Data'!$D$2:$D$493,$A12,'Employee Data'!$E$2:$E$493,D$11,'Employee Data'!$C$2:$C$493,IF('Rewards Dashboard'!$D$3="All","*",'Rewards Dashboard'!$D$3)),NA()),NA()),NA()) -> 5944.8276 | E12: =IF(OR('Rewards Dashboard'!$B$3="All",'Rewards Dashboard'!$B$3=E$11),IF(OR('Rewards Dashboard'!$F$3="All",'Rewards Dashboard'!$F$3=$A12),IFERROR(AVERAGEIFS('Employee Data'!$I$2:$I$493,'Employee Data'!$D$2:$D$493,$A12,'Employee Data'!$E$2:$E$493,E$11,'Employee Data'!$C$2:$C$493,IF('Rewards Dashboard'!$D$3="All","*",'Rewards Dashboard'!$D$3)),NA()),NA()),NA()) -> 5785.4167
A13: HR | B13: =IF(OR('Rewards Dashboard'!$B$3="All",'Rewards Dashboard'!$B$3=B$11),IF(OR('Rewards Dashboard'!$F$3="All",'Rewards Dashboard'!$F$3=$A13),IFERROR(AVERAGEIFS('Employee Data'!$I$2:$I$493,'Employee Data'!$D$2:$D$493,$A13,'Employee Data'!$E$2:$E$493,B$11,'Employee Data'!$C$2:$C$493,IF('Rewards Dashboard'!$D$3="All","*",'Rewards Dashboard'!$D$3)),NA()),NA()),NA()) -> 5489.4737 | C13: =IF(OR('Rewards Dashboard'!$B$3="All",'Rewards Dashboard'!$B$3=C$11),IF(OR('Rewards Dashboard'!$F$3="All",'Rewards Dashboard'!$F$3=$A13),IFERROR(AVERAGEIFS('Employee Data'!$I$2:$I$493,'Employee Data'!$D$2:$D$493,$A13,'Employee Data'!$E$2:$E$493,C$11,'Employee Data'!$C$2:$C$493,IF('Rewards Dashboard'!$D$3="All","*",'Rewards Dashboard'!$D$3)),NA()),NA()),NA()) -> 5064.2857 | D13: =IF(OR('Rewards Dashboard'!$B$3="All",'Rewards Dashboard'!$B$3=D$11),IF(OR('Rewards Dashboard'!$F$3="All",'Rewards Dashboard'!$F$3=$A13),IFERROR(AVERAGEIFS('Employee Data'!$I$2:$I$493,'Employee Data'!$D$2:$D$493,$A13,'Employee Data'!$E$2:$E$493,D$11,'Employee Data'!$C$2:$C$493,IF('Rewards Dashboard'!$D$3="All","*",'Rewards Dashboard'!$D$3)),NA()),NA()),NA()) -> 4819.2308 | E13: =IF(OR('Rewards Dashboard'!$B$3="All",'Rewards Dashboard'!$B$3=E$11),IF(OR('Rewards Dashboard'!$F$3="All",'Rewards Dashboard'!$F$3=$A13),IFERROR(AVERAGEIFS('Employee Data'!$I$2:$I$493,'Employee Data'!$D$2:$D$493,$A13,'Employee Data'!$E$2:$E$493,E$11,'Employee Data'!$C$2:$C$493,IF('Rewards Dashboard'!$D$3="All","*",'Rewards Dashboard'!$D$3)),NA()),NA()),NA()) -> 4577.2727
A14: Operations | B14: =IF(OR('Rewards Dashboard'!$B$3="All",'Rewards Dashboard'!$B$3=B$11),IF(OR('Rewards Dashboard'!$F$3="All",'Rewards Dashboard'!$F$3=$A14),IFERROR(AVERAGEIFS('Employee Data'!$I$2:$I$493,'Employee Data'!$D$2:$D$493,$A14,'Employee Data'!$E$2:$E$493,B$11,'Employee Data'!$C$2:$C$493,IF('Rewards Dashboard'!$D$3="All","*",'Rewards Dashboard'!$D$3)),NA()),NA()),NA()) -> 4192.1053 | C14: =IF(OR('Rewards Dashboard'!$B$3="All",'Rewards Dashboard'!$B$3=C$11),IF(OR('Rewards Dashboard'!$F$3="All",'Rewards Dashboard'!$F$3=$A14),IFERROR(AVERAGEIFS('Employee Data'!$I$2:$I$493,'Employee Data'!$D$2:$D$493,$A14,'Employee Data'!$E$2:$E$493,C$11,'Employee Data'!$C$2:$C$493,IF('Rewards Dashboard'!$D$3="All","*",'Rewards Dashboard'!$D$3)),NA()),NA()),NA()) -> 5490.7407 | D14: =IF(OR('Rewards Dashboard'!$B$3="All",'Rewards Dashboard'!$B$3=D$11),IF(OR('Rewards Dashboard'!$F$3="All",'Rewards Dashboard'!$F$3=$A14),IFERROR(AVERAGEIFS('Employee Data'!$I$2:$I$493,'Employee Data'!$D$2:$D$493,$A14,'Employee Data'!$E$2:$E$493,D$11,'Employee Data'!$C$2:$C$493,IF('Rewards Dashboard'!$D$3="All","*",'Rewards Dashboard'!$D$3)),NA()),NA()),NA()) -> 5475 | E14: =IF(OR('Rewards Dashboard'!$B$3="All",'Rewards Dashboard'!$B$3=E$11),IF(OR('Rewards Dashboard'!$F$3="All",'Rewards Dashboard'!$F$3=$A14),IFERROR(AVERAGEIFS('Employee Data'!$I$2:$I$493,'Employee Data'!$D$2:$D$493,$A14,'Employee Data'!$E$2:$E$493,E$11,'Employee Data'!$C$2:$C$493,IF('Rewards Dashboard'!$D$3="All","*",'Rewards Dashboard'!$D$3)),NA()),NA()),NA()) -> 5140
A15: Sales | B15: =IF(OR('Rewards Dashboard'!$B$3="All",'Rewards Dashboard'!$B$3=B$11),IF(OR('Rewards Dashboard'!$F$3="All",'Rewards Dashboard'!$F$3=$A15),IFERROR(AVERAGEIFS('Employee Data'!$I$2:$I$493,'Employee Data'!$D$2:$D$493,$A15,'Employee Data'!$E$2:$E$493,B$11,'Employee Data'!$C$2:$C$493,IF('Rewards Dashboard'!$D$3="All","*",'Rewards Dashboard'!$D$3)),NA()),NA()),NA()) -> 5430 | C15: =IF(OR('Rewards Dashboard'!$B$3="All",'Rewards Dashboard'!$B$3=C$11),IF(OR('Rewards Dashboard'!$F$3="All",'Rewards Dashboard'!$F$3=$A15),IFERROR(AVERAGEIFS('Employee Data'!$I$2:$I$493,'Employee Data'!$D$2:$D$493,$A15,'Employee Data'!$E$2:$E$493,C$11,'Employee Data'!$C$2:$C$493,IF('Rewards Dashboard'!$D$3="All","*",'Rewards Dashboard'!$D$3)),NA()),NA()),NA()) -> 6062 | D15: =IF(OR('Rewards Dashboard'!$B$3="All",'Rewards Dashboard'!$B$3=D$11),IF(OR('Rewards Dashboard'!$F$3="All",'Rewards Dashboard'!$F$3=$A15),IFERROR(AVERAGEIFS('Employee Data'!$I$2:$I$493,'Employee Data'!$D$2:$D$493,$A15,'Employee Data'!$E$2:$E$493,D$11,'Employee Data'!$C$2:$C$493,IF('Rewards Dashboard'!$D$3="All","*",'Rewards Dashboard'!$D$3)),NA()),NA()),NA()) -> 5268.5714 | E15: =IF(OR('Rewards Dashboard'!$B$3="All",'Rewards Dashboard'!$B$3=E$11),IF(OR('Rewards Dashboard'!$F$3="All",'Rewards Dashboard'!$F$3=$A15),IFERROR(AVERAGEIFS('Employee Data'!$I$2:$I$493,'Employee Data'!$D$2:$D$493,$A15,'Employee Data'!$E$2:$E$493,E$11,'Employee Data'!$C$2:$C$493,IF('Rewards Dashboard'!$D$3="All","*",'Rewards Dashboard'!$D$3)),NA()),NA()),NA()) -> 5293.75
A16: Tech | B16: =IF(OR('Rewards Dashboard'!$B$3="All",'Rewards Dashboard'!$B$3=B$11),IF(OR('Rewards Dashboard'!$F$3="All",'Rewards Dashboard'!$F$3=$A16),IFERROR(AVERAGEIFS('Employee Data'!$I$2:$I$493,'Employee Data'!$D$2:$D$493,$A16,'Employee Data'!$E$2:$E$493,B$11,'Employee Data'!$C$2:$C$493,IF('Rewards Dashboard'!$D$3="All","*",'Rewards Dashboard'!$D$3)),NA()),NA()),NA()) -> 5174 | C16: =IF(OR('Rewards Dashboard'!$B$3="All",'Rewards Dashboard'!$B$3=C$11),IF(OR('Rewards Dashboard'!$F$3="All",'Rewards Dashboard'!$F$3=$A16),IFERROR(AVERAGEIFS('Employee Data'!$I$2:$I$493,'Employee Data'!$D$2:$D$493,$A16,'Employee Data'!$E$2:$E$493,C$11,'Employee Data'!$C$2:$C$493,IF('Rewards Dashboard'!$D$3="All","*",'Rewards Dashboard'!$D$3)),NA()),NA()),NA()) -> 5066 | D16: =IF(OR('Rewards Dashboard'!$B$3="All",'Rewards Dashboard'!$B$3=D$11),IF(OR('Rewards Dashboard'!$F$3="All",'Rewards Dashboard'!$F$3=$A16),IFERROR(AVERAGEIFS('Employee Data'!$I$2:$I$493,'Employee Data'!$D$2:$D$493,$A16,'Employee Data'!$E$2:$E$493,D$11,'Employee Data'!$C$2:$C$493,IF('Rewards Dashboard'!$D$3="All","*",'Rewards Dashboard'!$D$3)),NA()),NA()),NA()) -> 4591.6667 | E16: =IF(OR('Rewards Dashboard'!$B$3="All",'Rewards Dashboard'!$B$3=E$11),IF(OR('Rewards Dashboard'!$F$3="All",'Rewards Dashboard'!$F$3=$A16),IFERROR(AVERAGEIFS('Employee Data'!$I$2:$I$493,'Employee Data'!$D$2:$D$493,$A16,'Employee Data'!$E$2:$E$493,E$11,'Employee Data'!$C$2:$C$493,IF('Rewards Dashboard'!$D$3="All","*",'Rewards Dashboard'!$D$3)),NA()),NA()),NA()) -> 5511.1111
A21: Insurance tier | B21: Headcount
A22: Bronze | B22: {=SUMPRODUCT(--('Employee Data'!$A$2:$A$493<>""),--(('Rewards Dashboard'!$B$3="All")+('Employee Data'!$E$2:$E$493='Rewards Dashboard'!$B$3)>0),--(('Rewards Dashboard'!$D$3="All")+('Employee Data'!$C$2:$C$493='Rewards Dashboard'!$D$3)>0),--(('Rewards Dashboard'!$F$3="All")+('Employee Data'!$D$2:$D$493='Rewards Dashboard'!$F$3)>0),--('Employee Data'!$H$2:$H$493=A22))} -> 59
A23: Silver | B23: {=SUMPRODUCT(--('Employee Data'!$A$2:$A$493<>""),--(('Rewards Dashboard'!$B$3="All")+('Employee Data'!$E$2:$E$493='Rewards Dashboard'!$B$3)>0),--(('Rewards Dashboard'!$D$3="All")+('Employee Data'!$C$2:$C$493='Rewards Dashboard'!$D$3)>0),--(('Rewards Dashboard'!$F$3="All")+('Employee Data'!$D$2:$D$493='Rewards Dashboard'!$F$3)>0),--('Employee Data'!$H$2:$H$493=A23))} -> 217
A24: Gold | B24: {=SUMPRODUCT(--('Employee Data'!$A$2:$A$493<>""),--(('Rewards Dashboard'!$B$3="All")+('Employee Data'!$E$2:$E$493='Rewards Dashboard'!$B$3)>0),--(('Rewards Dashboard'!$D$3="All")+('Employee Data'!$C$2:$C$493='Rewards Dashboard'!$D$3)>0),--(('Rewards Dashboard'!$F$3="All")+('Employee Data'!$D$2:$D$493='Rewards Dashboard'!$F$3)>0),--('Employee Data'!$H$2:$H$493=A24))} -> 216
A29: Department | B29: Headcount
A30: Finance | B30: {=IF(OR('Rewards Dashboard'!$F$3="All",'Rewards Dashboard'!$F$3=A30),SUMPRODUCT(--('Employee Data'!$A$2:$A$493<>""),--(('Rewards Dashboard'!$B$3="All")+('Employee Data'!$E$2:$E$493='Rewards Dashboard'!$B$3)>0),--(('Rewards Dashboard'!$D$3="All")+('Employee Data'!$C$2:$C$493='Rewards Dashboard'!$D$3)>0),--('Employee Data'!$D$2:$D$493=A30)),NA())} -> 97
A31: HR | B31: {=IF(OR('Rewards Dashboard'!$F$3="All",'Rewards Dashboard'!$F$3=A31),SUMPRODUCT(--('Employee Data'!$A$2:$A$493<>""),--(('Rewards Dashboard'!$B$3="All")+('Employee Data'!$E$2:$E$493='Rewards Dashboard'!$B$3)>0),--(('Rewards Dashboard'!$D$3="All")+('Employee Data'!$C$2:$C$493='Rewards Dashboard'!$D$3)>0),--('Employee Data'!$D$2:$D$493=A31)),NA())} -> 88
A32: Operations | B32: {=IF(OR('Rewards Dashboard'!$F$3="All",'Rewards Dashboard'!$F$3=A32),SUMPRODUCT(--('Employee Data'!$A$2:$A$493<>""),--(('Rewards Dashboard'!$B$3="All")+('Employee Data'!$E$2:$E$493='Rewards Dashboard'!$B$3)>0),--(('Rewards Dashboard'!$D$3="All")+('Employee Data'!$C$2:$C$493='Rewards Dashboard'!$D$3)>0),--('Employee Data'!$D$2:$D$493=A32)),NA())} -> 97
A33: Sales | B33: {=IF(OR('Rewards Dashboard'!$F$3="All",'Rewards Dashboard'!$F$3=A33),SUMPRODUCT(--('Employee Data'!$A$2:$A$493<>""),--(('Rewards Dashboard'!$B$3="All")+('Employee Data'!$E$2:$E$493='Rewards Dashboard'!$B$3)>0),--(('Rewards Dashboard'!$D$3="All")+('Employee Data'!$C$2:$C$493='Rewards Dashboard'!$D$3)>0),--('Employee Data'!$D$2:$D$493=A33)),NA())} -> 109
A34: Tech | B34: {=IF(OR('Rewards Dashboard'!$F$3="All",'Rewards Dashboard'!$F$3=A34),SUMPRODUCT(--('Employee Data'!$A$2:$A$493<>""),--(('Rewards Dashboard'!$B$3="All")+('Employee Data'!$E$2:$E$493='Rewards Dashboard'!$B$3)>0),--(('Rewards Dashboard'!$D$3="All")+('Employee Data'!$C$2:$C$493='Rewards Dashboard'!$D$3)>0),--('Employee Data'!$D$2:$D$493=A34)),NA())} -> 101
A39: Salary band | B39: Gap (M-F)
A40: ='Gender Pay Equity'!H12 -> Junior | B40: ='Gender Pay Equity'!K12 -> 2229.5479
A41: ='Gender Pay Equity'!H13 -> Lead | B41: ='Gender Pay Equity'!K13 -> -2672.5515
A42: ='Gender Pay Equity'!H14 -> Mid | B42: ='Gender Pay Equity'!K14 -> 2277.3732
A43: ='Gender Pay Equity'!H15 -> Senior | B43: ='Gender Pay Equity'!K15 -> 1553.5495
A49: Department | B49: Location | C49: Avg salary | D49: Avg premium | E49: Headcount | F49: High-cost % | H49: Department | I49: Location | J49: Avg salary | K49: Avg premium | L49: Headcount | M49: High-cost %
A50: Finance | B50: Bengaluru | C50: {=IFERROR(SUMPRODUCT('Employee Data'!$F$2:$F$493,--('Employee Data'!$A$2:$A$493<>""),--(('Rewards Dashboard'!$B$3="All")+('Employee Data'!$E$2:$E$493='Rewards Dashboard'!$B$3)>0),--(('Rewards Dashboard'!$D$3="All")+('Employee Data'!$C$2:$C$493='Rewards Dashboard'!$D$3)>0),--(('Rewards Dashboard'!$F$3="All")+('Employee Data'!$D$2:$D$493='Rewards Dashboard'!$F$3)>0),--('Employee Data'!$D$2:$D$493=A50),--('Employee Data'!$E$2:$E$493=B50))/SUMPRODUCT(--('Employee Data'!$A$2:$A$493<>""),--(('Rewards Dashboard'!$B$3="All")+('Employee Data'!$E$2:$E$493='Rewards Dashboard'!$B$3)>0),--(('Rewards Dashboard'!$D$3="All")+('Employee Data'!$C$2:$C$493='Rewards Dashboard'!$D$3)>0),--(('Rewards Dashboard'!$F$3="All")+('Employee Data'!$D$2:$D$493='Rewards Dashboard'!$F$3)>0),--('Employee Data'!$D$2:$D$493=A50),--('Employee Data'!$E$2:$E$493=B50)),0)} -> 121773.86 | D50: {=IFERROR(SUMPRODUCT('Employee Data'!$I$2:$I$493,--('Employee Data'!$A$2:$A$493<>""),--(('Rewards Dashboard'!$B$3="All")+('Employee Data'!$E$2:$E$493='Rewards Dashboard'!$B$3)>0),--(('Rewards Dashboard'!$D$3="All")+('Employee Data'!$C$2:$C$493='Rewards Dashboard'!$D$3)>0),--(('Rewards Dashboard'!$F$3="All")+('Employee Data'!$D$2:$D$493='Rewards Dashboard'!$F$3)>0),--('Employee Data'!$D$2:$D$493=A50),--('Employee Data'!$E$2:$E$493=B50))/SUMPRODUCT(--('Employee Data'!$A$2:$A$493<>""),--(('Rewards Dashboard'!$B$3="All")+('Employee Data'!$E$2:$E$493='Rewards Dashboard'!$B$3)>0),--(('Rewards Dashboard'!$D$3="All")+('Employee Data'!$C$2:$C$493='Rewards Dashboard'!$D$3)>0),--(('Rewards Dashboard'!$F$3="All")+('Employee Data'!$D$2:$D$493='Rewards Dashboard'!$F$3)>0),--('Employee Data'!$D$2:$D$493=A50),--('Employee Data'!$E$2:$E$493=B50)),0)} -> 4927.2727 | E50: {=SUMPRODUCT(--('Employee Data'!$A$2:$A$493<>""),--(('Rewards Dashboard'!$B$3="All")+('Employee Data'!$E$2:$E$493='Rewards Dashboard'!$B$3)>0),--(('Rewards Dashboard'!$D$3="All")+('Employee Data'!$C$2:$C$493='Rewards Dashboard'!$D$3)>0),--(('Rewards Dashboard'!$F$3="All")+('Employee Data'!$D$2:$D$493='Rewards Dashboard'!$F$3)>0),--('Employee Data'!$D$2:$D$493=A50),--('Employee Data'!$E$2:$E$493=B50))} -> 22 | F50: {=IFERROR(SUMPRODUCT(--('Employee Data'!$I$2:$I$493>7000),--('Employee Data'!$A$2:$A$493<>""),--(('Rewards Dashboard'!$B$3="All")+('Employee Data'!$E$2:$E$493='Rewards Dashboard'!$B$3)>0),--(('Rewards Dashboard'!$D$3="All")+('Employee Data'!$C$2:$C$493='Rewards Dashboard'!$D$3)>0),--(('Rewards Dashboard'!$F$3="All")+('Employee Data'!$D$2:$D$493='Rewards Dashboard'!$F$3)>0),--('Employee Data'!$D$2:$D$493=A50),--('Employee Data'!$E$2:$E$493=B50))/E50,0)} -> 0.18181818 | H50: {=_xlfn.TAKE(_xlfn.SORTBY(_xlfn._xlws.FILTER($A$50:$F$69,$E$50:$E$69>0),_xlfn._xlws.FILTER($F$50:$F$69,$E$50:$E$69>0),-1,_xlfn._xlws.FILTER($D$50:$D$69,$E$50:$E$69>0),-1),6)} -> Finance | I50: Hyderabad | J50: 132462.28 | K50: 5944.8276 | L50: 29 | M50: 0.34482759
A51: HR | B51: Bengaluru | C51: {=IFERROR(SUMPRODUCT('Employee Data'!$F$2:$F$493,--('Employee Data'!$A$2:$A$493<>""),--(('Rewards Dashboard'!$B$3="All")+('Employee Data'!$E$2:$E$493='Rewards Dashboard'!$B$3)>0),--(('Rewards Dashboard'!$D$3="All")+('Employee Data'!$C$2:$C$493='Rewards Dashboard'!$D$3)>0),--(('Rewards Dashboard'!$F$3="All")+('Employee Data'!$D$2:$D$493='Rewards Dashboard'!$F$3)>0),--('Employee Data'!$D$2:$D$493=A51),--('Employee Data'!$E$2:$E$493=B51))/SUMPRODUCT(--('Employee Data'!$A$2:$A$493<>""),--(('Rewards Dashboard'!$B$3="All")+('Employee Data'!$E$2:$E$493='Rewards Dashboard'!$B$3)>0),--(('Rewards Dashboard'!$D$3="All")+('Employee Data'!$C$2:$C$493='Rewards Dashboard'!$D$3)>0),--(('Rewards Dashboard'!$F$3="All")+('Employee Data'!$D$2:$D$493='Rewards Dashboard'!$F$3)>0),--('Employee Data'!$D$2:$D$493=A51),--('Employee Data'!$E$2:$E$493=B51)),0)} -> 137245.47 | D51: {=IFERROR(SUMPRODUCT('Employee Data'!$I$2:$I$493,--('Employee Data'!$A$2:$A$493<>""),--(('Rewards Dashboard'!$B$3="All")+('Employee Data'!$E$2:$E$493='Rewards Dashboard'!$B$3)>0),--(('Rewards Dashboard'!$D$3="All")+('Employee Data'!$C$2:$C$493='Rewards Dashboard'!$D$3)>0),--(('Rewards Dashboard'!$F$3="All")+('Employee Data'!$D$2:$D$493='Rewards Dashboard'!$F$3)>0),--('Employee Data'!$D$2:$D$493=A51),--('Employee Data'!$E$2:$E$493=B51))/SUMPRODUCT(--('Employee Data'!$A$2:$A$493<>""),--(('Rewards Dashboard'!$B$3="All")+('Employee Data'!$E$2:$E$493='Rewards Dashboard'!$B$3)>0),--(('Rewards Dashboard'!$D$3="All")+('Employee Data'!$C$2:$C$493='Rewards Dashboard'!$D$3)>0),--(('Rewards Dashboard'!$F$3="All")+('Employee Data'!$D$2:$D$493='Rewards Dashboard'!$F$3)>0),--('Employee Data'!$D$2:$D$493=A51),--('Employee Data'!$E$2:$E$493=B51)),0)} -> 5489.4737 | E51: {=SUMPRODUCT(--('Employee Data'!$A$2:$A$493<>""),--(('Rewards Dashboard'!$B$3="All")+('Employee Data'!$E$2:$E$493='Rewards Dashboard'!$B$3)>0),--(('Rewards Dashboard'!$D$3="All")+('Employee Data'!$C$2:$C$493='Rewards Dashboard'!$D$3)>0),--(('Rewards Dashboard'!$F$3="All")+('Employee Data'!$D$2:$D$493='Rewards Dashboard'!$F$3)>0),--('Employee Data'!$D$2:$D$493=A51),--('Employee Data'!$E$2:$E$493=B51))} -> 19 | F51: {=IFERROR(SUMPRODUCT(--('Employee Data'!$I$2:$I$493>7000),--('Employee Data'!$A$2:$A$493<>""),--(('Rewards Dashboard'!$B$3="All")+('Employee Data'!$E$2:$E$493='Rewards Dashboard'!$B$3)>0),--(('Rewards Dashboard'!$D$3="All")+('Employee Data'!$C$2:$C$493='Rewards Dashboard'!$D$3)>0),--(('Rewards Dashboard'!$F$3="All")+('Employee Data'!$D$2:$D$493='Rewards Dashboard'!$F$3)>0),--('Employee Data'!$D$2:$D$493=A51),--('Employee Data'!$E$2:$E$493=B51))/E51,0)} -> 0.26315789 | H51: Sales | I51: Gurugram | J51: 113461.64 | K51: 6062 | L51: 25 | M51: 0.32
A52: Operations | B52: Bengaluru | C52: {=IFERROR(SUMPRODUCT('Employee Data'!$F$2:$F$493,--('Employee Data'!$A$2:$A$493<>""),--(('Rewards Dashboard'!$B$3="All")+('Employee Data'!$E$2:$E$493='Rewards Dashboard'!$B$3)>0),--(('Rewards Dashboard'!$D$3="All")+('Employee Data'!$C$2:$C$493='Rewards Dashboard'!$D$3)>0),--(('Rewards Dashboard'!$F$3="All")+('Employee Data'!$D$2:$D$493='Rewards Dashboard'!$F$3)>0),--('Employee Data'!$D$2:$D$493=A52),--('Employee Data'!$E$2:$E$493=B52))/SUMPRODUCT(--('Employee Data'!$A$2:$A$493<>""),--(('Rewards Dashboard'!$B$3="All")+('Employee Data'!$E$2:$E$493='Rewards Dashboard'!$B$3)>0),--(('Rewards Dashboard'!$D$3="All")+('Employee Data'!$C$2:$C$493='Rewards Dashboard'!$D$3)>0),--(('Rewards Dashboard'!$F$3="All")+('Employee Data'!$D$2:$D$493='Rewards Dashboard'!$F$3)>0),--('Employee Data'!$D$2:$D$493=A52),--('Employee Data'!$E$2:$E$493=B52)),0)} -> 148077.74 | D52: {=IFERROR(SUMPRODUCT('Employee Data'!$I$2:$I$493,--('Employee Data'!$A$2:$A$493<>""),--(('Rewards Dashboard'!$B$3="All")+('Employee Data'!$E$2:$E$493='Rewards Dashboard'!$B$3)>0),--(('Rewards Dashboard'!$D$3="All")+('Employee Data'!$C$2:$C$493='Rewards Dashboard'!$D$3)>0),--(('Rewards Dashboard'!$F$3="All")+('Employee Data'!$D$2:$D$493='Rewards Dashboard'!$F$3)>0),--('Employee Data'!$D$2:$D$493=A52),--('Employee Data'!$E$2:$E$493=B52))/SUMPRODUCT(--('Employee Data'!$A$2:$A$493<>""),--(('Rewards Dashboard'!$B$3="All")+('Employee Data'!$E$2:$E$493='Rewards Dashboard'!$B$3)>0),--(('Rewards Dashboard'!$D$3="All")+('Employee Data'!$C$2:$C$493='Rewards Dashboard'!$D$3)>0),--(('Rewards Dashboard'!$F$3="All")+('Employee Data'!$D$2:$D$493='Rewards Dashboard'!$F$3)>0),--('Employee Data'!$D$2:$D$493=A52),--('Employee Data'!$E$2:$E$493=B52)),0)} -> 4192.1053 | E52: {=SUMPRODUCT(--('Employee Data'!$A$2:$A$493<>""),--(('Rewards Dashboard'!$B$3="All")+('Employee Data'!$E$2:$E$493='Rewards Dashboard'!$B$3)>0),--(('Rewards Dashboard'!$D$3="All")+('Employee Data'!$C$2:$C$493='Rewards Dashboard'!$D$3)>0),--(('Rewards Dashboard'!$F$3="All")+('Employee Data'!$D$2:$D$493='Rewards Dashboard'!$F$3)>0),--('Employee Data'!$D$2:$D$493=A52),--('Employee Data'!$E$2:$E$493=B52))} -> 19 | F52: {=IFERROR(SUMPRODUCT(--('Employee Data'!$I$2:$I$493>7000),--('Employee Data'!$A$2:$A$493<>""),--(('Rewards Dashboard'!$B$3="All")+('Employee Data'!$E$2:$E$493='Rewards Dashboard'!$B$3)>0),--(('Rewards Dashboard'!$D$3="All")+('Employee Data'!$C$2:$C$493='Rewards Dashboard'!$D$3)>0),--(('Rewards Dashboard'!$F$3="All")+('Employee Data'!$D$2:$D$493='Rewards Dashboard'!$F$3)>0),--('Employee Data'!$D$2:$D$493=A52),--('Employee Data'!$E$2:$E$493=B52))/E52,0)} -> 0.21052632 | H52: Operations | I52: Hyderabad | J52: 116854.31 | K52: 5475 | L52: 26 | M52: 0.30769231
A53: Sales | B53: Bengaluru | C53: {=IFERROR(SUMPRODUCT('Employee Data'!$F$2:$F$493,--('Employee Data'!$A$2:$A$493<>""),--(('Rewards Dashboard'!$B$3="All")+('Employee Data'!$E$2:$E$493='Rewards Dashboard'!$B$3)>0),--(('Rewards Dashboard'!$D$3="All")+('Employee Data'!$C$2:$C$493='Rewards Dashboard'!$D$3)>0),--(('Rewards Dashboard'!$F$3="All")+('Employee Data'!$D$2:$D$493='Rewards Dashboard'!$F$3)>0),--('Employee Data'!$D$2:$D$493=A53),--('Employee Data'!$E$2:$E$493=B53))/SUMPRODUCT(--('Employee Data'!$A$2:$A$493<>""),--(('Rewards Dashboard'!$B$3="All")+('Employee Data'!$E$2:$E$493='Rewards Dashboard'!$B$3)>0),--(('Rewards Dashboard'!$D$3="All")+('Employee Data'!$C$2:$C$493='Rewards Dashboard'!$D$3)>0),--(('Rewards Dashboard'!$F$3="All")+('Employee Data'!$D$2:$D$493='Rewards Dashboard'!$F$3)>0),--('Employee Data'!$D$2:$D$493=A53),--('Employee Data'!$E$2:$E$493=B53)),0)} -> 125504.2 | D53: {=IFERROR(SUMPRODUCT('Employee Data'!$I$2:$I$493,--('Employee Data'!$A$2:$A$493<>""),--(('Rewards Dashboard'!$B$3="All")+('Employee Data'!$E$2:$E$493='Rewards Dashboard'!$B$3)>0),--(('Rewards Dashboard'!$D$3="All")+('Employee Data'!$C$2:$C$493='Rewards Dashboard'!$D$3)>0),--(('Rewards Dashboard'!$F$3="All")+('Employee Data'!$D$2:$D$493='Rewards Dashboard'!$F$3)>0),--('Employee Data'!$D$2:$D$493=A53),--('Employee Data'!$E$2:$E$493=B53))/SUMPRODUCT(--('Employee Data'!$A$2:$A$493<>""),--(('Rewards Dashboard'!$B$3="All")+('Employee Data'!$E$2:$E$493='Rewards Dashboard'!$B$3)>0),--(('Rewards Dashboard'!$D$3="All")+('Employee Data'!$C$2:$C$493='Rewards Dashboard'!$D$3)>0),--(('Rewards Dashboard'!$F$3="All")+('Employee Data'!$D$2:$D$493='Rewards Dashboard'!$F$3)>0),--('Employee Data'!$D$2:$D$493=A53),--('Employee Data'!$E$2:$E$493=B53)),0)} -> 5430 | E53: {=SUMPRODUCT(--('Employee Data'!$A$2:$A$493<>""),--(('Rewards Dashboard'!$B$3="All")+('Employee Data'!$E$2:$E$493='Rewards Dashboard'!$B$3)>0),--(('Rewards Dashboard'!$D$3="All")+('Employee Data'!$C$2:$C$493='Rewards Dashboard'!$D$3)>0),--(('Rewards Dashboard'!$F$3="All")+('Employee Data'!$D$2:$D$493='Rewards Dashboard'!$F$3)>0),--('Employee Data'!$D$2:$D$493=A53),--('Employee Data'!$E$2:$E$493=B53))} -> 25 | F53: {=IFERROR(SUMPRODUCT(--('Employee Data'!$I$2:$I$493>7000),--('Employee Data'!$A$2:$A$493<>""),--(('Rewards Dashboard'!$B$3="All")+('Employee Data'!$E$2:$E$493='Rewards Dashboard'!$B$3)>0),--(('Rewards Dashboard'!$D$3="All")+('Employee Data'!$C$2:$C$493='Rewards Dashboard'!$D$3)>0),--(('Rewards Dashboard'!$F$3="All")+('Employee Data'!$D$2:$D$493='Rewards Dashboard'!$F$3)>0),--('Employee Data'!$D$2:$D$493=A53),--('Employee Data'!$E$2:$E$493=B53))/E53,0)} -> 0.2 | H53: Sales | I53: Noida | J53: 141647.96 | K53: 5293.75 | L53: 24 | M53: 0.29166667
A54: Tech | B54: Bengaluru | C54: {=IFERROR(SUMPRODUCT('Employee Data'!$F$2:$F$493,--('Employee Data'!$A$2:$A$493<>""),--(('Rewards Dashboard'!$B$3="All")+('Employee Data'!$E$2:$E$493='Rewards Dashboard'!$B$3)>0),--(('Rewards Dashboard'!$D$3="All")+('Employee Data'!$C$2:$C$493='Rewards Dashboard'!$D$3)>0),--(('Rewards Dashboard'!$F$3="All")+('Employee Data'!$D$2:$D$493='Rewards Dashboard'!$F$3)>0),--('Employee Data'!$D$2:$D$493=A54),--('Employee Data'!$E$2:$E$493=B54))/SUMPRODUCT(--('Employee Data'!$A$2:$A$493<>""),--(('Rewards Dashboard'!$B$3="All")+('Employee Data'!$E$2:$E$493='Rewards Dashboard'!$B$3)>0),--(('Rewards Dashboard'!$D$3="All")+('Employee Data'!$C$2:$C$493='Rewards Dashboard'!$D$3)>0),--(('Rewards Dashboard'!$F$3="All")+('Employee Data'!$D$2:$D$493='Rewards Dashboard'!$F$3)>0),--('Employee Data'!$D$2:$D$493=A54),--('Employee Data'!$E$2:$E$493=B54)),0)} -> 128991.12 | D54: {=IFERROR(SUMPRODUCT('Employee Data'!$I$2:$I$493,--('Employee Data'!$A$2:$A$493<>""),--(('Rewards Dashboard'!$B$3="All")+('Employee Data'!$E$2:$E$493='Rewards Dashboard'!$B$3)>0),--(('Rewards Dashboard'!$D$3="All")+('Employee Data'!$C$2:$C$493='Rewards Dashboard'!$D$3)>0),--(('Rewards Dashboard'!$F$3="All")+('Employee Data'!$D$2:$D$493='Rewards Dashboard'!$F$3)>0),--('Employee Data'!$D$2:$D$493=A54),--('Employee Data'!$E$2:$E$493=B54))/SUMPRODUCT(--('Employee Data'!$A$2:$A$493<>""),--(('Rewards Dashboard'!$B$3="All")+('Employee Data'!$E$2:$E$493='Rewards Dashboard'!$B$3)>0),--(('Rewards Dashboard'!$D$3="All")+('Employee Data'!$C$2:$C$493='Rewards Dashboard'!$D$3)>0),--(('Rewards Dashboard'!$F$3="All")+('Employee Data'!$D$2:$D$493='Rewards Dashboard'!$F$3)>0),--('Employee Data'!$D$2:$D$493=A54),--('Employee Data'!$E$2:$E$493=B54)),0)} -> 5174 | E54: {=SUMPRODUCT(--('Employee Data'!$A$2:$A$493<>""),--(('Rewards Dashboard'!$B$3="All")+('Employee Data'!$E$2:$E$493='Rewards Dashboard'!$B$3)>0),--(('Rewards Dashboard'!$D$3="All")+('Employee Data'!$C$2:$C$493='Rewards Dashboard'!$D$3)>0),--(('Rewards Dashboard'!$F$3="All")+('Employee Data'!$D$2:$D$493='Rewards Dashboard'!$F$3)>0),--('Employee Data'!$D$2:$D$493=A54),--('Employee Data'!$E$2:$E$493=B54))} -> 25 | F54: {=IFERROR(SUMPRODUCT(--('Employee Data'!$I$2:$I$493>7000),--('Employee Data'!$A$2:$A$493<>""),--(('Rewards Dashboard'!$B$3="All")+('Employee Data'!$E$2:$E$493='Rewards Dashboard'!$B$3)>0),--(('Rewards Dashboard'!$D$3="All")+('Employee Data'!$C$2:$C$493='Rewards Dashboard'!$D$3)>0),--(('Rewards Dashboard'!$F$3="All")+('Employee Data'!$D$2:$D$493='Rewards Dashboard'!$F$3)>0),--('Employee Data'!$D$2:$D$493=A54),--('Employee Data'!$E$2:$E$493=B54))/E54,0)} -> 0.16 | H54: HR | I54: Bengaluru | J54: 137245.47 | K54: 5489.4737 | L54: 19 | M54: 0.26315789
A55: Finance | B55: Gurugram | C55: {=IFERROR(SUMPRODUCT('Employee Data'!$F$2:$F$493,--('Employee Data'!$A$2:$A$493<>""),--(('Rewards Dashboard'!$B$3="All")+('Employee Data'!$E$2:$E$493='Rewards Dashboard'!$B$3)>0),--(('Rewards Dashboard'!$D$3="All")+('Employee Data'!$C$2:$C$493='Rewards Dashboard'!$D$3)>0),--(('Rewards Dashboard'!$F$3="All")+('Employee Data'!$D$2:$D$493='Rewards Dashboard'!$F$3)>0),--('Employee Data'!$D$2:$D$493=A55),--('Employee Data'!$E$2:$E$493=B55))/SUMPRODUCT(--('Employee Data'!$A$2:$A$493<>""),--(('Rewards Dashboard'!$B$3="All")+('Employee Data'!$E$2:$E$493='Rewards Dashboard'!$B$3)>0),--(('Rewards Dashboard'!$D$3="All")+('Employee Data'!$C$2:$C$493='Rewards Dashboard'!$D$3)>0),--(('Rewards Dashboard'!$F$3="All")+('Employee Data'!$D$2:$D$493='Rewards Dashboard'!$F$3)>0),--('Employee Data'!$D$2:$D$493=A55),--('Employee Data'!$E$2:$E$493=B55)),0)} -> 118022.5 | D55: {=IFERROR(SUMPRODUCT('Employee Data'!$I$2:$I$493,--('Employee Data'!$A$2:$A$493<>""),--(('Rewards Dashboard'!$B$3="All")+('Employee Data'!$E$2:$E$493='Rewards Dashboard'!$B$3)>0),--(('Rewards Dashboard'!$D$3="All")+('Employee Data'!$C$2:$C$493='Rewards Dashboard'!$D$3)>0),--(('Rewards Dashboard'!$F$3="All")+('Employee Data'!$D$2:$D$493='Rewards Dashboard'!$F$3)>0),--('Employee Data'!$D$2:$D$493=A55),--('Employee Data'!$E$2:$E$493=B55))/SUMPRODUCT(--('Employee Data'!$A$2:$A$493<>""),--(('Rewards Dashboard'!$B$3="All")+('Employee Data'!$E$2:$E$493='Rewards Dashboard'!$B$3)>0),--(('Rewards Dashboard'!$D$3="All")+('Employee Data'!$C$2:$C$493='Rewards Dashboard'!$D$3)>0),--(('Rewards Dashboard'!$F$3="All")+('Employee Data'!$D$2:$D$493='Rewards Dashboard'!$F$3)>0),--('Employee Data'!$D$2:$D$493=A55),--('Employee Data'!$E$2:$E$493=B55)),0)} -> 5190.9091 | E55: {=SUMPRODUCT(--('Employee Data'!$A$2:$A$493<>""),--(('Rewards Dashboard'!$B$3="All")+('Employee Data'!$E$2:$E$493='Rewards Dashboard'!$B$3)>0),--(('Rewards Dashboard'!$D$3="All")+('Employee Data'!$C$2:$C$493='Rewards Dashboard'!$D$3)>0),--(('Rewards Dashboard'!$F$3="All")+('Employee Data'!$D$2:$D$493='Rewards Dashboard'!$F$3)>0),--('Employee Data'!$D$2:$D$493=A55),--('Employee Data'!$E$2:$E$493=B55))} -> 22 | F55: {=IFERROR(SUMPRODUCT(--('Employee Data'!$I$2:$I$493>7000),--('Employee Data'!$A$2:$A$493<>""),--(('Rewards Dashboard'!$B$3="All")+('Employee Data'!$E$2:$E$493='Rewards Dashboard'!$B$3)>0),--(('Rewards Dashboard'!$D$3="All")+('Employee Data'!$C$2:$C$493='Rewards Dashboard'!$D$3)>0),--(('Rewards Dashboard'!$F$3="All")+('Employee Data'!$D$2:$D$493='Rewards Dashboard'!$F$3)>0),--('Employee Data'!$D$2:$D$493=A55),--('Employee Data'!$E$2:$E$493=B55))/E55,0)} -> 0.22727273 | H55: Operations | I55: Gurugram | J55: 129313.89 | K55: 5490.7407 | L55: 27 | M55: 0.25925926
A56: HR | B56: Gurugram | C56: {=IFERROR(SUMPRODUCT('Employee Data'!$F$2:$F$493,--('Employee Data'!$A$2:$A$493<>""),--(('Rewards Dashboard'!$B$3="All")+('Employee Data'!$E$2:$E$493='Rewards Dashboard'!$B$3)>0),--(('Rewards Dashboard'!$D$3="All")+('Employee Data'!$C$2:$C$493='Rewards Dashboard'!$D$3)>0),--(('Rewards Dashboard'!$F$3="All")+('Employee Data'!$D$2:$D$493='Rewards Dashboard'!$F$3)>0),--('Employee Data'!$D$2:$D$493=A56),--('Employee Data'!$E$2:$E$493=B56))/SUMPRODUCT(--('Employee Data'!$A$2:$A$493<>""),--(('Rewards Dashboard'!$B$3="All")+('Employee Data'!$E$2:$E$493='Rewards Dashboard'!$B$3)>0),--(('Rewards Dashboard'!$D$3="All")+('Employee Data'!$C$2:$C$493='Rewards Dashboard'!$D$3)>0),--(('Rewards Dashboard'!$F$3="All")+('Employee Data'!$D$2:$D$493='Rewards Dashboard'!$F$3)>0),--('Employee Data'!$D$2:$D$493=A56),--('Employee Data'!$E$2:$E$493=B56)),0)} -> 139907.29 | D56: {=IFERROR(SUMPRODUCT('Employee Data'!$I$2:$I$493,--('Employee Data'!$A$2:$A$493<>""),--(('Rewards Dashboard'!$B$3="All")+('Employee Data'!$E$2:$E$493='Rewards Dashboard'!$B$3)>0),--(('Rewards Dashboard'!$D$3="All")+('Employee Data'!$C$2:$C$493='Rewards Dashboard'!$D$3)>0),--(('Rewards Dashboard'!$F$3="All")+('Employee Data'!$D$2:$D$493='Rewards Dashboard'!$F$3)>0),--('Employee Data'!$D$2:$D$493=A56),--('Employee Data'!$E$2:$E$493=B56))/SUMPRODUCT(--('Employee Data'!$A$2:$A$493<>""),--(('Rewards Dashboard'!$B$3="All")+('Employee Data'!$E$2:$E$493='Rewards Dashboard'!$B$3)>0),--(('Rewards Dashboard'!$D$3="All")+('Employee Data'!$C$2:$C$493='Rewards Dashboard'!$D$3)>0),--(('Rewards Dashboard'!$F$3="All")+('Employee Data'!$D$2:$D$493='Rewards Dashboard'!$F$3)>0),--('Employee Data'!$D$2:$D$493=A56),--('Employee Data'!$E$2:$E$493=B56)),0)} -> 5064.2857 | E56: {=SUMPRODUCT(--('Employee Data'!$A$2:$A$493<>""),--(('Rewards Dashboard'!$B$3="All")+('Employee Data'!$E$2:$E$493='Rewards Dashboard'!$B$3)>0),--(('Rewards Dashboard'!$D$3="All")+('Employee Data'!$C$2:$C$493='Rewards Dashboard'!$D$3)>0),--(('Rewards Dashboard'!$F$3="All")+('Employee Data'!$D$2:$D$493='Rewards Dashboard'!$F$3)>0),--('Employee Data'!$D$2:$D$493=A56),--('Employee Data'!$E$2:$E$493=B56))} -> 21 | F56: {=IFERROR(SUMPRODUCT(--('Employee Data'!$I$2:$I$493>7000),--('Employee Data'!$A$2:$A$493<>""),--(('Rewards Dashboard'!$B$3="All")+('Employee Data'!$E$2:$E$493='Rewards Dashboard'!$B$3)>0),--(('Rewards Dashboard'!$D$3="All")+('Employee Data'!$C$2:$C$493='Rewards Dashboard'!$D$3)>0),--(('Rewards Dashboard'!$F$3="All")+('Employee Data'!$D$2:$D$493='Rewards Dashboard'!$F$3)>0),--('Employee Data'!$D$2:$D$493=A56),--('Employee Data'!$E$2:$E$493=B56))/E56,0)} -> 0.19047619
A57: Operations | B57: Gurugram | C57: {=IFERROR(SUMPRODUCT('Employee Data'!$F$2:$F$493,--('Employee Data'!$A$2:$A$493<>""),--(('Rewards Dashboard'!$B$3="All")+('Employee Data'!$E$2:$E$493='Rewards Dashboard'!$B$3)>0),--(('Rewards Dashboard'!$D$3="All")+('Employee Data'!$C$2:$C$493='Rewards Dashboard'!$D$3)>0),--(('Rewards Dashboard'!$F$3="All")+('Employee Data'!$D$2:$D$493='Rewards Dashboard'!$F$3)>0),--('Employee Data'!$D$2:$D$493=A57),--('Employee Data'!$E$2:$E$493=B57))/SUMPRODUCT(--('Employee Data'!$A$2:$A$493<>""),--(('Rewards Dashboard'!$B$3="All")+('Employee Data'!$E$2:$E$493='Rewards Dashboard'!$B$3)>0),--(('Rewards Dashboard'!$D$3="All")+('Employee Data'!$C$2:$C$493='Rewards Dashboard'!$D$3)>0),--(('Rewards Dashboard'!$F$3="All")+('Employee Data'!$D$2:$D$493='Rewards Dashboard'!$F$3)>0),--('Employee Data'!$D$2:$D$493=A57),--('Employee Data'!$E$2:$E$493=B57)),0)} -> 129313.89 | D57: {=IFERROR(SUMPRODUCT('Employee Data'!$I$2:$I$493,--('Employee Data'!$A$2:$A$493<>""),--(('Rewards Dashboard'!$B$3="All")+('Employee Data'!$E$2:$E$493='Rewards Dashboard'!$B$3)>0),--(('Rewards Dashboard'!$D$3="All")+('Employee Data'!$C$2:$C$493='Rewards Dashboard'!$D$3)>0),--(('Rewards Dashboard'!$F$3="All")+('Employee Data'!$D$2:$D$493='Rewards Dashboard'!$F$3)>0),--('Employee Data'!$D$2:$D$493=A57),--('Employee Data'!$E$2:$E$493=B57))/SUMPRODUCT(--('Employee Data'!$A$2:$A$493<>""),--(('Rewards Dashboard'!$B$3="All")+('Employee Data'!$E$2:$E$493='Rewards Dashboard'!$B$3)>0),--(('Rewards Dashboard'!$D$3="All")+('Employee Data'!$C$2:$C$493='Rewards Dashboard'!$D$3)>0),--(('Rewards Dashboard'!$F$3="All")+('Employee Data'!$D$2:$D$493='Rewards Dashboard'!$F$3)>0),--('Employee Data'!$D$2:$D$493=A57),--('Employee Data'!$E$2:$E$493=B57)),0)} -> 5490.7407 | E57: {=SUMPRODUCT(--('Employee Data'!$A$2:$A$493<>""),--(('Rewards Dashboard'!$B$3="All")+('Employee Data'!$E$2:$E$493='Rewards Dashboard'!$B$3)>0),--(('Rewards Dashboard'!$D$3="All")+('Employee Data'!$C$2:$C$493='Rewards Dashboard'!$D$3)>0),--(('Rewards Dashboard'!$F$3="All")+('Employee Data'!$D$2:$D$493='Rewards Dashboard'!$F$3)>0),--('Employee Data'!$D$2:$D$493=A57),--('Employee Data'!$E$2:$E$493=B57))} -> 27 | F57: {=IFERROR(SUMPRODUCT(--('Employee Data'!$I$2:$I$493>7000),--('Employee Data'!$A$2:$A$493<>""),--(('Rewards Dashboard'!$B$3="All")+('Employee Data'!$E$2:$E$493='Rewards Dashboard'!$B$3)>0),--(('Rewards Dashboard'!$D$3="All")+('Employee Data'!$C$2:$C$493='Rewards Dashboard'!$D$3)>0),--(('Rewards Dashboard'!$F$3="All")+('Employee Data'!$D$2:$D$493='Rewards Dashboard'!$F$3)>0),--('Employee Data'!$D$2:$D$493=A57),--('Employee Data'!$E$2:$E$493=B57))/E57,0)} -> 0.25925926
A58: Sales | B58: Gurugram | C58: {=IFERROR(SUMPRODUCT('Employee Data'!$F$2:$F$493,--('Employee Data'!$A$2:$A$493<>""),--(('Rewards Dashboard'!$B$3="All")+('Employee Data'!$E$2:$E$493='Rewards Dashboard'!$B$3)>0),--(('Rewards Dashboard'!$D$3="All")+('Employee Data'!$C$2:$C$493='Rewards Dashboard'!$D$3)>0),--(('Rewards Dashboard'!$F$3="All")+('Employee Data'!$D$2:$D$493='Rewards Dashboard'!$F$3)>0),--('Employee Data'!$D$2:$D$493=A58),--('Employee Data'!$E$2:$E$493=B58))/SUMPRODUCT(--('Employee Data'!$A$2:$A$493<>""),--(('Rewards Dashboard'!$B$3="All")+('Employee Data'!$E$2:$E$493='Rewards Dashboard'!$B$3)>0),--(('Rewards Dashboard'!$D$3="All")+('Employee Data'!$C$2:$C$493='Rewards Dashboard'!$D$3)>0),--(('Rewards Dashboard'!$F$3="All")+('Employee Data'!$D$2:$D$493='Rewards Dashboard'!$F$3)>0),--('Employee Data'!$D$2:$D$493=A58),--('Employee Data'!$E$2:$E$493=B58)),0)} -> 113461.64 | D58: {=IFERROR(SUMPRODUCT('Employee Data'!$I$2:$I$493,--('Employee Data'!$A$2:$A$493<>""),--(('Rewards Dashboard'!$B$3="All")+('Employee Data'!$E$2:$E$493='Rewards Dashboard'!$B$3)>0),--(('Rewards Dashboard'!$D$3="All")+('Employee Data'!$C$2:$C$493='Rewards Dashboard'!$D$3)>0),--(('Rewards Dashboard'!$F$3="All")+('Employee Data'!$D$2:$D$493='Rewards Dashboard'!$F$3)>0),--('Employee Data'!$D$2:$D$493=A58),--('Employee Data'!$E$2:$E$493=B58))/SUMPRODUCT(--('Employee Data'!$A$2:$A$493<>""),--(('Rewards Dashboard'!$B$3="All")+('Employee Data'!$E$2:$E$493='Rewards Dashboard'!$B$3)>0),--(('Rewards Dashboard'!$D$3="All")+('Employee Data'!$C$2:$C$493='Rewards Dashboard'!$D$3)>0),--(('Rewards Dashboard'!$F$3="All")+('Employee Data'!$D$2:$D$493='Rewards Dashboard'!$F$3)>0),--('Employee Data'!$D$2:$D$493=A58),--('Employee Data'!$E$2:$E$493=B58)),0)} -> 6062 | E58: {=SUMPRODUCT(--('Employee Data'!$A$2:$A$493<>""),--(('Rewards Dashboard'!$B$3="All")+('Employee Data'!$E$2:$E$493='Rewards Dashboard'!$B$3)>0),--(('Rewards Dashboard'!$D$3="All")+('Employee Data'!$C$2:$C$493='Rewards Dashboard'!$D$3)>0),--(('Rewards Dashboard'!$F$3="All")+('Employee Data'!$D$2:$D$493='Rewards Dashboard'!$F$3)>0),--('Employee Data'!$D$2:$D$493=A58),--('Employee Data'!$E$2:$E$493=B58))} -> 25 | F58: {=IFERROR(SUMPRODUCT(--('Employee Data'!$I$2:$I$493>7000),--('Employee Data'!$A$2:$A$493<>""),--(('Rewards Dashboard'!$B$3="All")+('Employee Data'!$E$2:$E$493='Rewards Dashboard'!$B$3)>0),--(('Rewards Dashboard'!$D$3="All")+('Employee Data'!$C$2:$C$493='Rewards Dashboard'!$D$3)>0),--(('Rewards Dashboard'!$F$3="All")+('Employee Data'!$D$2:$D$493='Rewards Dashboard'!$F$3)>0),--('Employee Data'!$D$2:$D$493=A58),--('Employee Data'!$E$2:$E$493=B58))/E58,0)} -> 0.32
A59: Tech | B59: Gurugram | C59: {=IFERROR(SUMPRODUCT('Employee Data'!$F$2:$F$493,--('Employee Data'!$A$2:$A$493<>""),--(('Rewards Dashboard'!$B$3="All")+('Employee Data'!$E$2:$E$493='Rewards Dashboard'!$B$3)>0),--(('Rewards Dashboard'!$D$3="All")+('Employee Data'!$C$2:$C$493='Rewards Dashboard'!$D$3)>0),--(('Rewards Dashboard'!$F$3="All")+('Employee Data'!$D$2:$D$493='Rewards Dashboard'!$F$3)>0),--('Employee Data'!$D$2:$D$493=A59),--('Employee Data'!$E$2:$E$493=B59))/SUMPRODUCT(--('Employee Data'!$A$2:$A$493<>""),--(('Rewards Dashboard'!$B$3="All")+('Employee Data'!$E$2:$E$493='Rewards Dashboard'!$B$3)>0),--(('Rewards Dashboard'!$D$3="All")+('Employee Data'!$C$2:$C$493='Rewards Dashboard'!$D$3)>0),--(('Rewards Dashboard'!$F$3="All")+('Employee Data'!$D$2:$D$493='Rewards Dashboard'!$F$3)>0),--('Employee Data'!$D$2:$D$493=A59),--('Employee Data'!$E$2:$E$493=B59)),0)} -> 131479.08 | D59: {=IFERROR(SUMPRODUCT('Employee Data'!$I$2:$I$493,--('Employee Data'!$A$2:$A$493<>""),--(('Rewards Dashboard'!$B$3="All")+('Employee Data'!$E$2:$E$493='Rewards Dashboard'!$B$3)>0),--(('Rewards Dashboard'!$D$3="All")+('Employee Data'!$C$2:$C$493='Rewards Dashboard'!$D$3)>0),--(('Rewards Dashboard'!$F$3="All")+('Employee Data'!$D$2:$D$493='Rewards Dashboard'!$F$3)>0),--('Employee Data'!$D$2:$D$493=A59),--('Employee Data'!$E$2:$E$493=B59))/SUMPRODUCT(--('Employee Data'!$A$2:$A$493<>""),--(('Rewards Dashboard'!$B$3="All")+('Employee Data'!$E$2:$E$493='Rewards Dashboard'!$B$3)>0),--(('Rewards Dashboard'!$D$3="All")+('Employee Data'!$C$2:$C$493='Rewards Dashboard'!$D$3)>0),--(('Rewards Dashboard'!$F$3="All")+('Employee Data'!$D$2:$D$493='Rewards Dashboard'!$F$3)>0),--('Employee Data'!$D$2:$D$493=A59),--('Employee Data'!$E$2:$E$493=B59)),0)} -> 5066 | E59: {=SUMPRODUCT(--('Employee Data'!$A$2:$A$493<>""),--(('Rewards Dashboard'!$B$3="All")+('Employee Data'!$E$2:$E$493='Rewards Dashboard'!$B$3)>0),--(('Rewards Dashboard'!$D$3="All")+('Employee Data'!$C$2:$C$493='Rewards Dashboard'!$D$3)>0),--(('Rewards Dashboard'!$F$3="All")+('Employee Data'!$D$2:$D$493='Rewards Dashboard'!$F$3)>0),--('Employee Data'!$D$2:$D$493=A59),--('Employee Data'!$E$2:$E$493=B59))} -> 25 | F59: {=IFERROR(SUMPRODUCT(--('Employee Data'!$I$2:$I$493>7000),--('Employee Data'!$A$2:$A$493<>""),--(('Rewards Dashboard'!$B$3="All")+('Employee Data'!$E$2:$E$493='Rewards Dashboard'!$B$3)>0),--(('Rewards Dashboard'!$D$3="All")+('Employee Data'!$C$2:$C$493='Rewards Dashboard'!$D$3)>0),--(('Rewards Dashboard'!$F$3="All")+('Employee Data'!$D$2:$D$493='Rewards Dashboard'!$F$3)>0),--('Employee Data'!$D$2:$D$493=A59),--('Employee Data'!$E$2:$E$493=B59))/E59,0)} -> 0.2
A60: Finance | B60: Hyderabad | C60: {=IFERROR(SUMPRODUCT('Employee Data'!$F$2:$F$493,--('Employee Data'!$A$2:$A$493<>""),--(('Rewards Dashboard'!$B$3="All")+('Employee Data'!$E$2:$E$493='Rewards Dashboard'!$B$3)>0),--(('Rewards Dashboard'!$D$3="All")+('Employee Data'!$C$2:$C$493='Rewards Dashboard'!$D$3)>0),--(('Rewards Dashboard'!$F$3="All")+('Employee Data'!$D$2:$D$493='Rewards Dashboard'!$F$3)>0),--('Employee Data'!$D$2:$D$493=A60),--('Employee Data'!$E$2:$E$493=B60))/SUMPRODUCT(--('Employee Data'!$A$2:$A$493<>""),--(('Rewards Dashboard'!$B$3="All")+('Employee Data'!$E$2:$E$493='Rewards Dashboard'!$B$3)>0),--(('Rewards Dashboard'!$D$3="All")+('Employee Data'!$C$2:$C$493='Rewards Dashboard'!$D$3)>0),--(('Rewards Dashboard'!$F$3="All")+('Employee Data'!$D$2:$D$493='Rewards Dashboard'!$F$3)>0),--('Employee Data'!$D$2:$D$493=A60),--('Employee Data'!$E$2:$E$493=B60)),0)} -> 132462.28 | D60: {=IFERROR(SUMPRODUCT('Employee Data'!$I$2:$I$493,--('Employee Data'!$A$2:$A$493<>""),--(('Rewards Dashboard'!$B$3="All")+('Employee Data'!$E$2:$E$493='Rewards Dashboard'!$B$3)>0),--(('Rewards Dashboard'!$D$3="All")+('Employee Data'!$C$2:$C$493='Rewards Dashboard'!$D$3)>0),--(('Rewards Dashboard'!$F$3="All")+('Employee Data'!$D$2:$D$493='Rewards Dashboard'!$F$3)>0),--('Employee Data'!$D$2:$D$493=A60),--('Employee Data'!$E$2:$E$493=B60))/SUMPRODUCT(--('Employee Data'!$A$2:$A$493<>""),--(('Rewards Dashboard'!$B$3="All")+('Employee Data'!$E$2:$E$493='Rewards Dashboard'!$B$3)>0),--(('Rewards Dashboard'!$D$3="All")+('Employee Data'!$C$2:$C$493='Rewards Dashboard'!$D$3)>0),--(('Rewards Dashboard'!$F$3="All")+('Employee Data'!$D$2:$D$493='Rewards Dashboard'!$F$3)>0),--('Employee Data'!$D$2:$D$493=A60),--('Employee Data'!$E$2:$E$493=B60)),0)} -> 5944.8276 | E60: {=SUMPRODUCT(--('Employee Data'!$A$2:$A$493<>""),--(('Rewards Dashboard'!$B$3="All")+('Employee Data'!$E$2:$E$493='Rewards Dashboard'!$B$3)>0),--(('Rewards Dashboard'!$D$3="All")+('Employee Data'!$C$2:$C$493='Rewards Dashboard'!$D$3)>0),--(('Rewards Dashboard'!$F$3="All")+('Employee Data'!$D$2:$D$493='Rewards Dashboard'!$F$3)>0),--('Employee Data'!$D$2:$D$493=A60),--('Employee Data'!$E$2:$E$493=B60))} -> 29 | F60: {=IFERROR(SUMPRODUCT(--('Employee Data'!$I$2:$I$493>7000),--('Employee Data'!$A$2:$A$493<>""),--(('Rewards Dashboard'!$B$3="All")+('Employee Data'!$E$2:$E$493='Rewards Dashboard'!$B$3)>0),--(('Rewards Dashboard'!$D$3="All")+('Employee Data'!$C$2:$C$493='Rewards Dashboard'!$D$3)>0),--(('Rewards Dashboard'!$F$3="All")+('Employee Data'!$D$2:$D$493='Rewards Dashboard'!$F$3)>0),--('Employee Data'!$D$2:$D$493=A60),--('Employee Data'!$E$2:$E$493=B60))/E60,0)} -> 0.34482759
...

Sheet Basic Analysis
A1: Headcount | B1: Department | I1: Headcount | J1: Location
A2: Band/ Gender | B2: Finance | C2: HR | D2: Operations | E2: Sales | F2: Tech | G2: Grand Total | I2: Band/ Gender | J2: Bengaluru | K2: Gurugram | L2: Hyderabad | M2: Noida | N2: Grand Total
A3: Junior | B3: 19 | C3: 17 | D3: 23 | E3: 38 | F3: 27 | G3: 124 | I3: Junior | J3: 26 | K3: 35 | L3: 43 | M3: 20 | N3: 124
A4: Lead | B4: 23 | C4: 25 | D4: 22 | E4: 24 | F4: 28 | G4: 122 | I4: Lead | J4: 24 | K4: 27 | L4: 30 | M4: 41 | N4: 122
A5: Mid | B5: 29 | C5: 21 | D5: 27 | E5: 22 | F5: 24 | G5: 123 | I5: Mid | J5: 28 | K5: 29 | L5: 34 | M5: 32 | N5: 123
A6: Senior | B6: 26 | C6: 25 | D6: 25 | E6: 25 | F6: 22 | G6: 123 | I6: Senior | J6: 32 | K6: 29 | L6: 33 | M6: 29 | N6: 123
A7: Grand Total | B7: 97 | C7: 88 | D7: 97 | E7: 109 | F7: 101 | G7: 492 | I7: Grand Total | J7: 110 | K7: 120 | L7: 140 | M7: 122 | N7: 492
B9: Band/ Monthly Salary | K9: Salary Band/ Gender | L9: Headcount | M9: Gender % | N9: Monthly Salary % | O9: Total Monthly Salary
B10: Junior | D10: Lead | F10: Mid | H10: Senior | K10: Junior | L10: 124 | M10: 0.25203252 | N10: 0.11433413 | O10: 7350717
A11: Department | B11: Max Salary | C11: Min Salary | D11: Max Salary | E11: Min Salary | F11: Max Salary | G11: Min Salary | H11: Max Salary | I11: Min Salary | K11: Lead | L11: 122 | M11: 0.24796748 | N11: 0.38898749 | O11: 25008603
A12: Finance | B12: 81759 | C12: 37523 | D12: 233215 | E12: 182728 | F12: 127240 | G12: 84024 | H12: 171102 | I12: 129557 | K12: Mid | L12: 123 | M12: 0.25 | N12: 0.2031377 | O12: 13060035
A13: HR | B13: 80260 | C13: 37141 | D13: 232995 | E13: 180363 | F13: 125231 | G13: 83783 | H13: 178932 | I13: 130746 | K13: Senior | L13: 123 | M13: 0.25 | N13: 0.29354068 | O13: 18872181
A14: Operations | B14: 81702 | C14: 39239 | D14: 227850 | E14: 179298 | F14: 126047 | G14: 82771 | H14: 176905 | I14: 133788 | K14: Grand Total | L14: 492 | M14: 1 | N14: 1 | O14: 64291536
A15: Sales | B15: 82315 | C15: 37116 | D15: 231891 | E15: 179542 | F15: 127306 | G15: 83408 | H15: 178690 | I15: 132030
A16: Tech | B16: 81837 | C16: 37654 | D16: 230347 | E16: 178969 | F16: 129037 | G16: 85748 | H16: 178002 | I16: 130087
A17: Grand Total | B17: 82315 | C17: 37116 | D17: 233215 | E17: 178969 | F17: 129037 | G17: 82771 | H17: 178932 | I17: 129557
A20: Insurance Tier | B20: Count | D20: Gender | E20: Sum of Monthly Base Salary (INR) | F20: Sum of Monthly Base Salary (INR)2
A21: Bronze | B21: 59 | D21: Female | E21: 0.4321614 | F21: 27784320
A22: Gold | B22: 216 | D22: Male | E22: 0.56154765 | F22: 36102761
A23: Silver | B23: 217 | D23: Transgender | E23: 0.0062909525 | F23: 404455
A24: Grand Total | B24: 492 | D24: Grand Total | E24: 1 | F24: 64291536
B27: Salary Band
B28: Female | D28: Male | F28: Total Average Salary | G28: Total Count of Monthly Base Salary (INR)
A29: Gender | B29: Average Salary | C29: Count of Monthly Base Salary (INR) | D29: Average Salary | E29: Count of Monthly Base Salary (INR)
A30: Junior | B30: 58605.621 | C30: 66 | D30: 60047.345 | E30: 58 | F30: 59279.976 | G30: 124
A31: Mid | B31: 106884.82 | C31: 55 | D31: 105455.64 | E31: 67 | F31: 106099.94 | G31: 122
A32: Senior | B32: 151651.42 | C32: 59 | D32: 155421.52 | E32: 62 | F32: 153583.21 | G32: 121
A33: Lead | B33: 206596.59 | C33: 44 | D33: 204081.45 | E33: 78 | F33: 204988.55 | G33: 122
A34: Grand Total | B34: 124037.14 | C34: 224 | D34: 136236.83 | E34: 265 | F34: 130648.43 | G34: 489
A37: Band | B37: Gap % | C37: Female Share % | D37: Male Share %
A38: Raw ( Company-wide) | B38: 0.093378017 | C38: =C34/G34 -> 0.45807771 | D38: 0.54192229
A39: Junior | B39: =(D30-B30)/D30 -> 0.024009781 | C39: =$C30/$G30 -> 0.53225806 | D39: 0.46774194
A40: Mid | B40: =(D31-B31)/D31 -> -0.013552394 | C40: =$C31/$G31 -> 0.45081967 | D40: 0.54918033
A41: Senior | B41: =(D32-B32)/D32 -> 0.02425721 | C41: =$C32/$G32 -> 0.48760331 | D41: 0.63934426
A42: Lead | B42: =(D33-B33)/D33 -> -0.012324208 | C42: =$C33/$G33 -> 0.36065574 | D42: 0.51239669

Sheet Rewards & Benefits Allocation
A1: Department | B1: Headcount | C1: Total Monthly Premium Cost | D1: Average Salary | E1: High-Cost Employee % | G1: Average of Monthly Premiums | H1: Locations
A2: Bengaluru | G2: Department | H2: Bengaluru | I2: Gurugram | J2: Hyderabad | K2: Noida | L2: Grand Total
A3: Finance | B3: 22 | C3: 108400 | D3: 121773.86 | E3: 0.18181818 | G3: Finance | H3: 4927.2727 | I3: 5190.9091 | J3: 5944.8276 | K3: 5785.4167 | L3: 5503.6082
A4: HR | B4: 19 | C4: 104300 | D4: 137245.47 | E4: 0.26315789 | G4: HR | H4: 5489.4737 | I4: 5064.2857 | J4: 4819.2308 | K4: 4577.2727 | L4: 4961.9318
A5: Operations | B5: 19 | C5: 79650 | D5: 148077.74 | E5: 0.21052632 | G5: Operations | H5: 4192.1053 | I5: 5490.7407 | J5: 5475 | K5: 5140 | L5: 5141.7526
A6: Sales | B6: 25 | C6: 135750 | D6: 125504.2 | E6: 0.2 | G6: Sales | H6: 5430 | I6: 6062 | J6: 5268.5714 | K6: 5293.75 | L6: 5493.1193
A7: Tech | B7: 25 | C7: 129350 | D7: 128991.12 | E7: 0.16 | G7: Tech | H7: 5174 | I7: 5066 | J7: 4591.6667 | K7: 5511.1111 | L7: 5099.0099
A8: Gurugram | G8: Grand Total | H8: 5067.7273 | I8: 5391.6667 | J8: 5247.5 | K8: 5277.8689 | L8: 5250
A9: Finance | B9: 22 | C9: 114200 | D9: 118022.5 | E9: 0.22727273
A10: HR | B10: 21 | C10: 106350 | D10: 139907.29 | E10: 0.19047619
A11: Operations | B11: 27 | C11: 148250 | D11: 129313.89 | E11: 0.25925926
A12: Sales | B12: 25 | C12: 151550 | D12: 113461.64 | E12: 0.32
A13: Tech | B13: 25 | C13: 126650 | D13: 131479.08 | E13: 0.2
A14: Hyderabad
A15: Finance | B15: 29 | C15: 172400 | D15: 132462.28 | E15: 0.34482759
A16: HR | B16: 26 | C16: 125300 | D16: 130150.08 | E16: 0.19230769
A17: Operations | B17: 26 | C17: 142350 | D17: 116854.31 | E17: 0.30769231
A18: Sales | B18: 35 | C18: 184400 | D18: 110408.23 | E18: 0.22857143
A19: Tech | B19: 24 | C19: 110200 | D19: 130166.62 | E19: 0.25
A20: Noida
A21: Finance | B21: 24 | C21: 138850 | D21: 157452.21 | E21: 0.25
A22: HR | B22: 22 | C22: 100700 | D22: 147247.77 | E22: 0.18181818
A23: Operations | B23: 25 | C23: 128500 | D23: 132747.92 | E23: 0.16
A24: Sales | B24: 24 | C24: 127050 | D24: 141647.96 | E24: 0.29166667
A25: Tech | B25: 27 | C25: 148800 | D25: 136706.89 | E25: 0.22222222
A26: Grand Total | B26: 492 | C26: 2583000 | D26: 130673.85 | E26: 0.23373984

Sheet Gender Pay Equity
A1: Gender Pay Gap | B1: Column Labels
A2: Row Labels | B2: Junior | C2: Lead | D2: Mid | E2: Senior | F2: Grand Total
A3: Finance | B3: -1914.1477 | C3: 645.74603 | D3: -9131.4103 | E3: 3400.9097 | F3: 13956.744
A4: HR | B4: -3919.0833 | C4: -9621.3442 | D4: 19018.75 | E4: -6106.0649 | F4: 2846.9302
A5: Operations | B5: -6200.5455 | C5: -5564.875 | D5: -6024.044 | E5: 14464.786 | F5: 7322.0557
A6: Sales | B6: 8647.8068 | C6: 11512.289 | D6: -5826.5167 | E6: 9911.487 | F6: 19986.901
A7: Tech | B7: 3801.15 | C7: -7848.4286 | D7: -259.25 | E7: -3039.9808 | F7: 14463.618
A8: Grand Total | B8: 1441.7236 | C8: -2515.1422 | D8: -1429.1764 | E8: 3770.0924 | F8: 12199.691
A10: Average of Monthly Base Salary (INR) | B10: Column Labels | E10: Each band's gap is under 3% of that band's average, and the direction flips (women ahead in three bands, men ahead in one). This pattern is consistent with normal variation rather than a systematic gap — no band shows a one-sided, consistent disadvantage for either gender. | H10: Average of Monthly Base Salary (INR)
A11: Row Labels | B11: Female | C11: Male | D11: Gap (M-F) | H11: Salary Band | I11: Female | J11: Male | K11: Gap (M-F)
A12: Junior | B12: 58605.621 | C12: 60047.345 | D12: =B12-C12 -> -1441.7236 | H12: Junior | I12: 62039.327 | J12: 59809.779 | K12: 2229.5479
A13: Lead | B13: 206596.59 | C13: 204081.45 | D13: =B13-C13 -> 2515.1422 | H13: Lead | I13: 184793.39 | J13: 187465.94 | K13: -2672.5515
A14: Mid | B14: 106884.82 | C14: 105455.64 | D14: =B14-C14 -> 1429.1764 | H14: Mid | I14: 95928.466 | J14: 93651.092 | K14: 2277.3732
A15: Senior | B15: 151651.42 | C15: 155421.52 | D15: =B15-C15 -> -3770.0924 | H15: Senior | I15: 132606.52 | J15: 131052.97 | K15: 1553.5495
A16: Grand Total | B16: 124037.14 | C16: 136236.83 | D16: =B16-C16 -> -12199.691 | H16: Grand Total | I16: 117664.59 | J16: 118712.07 | K16: -1047.4824
A18: Note: The Transgender group is too small for standalone statistical comparison and is excluded from the gender pay analysis below — noted here as a scope limitation, not an omission.

Sheet Vendor Map Data
A1: Internal Department | B1: Vendor Survey Job Code | C1: Vendor Global Group Name | D1: Industry Peer Segment
A2: Tech | B2: IN-TECH-04 | C2: High-Value Technical Core | D2: Technology / Energy
A3: Operations | B3: IN-OPS-02 | C3: Core Operations Specialist | D3: Industrial Operations
A4: Sales | B4: IN-SLS-01 | C4: Field Sales Execution | D4: Commercial & Retail
A5: Finance | B5: IN-FIN-03 | C5: Corporate Finance Core | D5: Shared Services
A6: HR | B6: IN-HR-02 | C6: Corporate Talent Admin | D6: Shared Services

Sheet Query_Audit_Exceptions
A1: Employee ID | B1: Full Name | C1: Gender | D1: Department | E1: Location | F1: Monthly Base Salary (INR) | G1: Corporate Benefit Plan | H1: Insurance tier | I1: Monthly Premiums | J1: Salary Bracket | K1: Salary Tier | L1: Vendor Survey Job Code | M1: Vendor Global Group Name

Sheet Employee Data
A1: Employee ID | B1: Full Name | C1: Gender | D1: Department | E1: Location | F1: Monthly Base Salary (INR) | G1: Corporate Benefit Plan | H1: Insurance tier | I1: Monthly Premiums | J1: Salary Bracket | K1: Salary Tier | L1: Vendor Survey Job Code | M1: Vendor Global Group Name | O1: Min | P1: =MIN(F:F) -> 37116 | Q1: Max | R1: =MAX(F:F) -> 233215
A2: Emp1011 | B2: Philip Dias | C2: Male | D2: Operations | E2: Hyderabad | F2: 99610 | G2: Family Floater | H2: Gold | I2: 6750 | J2: Between 50k and 200k | K2: Mid | L2: IN-OPS-02 | M2: Core Operations Specialist | O2: Range of Salary | P2: =R1-P1 -> 196099
A3: Emp1337 | B3: Kaif Pathan | C3: Male | D3: Operations | E3: Gurugram | F3: 99367 | G3: Family Floater | H3: Gold | I3: 6750 | J3: Between 50k and 200k | K3: Mid | L3: IN-OPS-02 | M3: Core Operations Specialist | O3: IQR | P3: =_xlfn.QUARTILE.INC(Indian_Employee_Data[Monthly Base Salary (INR)],1) - _xlfn.QUARTILE.INC(Indian_Employee_Data[Monthly Base Salary (INR)],) -> 45195.5
A4: Emp1399 | B4: Karma Lepcha | C4: Male | D4: Operations | E4: Hyderabad | F4: 96746 | G4: Parents Included | H4: Gold | I4: 9000 | J4: Between 50k and 200k | K4: Mid | L4: IN-OPS-02 | M4: Core Operations Specialist | O4: Outlier check | P4: Lower bound | Q4: Upper Bound
A5: Emp1358 | B5: Nongthombam Nongthombam | C5: Male | D5: Operations | E5: Noida | F5: 98251 | G5: Parents Included | H5: Gold | I5: 9000 | J5: Between 50k and 200k | K5: Mid | L5: IN-OPS-02 | M5: Core Operations Specialist | P5: =_xlfn.QUARTILE.INC(Indian_Employee_Data[Monthly Base Salary (INR)],1) - (1.5*$P$3) -> 14518.25 | Q5: =_xlfn.QUARTILE.INC(Indian_Employee_Data[Monthly Base Salary (INR)],3) - (1.5*$P$3) -> 110957.25
A6: Emp1396 | B6: Kersi Anand | C6: Male | D6: Sales | E6: Bengaluru | F6: 101272 | G6: Family Floater | H6: Gold | I6: 6750 | J6: Between 50k and 200k | K6: Mid | L6: IN-SLS-01 | M6: Field Sales Execution | P6: No Low Outliers | Q6: High Outliers Exist
A7: Emp1382 | B7: Gursharan Dhaliwal | C7: Male | D7: Finance | E7: Noida | F7: 100499 | G7: Family Floater | H7: Gold | I7: 6750 | J7: Between 50k and 200k | K7: Mid | L7: IN-FIN-03 | M7: Corporate Finance Core
