Workbook
Name Slicer_Department: #N/A
Name Slicer_Gender: #N/A
Name Slicer_Location: #N/A

Sheet Cover
A1: Rewards & Benefits Analytics Dashboard
A2: McKinsey-style executive view using live formulas, pivots, and all employee records.
A4: CONTENTS | B4: DESCRIPTION
A5: Rewards Dashboard | B5: Interactive executive dashboard with filters, KPI cards, charts, benchmarking table, and narrative insights.
A6: Employee Data | B6: Source employee table used for the live dashboard calculations.
A7: Rewards & Benefits Allocation | B7: Existing pivot allocation view used as a validation source for premium and high-cost totals.
A8: Gender Pay Equity | B8: Existing gender pay pivot analysis referenced in the pay-gap visualization.
A9: Basic Analysis | B9: Existing pivot-table workbook analysis supporting the dashboard.
A10: Dashboard Data | B10: Hidden helper sheet with live formulas feeding dashboard charts.

Sheet Rewards Dashboard
A1: Rewards operations dashboard
A2: Interactive rewards, benefits, pay equity and benchmarking view — change filters to refresh KPIs, charts and table.
A3: Location | B3: All | C3: Gender | D3: All | E3: Department | F3: All | H3: Source: Demo Data created with 492 rows | J3: Source: Demo Data created with 492 rows
A5: Headcount | D5: Avg salary | G5: Total premium | J5: High-cost %
A6: =GETPIVOTDATA("[Measures].[Headcount]",'Rewards & Benefits Allocation'!$A$1) -> 492 | D6: =GETPIVOTDATA("[Measures].[Average Salary]",'Rewards & Benefits Allocation'!$A$1) -> 118675.04 | G6: =GETPIVOTDATA("[Measures].[Total Monthly Premium Cost]",'Rewards & Benefits Allocation'!$A$1) -> 2583000 | J6: =GETPIVOTDATA("[Measures].[High-Cost Employee %]",'Rewards & Benefits Allocation'!$A$1) -> 0.23373984
A10: AVG PREMIUM BY DEPARTMENT X LOCATION | H10: PLAN MIX BY TIER
A27: HEADCOUNT BY DEPARTMENT | H27: GENDER PAY GAP BY SALARY BAND
A44: BENCHMARKING SUBMISSION VIEW
A45: Department | B45: Location | C45: Avg salary | D45: Avg premium | E45: Headcount | F45: High-cost % | H45: Story in brief: High-cost employees are defined as employees with monthly premiums over ₹7,000. Under this threshold, high-premium benefit combinations are the main cost concentration. Use the filters above to isolate a city, gender, or department; every KPI, chart and benchmarking row recalculates from the employee-level source table.
A46: ='Helper Sheet'!H50 -> Finance | B46: ='Helper Sheet'!I50 -> Hyderabad | C46: ='Helper Sheet'!J50 -> 128885.24 | D46: ='Helper Sheet'!K50 -> 5944.8276 | E46: ='Helper Sheet'!L50 -> 29 | F46: ='Helper Sheet'!M50 -> 0.34482759
A47: ='Helper Sheet'!H51 -> Sales | B47: ='Helper Sheet'!I51 -> Gurugram | C47: ='Helper Sheet'!J51 -> 134835.56 | D47: ='Helper Sheet'!K51 -> 6062 | E47: ='Helper Sheet'!L51 -> 25 | F47: ='Helper Sheet'!M51 -> 0.32
A48: ='Helper Sheet'!H52 -> Operations | B48: ='Helper Sheet'!I52 -> Hyderabad | C48: ='Helper Sheet'!J52 -> 130724.81 | D48: ='Helper Sheet'!K52 -> 5475 | E48: ='Helper Sheet'!L52 -> 26 | F48: ='Helper Sheet'!M52 -> 0.30769231
A49: ='Helper Sheet'!H53 -> Sales | B49: ='Helper Sheet'!I53 -> Noida | C49: ='Helper Sheet'!J53 -> 110101.08 | D49: ='Helper Sheet'!K53 -> 5293.75 | E49: ='Helper Sheet'!L53 -> 24 | F49: ='Helper Sheet'!M53 -> 0.29166667
A50: ='Helper Sheet'!H54 -> HR | B50: ='Helper Sheet'!I54 -> Bengaluru | C50: ='Helper Sheet'!J54 -> 131595.95 | D50: ='Helper Sheet'!K54 -> 5489.4737 | E50: ='Helper Sheet'!L54 -> 19 | F50: ='Helper Sheet'!M54 -> 0.26315789
A51: ='Helper Sheet'!H55 -> Operations | B51: ='Helper Sheet'!I55 -> Gurugram | C51: ='Helper Sheet'!J55 -> 117910.11 | D51: ='Helper Sheet'!K55 -> 5490.7407 | E51: ='Helper Sheet'!L55 -> 27 | F51: ='Helper Sheet'!M55 -> 0.25925926
A56: RAW DATA TABLE
A57: Raw data table: the dashboard is powered by `Employee Data` rows with validated Location, Department, Gender, Insurance tier and Corporate Benefit Plan fields. The hidden `Dashboard Data` helper sheet holds live formulas that feed the charts; source records remain on the original data sheet.

Sheet Helper Sheet
A1: Locations | B1: Genders | C1: Departments | D1: Tiers | E1: Plans | F1: Salary Bands
A2: All | B2: All | C2: All | D2: Bronze | E2: Individual | F2: Junior
A3: Bengaluru | B3: Female | C3: Finance | D3: Silver | E3: Family Floater | F3: Mid
A4: Gurugram | B4: Male | C4: HR | D4: Gold | E4: Parents Included | F4: Senior
A5: Hyderabad | B5: Transgender | C5: Operations | F5: Lead
A6: Noida | C6: Sales
C7: Tech
A11: Department | B11: Bengaluru | C11: Gurugram | D11: Hyderabad | E11: Noida
A12: Finance | B12: =IF(OR('Rewards Dashboard'!$B$3="All",'Rewards Dashboard'!$B$3=B$11),IF(OR('Rewards Dashboard'!$F$3="All",'Rewards Dashboard'!$F$3=$A12),IFERROR(AVERAGEIFS('Employee Data'!$I$2:$I$493,'Employee Data'!$D$2:$D$493,$A12,'Employee Data'!$E$2:$E$493,B$11,'Employee Data'!$C$2:$C$493,IF('Rewards Dashboard'!$D$3="All","*",'Rewards Dashboard'!$D$3)),NA()),NA()),NA()) -> 4927.2727 | C12: =IF(OR('Rewards Dashboard'!$B$3="All",'Rewards Dashboard'!$B$3=C$11),IF(OR('Rewards Dashboard'!$F$3="All",'Rewards Dashboard'!$F$3=$A12),IFERROR(AVERAGEIFS('Employee Data'!$I$2:$I$493,'Employee Data'!$D$2:$D$493,$A12,'Employee Data'!$E$2:$E$493,C$11,'Employee Data'!$C$2:$C$493,IF('Rewards Dashboard'!$D$3="All","*",'Rewards Dashboard'!$D$3)),NA()),NA()),NA()) -> 5190.9091 | D12: =IF(OR('Rewards Dashboard'!$B$3="All",'Rewards Dashboard'!$B$3=D$11),IF(OR('Rewards Dashboard'!$F$3="All",'Rewards Dashboard'!$F$3=$A12),IFERROR(AVERAGEIFS('Employee Data'!$I$2:$I$493,'Employee Data'!$D$2:$D$493,$A12,'Employee Data'!$E$2:$E$493,D$11,'Employee Data'!$C$2:$C$493,IF('Rewards Dashboard'!$D$3="All","*",'Rewards Dashboard'!$D$3)),NA()),NA()),NA()) -> 5944.8276 | E12: =IF(OR('Rewards Dashboard'!$B$3="All",'Rewards Dashboard'!$B$3=E$11),IF(OR('Rewards Dashboard'!$F$3="All",'Rewards Dashboard'!$F$3=$A12),IFERROR(AVERAGEIFS('Employee Data'!$I$2:$I$493,'Employee Data'!$D$2:$D$493,$A12,'Employee Data'!$E$2:$E$493,E$11,'Employee Data'!$C$2:$C$493,IF('Rewards Dashboard'!$D$3="All","*",'Rewards Dashboard'!$D$3)),NA()),NA()),NA()) -> 5785.4167
A13: HR | B13: =IF(OR('Rewards Dashboard'!$B$3="All",'Rewards Dashboard'!$B$3=B$11),IF(OR('Rewards Dashboard'!$F$3="All",'Rewards Dashboard'!$F$3=$A13),IFERROR(AVERAGEIFS('Employee Data'!$I$2:$I$493,'Employee Data'!$D$2:$D$493,$A13,'Employee Data'!$E$2:$E$493,B$11,'Employee Data'!$C$2:$C$493,IF('Rewards Dashboard'!$D$3="All","*",'Rewards Dashboard'!$D$3)),NA()),NA()),NA()) -> 5489.4737 | C13: =IF(OR('Rewards Dashboard'!$B$3="All",'Rewards Dashboard'!$B$3=C$11),IF(OR('Rewards Dashboard'!$F$3="All",'Rewards Dashboard'!$F$3=$A13),IFERROR(AVERAGEIFS('Employee Data'!$I$2:$I$493,'Employee Data'!$D$2:$D$493,$A13,'Employee Data'!$E$2:$E$493,C$11,'Employee Data'!$C$2:$C$493,IF('Rewards Dashboard'!$D$3="All","*",'Rewards Dashboard'!$D$3)),NA()),NA()),NA()) -> 5064.2857 | D13: =IF(OR('Rewards Dashboard'!$B$3="All",'Rewards Dashboard'!$B$3=D$11),IF(OR('Rewards Dashboard'!$F$3="All",'Rewards Dashboard'!$F$3=$A13),IFERROR(AVERAGEIFS('Employee Data'!$I$2:$I$493,'Employee Data'!$D$2:$D$493,$A13,'Employee Data'!$E$2:$E$493,D$11,'Employee Data'!$C$2:$C$493,IF('Rewards Dashboard'!$D$3="All","*",'Rewards Dashboard'!$D$3)),NA()),NA()),NA()) -> 4819.2308 | E13: =IF(OR('Rewards Dashboard'!$B$3="All",'Rewards Dashboard'!$B$3=E$11),IF(OR('Rewards Dashboard'!$F$3="All",'Rewards Dashboard'!$F$3=$A13),IFERROR(AVERAGEIFS('Employee Data'!$I$2:$I$493,'Employee Data'!$D$2:$D$493,$A13,'Employee Data'!$E$2:$E$493,E$11,'Employee Data'!$C$2:$C$493,IF('Rewards Dashboard'!$D$3="All","*",'Rewards Dashboard'!$D$3)),NA()),NA()),NA()) -> 4577.2727
A14: Operations | B14: =IF(OR('Rewards Dashboard'!$B$3="All",'Rewards Dashboard'!$B$3=B$11),IF(OR('Rewards Dashboard'!$F$3="All",'Rewards Dashboard'!$F$3=$A14),IFERROR(AVERAGEIFS('Employee Data'!$I$2:$I$493,'Employee Data'!$D$2:$D$493,$A14,'Employee Data'!$E$2:$E$493,B$11,'Employee Data'!$C$2:$C$493,IF('Rewards Dashboard'!$D$3="All","*",'Rewards Dashboard'!$D$3)),NA()),NA()),NA()) -> 4192.1053 | C14: =IF(OR('Rewards Dashboard'!$B$3="All",'Rewards Dashboard'!$B$3=C$11),IF(OR('Rewards Dashboard'!$F$3="All",'Rewards Dashboard'!$F$3=$A14),IFERROR(AVERAGEIFS('Employee Data'!$I$2:$I$493,'Employee Data'!$D$2:$D$493,$A14,'Employee Data'!$E$2:$E$493,C$11,'Employee Data'!$C$2:$C$493,IF('Rewards Dashboard'!$D$3="All","*",'Rewards Dashboard'!$D$3)),NA()),NA()),NA()) -> 5490.7407 | D14: =IF(OR('Rewards Dashboard'!$B$3="All",'Rewards Dashboard'!$B$3=D$11),IF(OR('Rewards Dashboard'!$F$3="All",'Rewards Dashboard'!$F$3=$A14),IFERROR(AVERAGEIFS('Employee Data'!$I$2:$I$493,'Employee Data'!$D$2:$D$493,$A14,'Employee Data'!$E$2:$E$493,D$11,'Employee Data'!$C$2:$C$493,IF('Rewards Dashboard'!$D$3="All","*",'Rewards Dashboard'!$D$3)),NA()),NA()),NA()) -> 5475 | E14: =IF(OR('Rewards Dashboard'!$B$3="All",'Rewards Dashboard'!$B$3=E$11),IF(OR('Rewards Dashboard'!$F$3="All",'Rewards Dashboard'!$F$3=$A14),IFERROR(AVERAGEIFS('Employee Data'!$I$2:$I$493,'Employee Data'!$D$2:$D$493,$A14,'Employee Data'!$E$2:$E$493,E$11,'Employee Data'!$C$2:$C$493,IF('Rewards Dashboard'!$D$3="All","*",'Rewards Dashboard'!$D$3)),NA()),NA()),NA()) -> 5140
A15: Sales | B15: =IF(OR('Rewards Dashboard'!$B$3="All",'Rewards Dashboard'!$B$3=B$11),IF(OR('Rewards Dashboard'!$F$3="All",'Rewards Dashboard'!$F$3=$A15),IFERROR(AVERAGEIFS('Employee Data'!$I$2:$I$493,'Employee Data'!$D$2:$D$493,$A15,'Employee Data'!$E$2:$E$493,B$11,'Employee Data'!$C$2:$C$493,IF('Rewards Dashboard'!$D$3="All","*",'Rewards Dashboard'!$D$3)),NA()),NA()),NA()) -> 5430 | C15: =IF(OR('Rewards Dashboard'!$B$3="All",'Rewards Dashboard'!$B$3=C$11),IF(OR('Rewards Dashboard'!$F$3="All",'Rewards Dashboard'!$F$3=$A15),IFERROR(AVERAGEIFS('Employee Data'!$I$2:$I$493,'Employee Data'!$D$2:$D$493,$A15,'Employee Data'!$E$2:$E$493,C$11,'Employee Data'!$C$2:$C$493,IF('Rewards Dashboard'!$D$3="All","*",'Rewards Dashboard'!$D$3)),NA()),NA()),NA()) -> 6062 | D15: =IF(OR('Rewards Dashboard'!$B$3="All",'Rewards Dashboard'!$B$3=D$11),IF(OR('Rewards Dashboard'!$F$3="All",'Rewards Dashboard'!$F$3=$A15),IFERROR(AVERAGEIFS('Employee Data'!$I$2:$I$493,'Employee Data'!$D$2:$D$493,$A15,'Employee Data'!$E$2:$E$493,D$11,'Employee Data'!$C$2:$C$493,IF('Rewards Dashboard'!$D$3="All","*",'Rewards Dashboard'!$D$3)),NA()),NA()),NA()) -> 5268.5714 | E15: =IF(OR('Rewards Dashboard'!$B$3="All",'Rewards Dashboard'!$B$3=E$11),IF(OR('Rewards Dashboard'!$F$3="All",'Rewards Dashboard'!$F$3=$A15),IFERROR(AVERAGEIFS('Employee Data'!$I$2:$I$493,'Employee Data'!$D$2:$D$493,$A15,'Employee Data'!$E$2:$E$493,E$11,'Employee Data'!$C$2:$C$493,IF('Rewards Dashboard'!$D$3="All","*",'Rewards Dashboard'!$D$3)),NA()),NA()),NA()) -> 5293.75
A16: Tech | B16: =IF(OR('Rewards Dashboard'!$B$3="All",'Rewards Dashboard'!$B$3=B$11),IF(OR('Rewards Dashboard'!$F$3="All",'Rewards Dashboard'!$F$3=$A16),IFERROR(AVERAGEIFS('Employee Data'!$I$2:$I$493,'Employee Data'!$D$2:$D$493,$A16,'Employee Data'!$E$2:$E$493,B$11,'Employee Data'!$C$2:$C$493,IF('Rewards Dashboard'!$D$3="All","*",'Rewards Dashboard'!$D$3)),NA()),NA()),NA()) -> 5174 | C16: =IF(OR('Rewards Dashboard'!$B$3="All",'Rewards Dashboard'!$B$3=C$11),IF(OR('Rewards Dashboard'!$F$3="All",'Rewards Dashboard'!$F$3=$A16),IFERROR(AVERAGEIFS('Employee Data'!$I$2:$I$493,'Employee Data'!$D$2:$D$493,$A16,'Employee Data'!$E$2:$E$493,C$11,'Employee Data'!$C$2:$C$493,IF('Rewards Dashboard'!$D$3="All","*",'Rewards Dashboard'!$D$3)),NA()),NA()),NA()) -> 5066 | D16: =IF(OR('Rewards Dashboard'!$B$3="All",'Rewards Dashboard'!$B$3=D$11),IF(OR('Rewards Dashboard'!$F$3="All",'Rewards Dashboard'!$F$3=$A16),IFERROR(AVERAGEIFS('Employee Data'!$I$2:$I$493,'Employee Data'!$D$2:$D$493,$A16,'Employee Data'!$E$2:$E$493,D$11,'Employee Data'!$C$2:$C$493,IF('Rewards Dashboard'!$D$3="All","*",'Rewards Dashboard'!$D$3)),NA()),NA()),NA()) -> 4591.6667 | E16: =IF(OR('Rewards Dashboard'!$B$3="All",'Rewards Dashboard'!$B$3=E$11),IF(OR('Rewards Dashboard'!$F$3="All",'Rewards Dashboard'!$F$3=$A16),IFERROR(AVERAGEIFS('Employee Data'!$I$2:$I$493,'Employee Data'!$D$2:$D$493,$A16,'Employee Data'!$E$2:$E$493,E$11,'Employee Data'!$C$2:$C$493,IF('Rewards Dashboard'!$D$3="All","*",'Rewards Dashboard'!$D$3)),NA()),NA()),NA()) -> 5511.1111
A21: Insurance tier | B21: Headcount
A22: Bronze | B22: {=SUMPRODUCT(--('Employee Data'!$A$2:$A$493<>""),--(('Rewards Dashboard'!$B$3="All")+('Employee Data'!$E$2:$E$493='Rewards Dashboard'!$B$3)>0),--(('Rewards Dashboard'!$D$3="All")+('Employee Data'!$C$2:$C$493='Rewards Dashboard'!$D$3)>0),--(('Rewards Dashboard'!$F$3="All")+('Employee Data'!$D$2:$D$493='Rewards Dashboard'!$F$3)>0),--('Employee Data'!$H$2:$H$493=A22))} -> 59
A23: Silver | B23: {=SUMPRODUCT(--('Employee Data'!$A$2:$A$493<>""),--(('Rewards Dashboard'!$B$3="All")+('Employee Data'!$E$2:$E$493='Rewards Dashboard'!$B$3)>0),--(('Rewards Dashboard'!$D$3="All")+('Employee Data'!$C$2:$C$493='Rewards Dashboard'!$D$3)>0),--(('Rewards Dashboard'!$F$3="All")+('Employee Data'!$D$2:$D$493='Rewards Dashboard'!$F$3)>0),--('Employee Data'!$H$2:$H$493=A23))} -> 217
A24: Gold | B24: {=SUMPRODUCT(--('Employee Data'!$A$2:$A$493<>""),--(('Rewards Dashboard'!$B$3="All")+('Employee Data'!$E$2:$E$493='Rewards Dashboard'!$B$3)>0),--(('Rewards Dashboard'!$D$3="All")+('Employee Data'!$C$2:$C$493='Rewards Dashboard'!$D$3)>0),--(('Rewards Dashboard'!$F$3="All")+('Employee Data'!$D$2:$D$493='Rewards Dashboard'!$F$3)>0),--('Employee Data'!$H$2:$H$493=A24))} -> 216
A29: Department | B29: Headcount
A30: Finance | B30: {=IF(OR('Rewards Dashboard'!$F$3="All",'Rewards Dashboard'!$F$3=A30),SUMPRODUCT(--('Employee Data'!$A$2:$A$493<>""),--(('Rewards Dashboard'!$B$3="All")+('Employee Data'!$E$2:$E$493='Rewards Dashboard'!$B$3)>0),--(('Rewards Dashboard'!$D$3="All")+('Employee Data'!$C$2:$C$493='Rewards Dashboard'!$D$3)>0),--('Employee Data'!$D$2:$D$493=A30)),NA())} -> 97
A31: HR | B31: {=IF(OR('Rewards Dashboard'!$F$3="All",'Rewards Dashboard'!$F$3=A31),SUMPRODUCT(--('Employee Data'!$A$2:$A$493<>""),--(('Rewards Dashboard'!$B$3="All")+('Employee Data'!$E$2:$E$493='Rewards Dashboard'!$B$3)>0),--(('Rewards Dashboard'!$D$3="All")+('Employee Data'!$C$2:$C$493='Rewards Dashboard'!$D$3)>0),--('Employee Data'!$D$2:$D$493=A31)),NA())} -> 88
A32: Operations | B32: {=IF(OR('Rewards Dashboard'!$F$3="All",'Rewards Dashboard'!$F$3=A32),SUMPRODUCT(--('Employee Data'!$A$2:$A$493<>""),--(('Rewards Dashboard'!$B$3="All")+('Employee Data'!$E$2:$E$493='Rewards Dashboard'!$B$3)>0),--(('Rewards Dashboard'!$D$3="All")+('Employee Data'!$C$2:$C$493='Rewards Dashboard'!$D$3)>0),--('Employee Data'!$D$2:$D$493=A32)),NA())} -> 97
A33: Sales | B33: {=IF(OR('Rewards Dashboard'!$F$3="All",'Rewards Dashboard'!$F$3=A33),SUMPRODUCT(--('Employee Data'!$A$2:$A$493<>""),--(('Rewards Dashboard'!$B$3="All")+('Employee Data'!$E$2:$E$493='Rewards Dashboard'!$B$3)>0),--(('Rewards Dashboard'!$D$3="All")+('Employee Data'!$C$2:$C$493='Rewards Dashboard'!$D$3)>0),--('Employee Data'!$D$2:$D$493=A33)),NA())} -> 109
A34: Tech | B34: {=IF(OR('Rewards Dashboard'!$F$3="All",'Rewards Dashboard'!$F$3=A34),SUMPRODUCT(--('Employee Data'!$A$2:$A$493<>""),--(('Rewards Dashboard'!$B$3="All")+('Employee Data'!$E$2:$E$493='Rewards Dashboard'!$B$3)>0),--(('Rewards Dashboard'!$D$3="All")+('Employee Data'!$C$2:$C$493='Rewards Dashboard'!$D$3)>0),--('Employee Data'!$D$2:$D$493=A34)),NA())} -> 101
A39: Salary band | B39: Gap (M-F)
A40: ='Gender Pay Equity'!H12 -> Junior | B40: ='Gender Pay Equity'!K12 -> 2229.5479
A41: ='Gender Pay Equity'!H13 -> Lead | B41: ='Gender Pay Equity'!K13 -> -2672.5515
A42: ='Gender Pay Equity'!H14 -> Mid | B42: ='Gender Pay Equity'!K14 -> 2277.3732
A43: ='Gender Pay Equity'!H15 -> Senior | B43: ='Gender Pay Equity'!K15 -> 1553.5495
A49: Department | B49: Location | C49: Avg salary | D49: Avg premium | E49: Headcount | F49: High-cost % | H49: Department | I49: Location | J49: Avg salary | K49: Avg premium | L49: Headcount | M49: High-cost %
A50: Finance | B50: Bengaluru | C50: {=IFERROR(SUMPRODUCT('Employee Data'!$F$2:$F$493,--('Employee Data'!$A$2:$A$493<>""),--(('Rewards Dashboard'!$B$3="All")+('Employee Data'!$E$2:$E$493='Rewards Dashboard'!$B$3)>0),--(('Rewards Dashboard'!$D$3="All")+('Employee Data'!$C$2:$C$493='Rewards Dashboard'!$D$3)>0),--(('Rewards Dashboard'!$F$3="All")+('Employee Data'!$D$2:$D$493='Rewards Dashboard'!$F$3)>0),--('Employee Data'!$D$2:$D$493=A50),--('Employee Data'!$E$2:$E$493=B50))/SUMPRODUCT(--('Employee Data'!$A$2:$A$493<>""),--(('Rewards Dashboard'!$B$3="All")+('Employee Data'!$E$2:$E$493='Rewards Dashboard'!$B$3)>0),--(('Rewards Dashboard'!$D$3="All")+('Employee Data'!$C$2:$C$493='Rewards Dashboard'!$D$3)>0),--(('Rewards Dashboard'!$F$3="All")+('Employee Data'!$D$2:$D$493='Rewards Dashboard'!$F$3)>0),--('Employee Data'!$D$2:$D$493=A50),--('Employee Data'!$E$2:$E$493=B50)),0)} -> 115477.86 | D50: {=IFERROR(SUMPRODUCT('Employee Data'!$I$2:$I$493,--('Employee Data'!$A$2:$A$493<>""),--(('Rewards Dashboard'!$B$3="All")+('Employee Data'!$E$2:$E$493='Rewards Dashboard'!$B$3)>0),--(('Rewards Dashboard'!$D$3="All")+('Employee Data'!$C$2:$C$493='Rewards Dashboard'!$D$3)>0),--(('Rewards Dashboard'!$F$3="All")+('Employee Data'!$D$2:$D$493='Rewards Dashboard'!$F$3)>0),--('Employee Data'!$D$2:$D$493=A50),--('Employee Data'!$E$2:$E$493=B50))/SUMPRODUCT(--('Employee Data'!$A$2:$A$493<>""),--(('Rewards Dashboard'!$B$3="All")+('Employee Data'!$E$2:$E$493='Rewards Dashboard'!$B$3)>0),--(('Rewards Dashboard'!$D$3="All")+('Employee Data'!$C$2:$C$493='Rewards Dashboard'!$D$3)>0),--(('Rewards Dashboard'!$F$3="All")+('Employee Data'!$D$2:$D$493='Rewards Dashboard'!$F$3)>0),--('Employee Data'!$D$2:$D$493=A50),--('Employee Data'!$E$2:$E$493=B50)),0)} -> 4927.2727 | E50: {=SUMPRODUCT(--('Employee Data'!$A$2:$A$493<>""),--(('Rewards Dashboard'!$B$3="All")+('Employee Data'!$E$2:$E$493='Rewards Dashboard'!$B$3)>0),--(('Rewards Dashboard'!$D$3="All")+('Employee Data'!$C$2:$C$493='Rewards Dashboard'!$D$3)>0),--(('Rewards Dashboard'!$F$3="All")+('Employee Data'!$D$2:$D$493='Rewards Dashboard'!$F$3)>0),--('Employee Data'!$D$2:$D$493=A50),--('Employee Data'!$E$2:$E$493=B50))} -> 22 | F50: {=IFERROR(SUMPRODUCT(--('Employee Data'!$I$2:$I$493>7000),--('Employee Data'!$A$2:$A$493<>""),--(('Rewards Dashboard'!$B$3="All")+('Employee Data'!$E$2:$E$493='Rewards Dashboard'!$B$3)>0),--(('Rewards Dashboard'!$D$3="All")+('Employee Data'!$C$2:$C$493='Rewards Dashboard'!$D$3)>0),--(('Rewards Dashboard'!$F$3="All")+('Employee Data'!$D$2:$D$493='Rewards Dashboard'!$F$3)>0),--('Employee Data'!$D$2:$D$493=A50),--('Employee Data'!$E$2:$E$493=B50))/E50,0)} -> 0.18181818 | H50: {=_xlfn.TAKE(_xlfn.SORTBY(_xlfn._xlws.FILTER($A$50:$F$69,$E$50:$E$69>0),_xlfn._xlws.FILTER($F$50:$F$69,$E$50:$E$69>0),-1,_xlfn._xlws.FILTER($D$50:$D$69,$E$50:$E$69>0),-1),6)} -> Finance | I50: Hyderabad | J50: 128885.24 | K50: 5944.8276 | L50: 29 | M50: 0.34482759
A51: HR | B51: Bengaluru | C51: {=IFERROR(SUMPRODUCT('Employee Data'!$F$2:$F$493,--('Employee Data'!$A$2:$A$493<>""),--(('Rewards Dashboard'!$B$3="All")+('Employee Data'!$E$2:$E$493='Rewards Dashboard'!$B$3)>0),--(('Rewards Dashboard'!$D$3="All")+('Employee Data'!$C$2:$C$493='Rewards Dashboard'!$D$3)>0),--(('Rewards Dashboard'!$F$3="All")+('Employee Data'!$D$2:$D$493='Rewards Dashboard'!$F$3)>0),--('Employee Data'!$D$2:$D$493=A51),--('Employee Data'!$E$2:$E$493=B51))/SUMPRODUCT(--('Employee Data'!$A$2:$A$493<>""),--(('Rewards Dashboard'!$B$3="All")+('Employee Data'!$E$2:$E$493='Rewards Dashboard'!$B$3)>0),--(('Rewards Dashboard'!$D$3="All")+('Employee Data'!$C$2:$C$493='Rewards Dashboard'!$D$3)>0),--(('Rewards Dashboard'!$F$3="All")+('Employee Data'!$D$2:$D$493='Rewards Dashboard'!$F$3)>0),--('Employee Data'!$D$2:$D$493=A51),--('Employee Data'!$E$2:$E$493=B51)),0)} -> 131595.95 | D51: {=IFERROR(SUMPRODUCT('Employee Data'!$I$2:$I$493,--('Employee Data'!$A$2:$A$493<>""),--(('Rewards Dashboard'!$B$3="All")+('Employee Data'!$E$2:$E$493='Rewards Dashboard'!$B$3)>0),--(('Rewards Dashboard'!$D$3="All")+('Employee Data'!$C$2:$C$493='Rewards Dashboard'!$D$3)>0),--(('Rewards Dashboard'!$F$3="All")+('Employee Data'!$D$2:$D$493='Rewards Dashboard'!$F$3)>0),--('Employee Data'!$D$2:$D$493=A51),--('Employee Data'!$E$2:$E$493=B51))/SUMPRODUCT(--('Employee Data'!$A$2:$A$493<>""),--(('Rewards Dashboard'!$B$3="All")+('Employee Data'!$E$2:$E$493='Rewards Dashboard'!$B$3)>0),--(('Rewards Dashboard'!$D$3="All")+('Employee Data'!$C$2:$C$493='Rewards Dashboard'!$D$3)>0),--(('Rewards Dashboard'!$F$3="All")+('Employee Data'!$D$2:$D$493='Rewards Dashboard'!$F$3)>0),--('Employee Data'!$D$2:$D$493=A51),--('Employee Data'!$E$2:$E$493=B51)),0)} -> 5489.4737 | E51: {=SUMPRODUCT(--('Employee Data'!$A$2:$A$493<>""),--(('Rewards Dashboard'!$B$3="All")+('Employee Data'!$E$2:$E$493='Rewards Dashboard'!$B$3)>0),--(('Rewards Dashboard'!$D$3="All")+('Employee Data'!$C$2:$C$493='Rewards Dashboard'!$D$3)>0),--(('Rewards Dashboard'!$F$3="All")+('Employee Data'!$D$2:$D$493='Rewards Dashboard'!$F$3)>0),--('Employee Data'!$D$2:$D$493=A51),--('Employee Data'!$E$2:$E$493=B51))} -> 19 | F51: {=IFERROR(SUMPRODUCT(--('Employee Data'!$I$2:$I$493>7000),--('Employee Data'!$A$2:$A$493<>""),--(('Rewards Dashboard'!$B$3="All")+('Employee Data'!$E$2:$E$493='Rewards Dashboard'!$B$3)>0),--(('Rewards Dashboard'!$D$3="All")+('Employee Data'!$C$2:$C$493='Rewards Dashboard'!$D$3)>0),--(('Rewards Dashboard'!$F$3="All")+('Employee Data'!$D$2:$D$493='Rewards Dashboard'!$F$3)>0),--('Employee Data'!$D$2:$D$493=A51),--('Employee Data'!$E$2:$E$493=B51))/E51,0)} -> 0.26315789 | H51: Sales | I51: Gurugram | J51: 134835.56 | K51: 6062 | L51: 25 | M51: 0.32
A52: Operations | B52: Bengaluru | C52: {=IFERROR(SUMPRODUCT('Employee Data'!$F$2:$F$493,--('Employee Data'!$A$2:$A$493<>""),--(('Rewards Dashboard'!$B$3="All")+('Employee Data'!$E$2:$E$493='Rewards Dashboard'!$B$3)>0),--(('Rewards Dashboard'!$D$3="All")+('Employee Data'!$C$2:$C$493='Rewards Dashboard'!$D$3)>0),--(('Rewards Dashboard'!$F$3="All")+('Employee Data'!$D$2:$D$493='Rewards Dashboard'!$F$3)>0),--('Employee Data'!$D$2:$D$493=A52),--('Employee Data'!$E$2:$E$493=B52))/SUMPRODUCT(--('Employee Data'!$A$2:$A$493<>""),--(('Rewards Dashboard'!$B$3="All")+('Employee Data'!$E$2:$E$493='Rewards Dashboard'!$B$3)>0),--(('Rewards Dashboard'!$D$3="All")+('Employee Data'!$C$2:$C$493='Rewards Dashboard'!$D$3)>0),--(('Rewards Dashboard'!$F$3="All")+('Employee Data'!$D$2:$D$493='Rewards Dashboard'!$F$3)>0),--('Employee Data'!$D$2:$D$493=A52),--('Employee Data'!$E$2:$E$493=B52)),0)} -> 102408.47 | D52: {=IFERROR(SUMPRODUCT('Employee Data'!$I$2:$I$493,--('Employee Data'!$A$2:$A$493<>""),--(('Rewards Dashboard'!$B$3="All")+('Employee Data'!$E$2:$E$493='Rewards Dashboard'!$B$3)>0),--(('Rewards Dashboard'!$D$3="All")+('Employee Data'!$C$2:$C$493='Rewards Dashboard'!$D$3)>0),--(('Rewards Dashboard'!$F$3="All")+('Employee Data'!$D$2:$D$493='Rewards Dashboard'!$F$3)>0),--('Employee Data'!$D$2:$D$493=A52),--('Employee Data'!$E$2:$E$493=B52))/SUMPRODUCT(--('Employee Data'!$A$2:$A$493<>""),--(('Rewards Dashboard'!$B$3="All")+('Employee Data'!$E$2:$E$493='Rewards Dashboard'!$B$3)>0),--(('Rewards Dashboard'!$D$3="All")+('Employee Data'!$C$2:$C$493='Rewards Dashboard'!$D$3)>0),--(('Rewards Dashboard'!$F$3="All")+('Employee Data'!$D$2:$D$493='Rewards Dashboard'!$F$3)>0),--('Employee Data'!$D$2:$D$493=A52),--('Employee Data'!$E$2:$E$493=B52)),0)} -> 4192.1053 | E52: {=SUMPRODUCT(--('Employee Data'!$A$2:$A$493<>""),--(('Rewards Dashboard'!$B$3="All")+('Employee Data'!$E$2:$E$493='Rewards Dashboard'!$B$3)>0),--(('Rewards Dashboard'!$D$3="All")+('Employee Data'!$C$2:$C$493='Rewards Dashboard'!$D$3)>0),--(('Rewards Dashboard'!$F$3="All")+('Employee Data'!$D$2:$D$493='Rewards Dashboard'!$F$3)>0),--('Employee Data'!$D$2:$D$493=A52),--('Employee Data'!$E$2:$E$493=B52))} -> 19 | F52: {=IFERROR(SUMPRODUCT(--('Employee Data'!$I$2:$I$493>7000),--('Employee Data'!$A$2:$A$493<>""),--(('Rewards Dashboard'!$B$3="All")+('Employee Data'!$E$2:$E$493='Rewards Dashboard'!$B$3)>0),--(('Rewards Dashboard'!$D$3="All")+('Employee Data'!$C$2:$C$493='Rewards Dashboard'!$D$3)>0),--(('Rewards Dashboard'!$F$3="All")+('Employee Data'!$D$2:$D$493='Rewards Dashboard'!$F$3)>0),--('Employee Data'!$D$2:$D$493=A52),--('Employee Data'!$E$2:$E$493=B52))/E52,0)} -> 0.21052632 | H52: Operations | I52: Hyderabad | J52: 130724.81 | K52: 5475 | L52: 26 | M52: 0.30769231
A53: Sales | B53: Bengaluru | C53: {=IFERROR(SUMPRODUCT('Employee Data'!$F$2:$F$493,--('Employee Data'!$A$2:$A$493<>""),--(('Rewards Dashboard'!$B$3="All")+('Employee Data'!$E$2:$E$493='Rewards Dashboard'!$B$3)>0),--(('Rewards Dashboard'!$D$3="All")+('Employee Data'!$C$2:$C$493='Rewards Dashboard'!$D$3)>0),--(('Rewards Dashboard'!$F$3="All")+('Employee Data'!$D$2:$D$493='Rewards Dashboard'!$F$3)>0),--('Employee Data'!$D$2:$D$493=A53),--('Employee Data'!$E$2:$E$493=B53))/SUMPRODUCT(--('Employee Data'!$A$2:$A$493<>""),--(('Rewards Dashboard'!$B$3="All")+('Employee Data'!$E$2:$E$493='Rewards Dashboard'!$B$3)>0),--(('Rewards Dashboard'!$D$3="All")+('Employee Data'!$C$2:$C$493='Rewards Dashboard'!$D$3)>0),--(('Rewards Dashboard'!$F$3="All")+('Employee Data'!$D$2:$D$493='Rewards Dashboard'!$F$3)>0),--('Employee Data'!$D$2:$D$493=A53),--('Employee Data'!$E$2:$E$493=B53)),0)} -> 125256.52 | D53: {=IFERROR(SUMPRODUCT('Employee Data'!$I$2:$I$493,--('Employee Data'!$A$2:$A$493<>""),--(('Rewards Dashboard'!$B$3="All")+('Employee Data'!$E$2:$E$493='Rewards Dashboard'!$B$3)>0),--(('Rewards Dashboard'!$D$3="All")+('Employee Data'!$C$2:$C$493='Rewards Dashboard'!$D$3)>0),--(('Rewards Dashboard'!$F$3="All")+('Employee Data'!$D$2:$D$493='Rewards Dashboard'!$F$3)>0),--('Employee Data'!$D$2:$D$493=A53),--('Employee Data'!$E$2:$E$493=B53))/SUMPRODUCT(--('Employee Data'!$A$2:$A$493<>""),--(('Rewards Dashboard'!$B$3="All")+('Employee Data'!$E$2:$E$493='Rewards Dashboard'!$B$3)>0),--(('Rewards Dashboard'!$D$3="All")+('Employee Data'!$C$2:$C$493='Rewards Dashboard'!$D$3)>0),--(('Rewards Dashboard'!$F$3="All")+('Employee Data'!$D$2:$D$493='Rewards Dashboard'!$F$3)>0),--('Employee Data'!$D$2:$D$493=A53),--('Employee Data'!$E$2:$E$493=B53)),0)} -> 5430 | E53: {=SUMPRODUCT(--('Employee Data'!$A$2:$A$493<>""),--(('Rewards Dashboard'!$B$3="All")+('Employee Data'!$E$2:$E$493='Rewards Dashboard'!$B$3)>0),--(('Rewards Dashboard'!$D$3="All")+('Employee Data'!$C$2:$C$493='Rewards Dashboard'!$D$3)>0),--(('Rewards Dashboard'!$F$3="All")+('Employee Data'!$D$2:$D$493='Rewards Dashboard'!$F$3)>0),--('Employee Data'!$D$2:$D$493=A53),--('Employee Data'!$E$2:$E$493=B53))} -> 25 | F53: {=IFERROR(SUMPRODUCT(--('Employee Data'!$I$2:$I$493>7000),--('Employee Data'!$A$2:$A$493<>""),--(('Rewards Dashboard'!$B$3="All")+('Employee Data'!$E$2:$E$493='Rewards Dashboard'!$B$3)>0),--(('Rewards Dashboard'!$D$3="All")+('Employee Data'!$C$2:$C$493='Rewards Dashboard'!$D$3)>0),--(('Rewards Dashboard'!$F$3="All")+('Employee Data'!$D$2:$D$493='Rewards Dashboard'!$F$3)>0),--('Employee Data'!$D$2:$D$493=A53),--('Employee Data'!$E$2:$E$493=B53))/E53,0)} -> 0.2 | H53: Sales | I53: Noida | J53: 110101.08 | K53: 5293.75 | L53: 24 | M53: 0.29166667
A54: Tech | B54: Bengaluru | C54: {=IFERROR(SUMPRODUCT('Employee Data'!$F$2:$F$493,--('Employee Data'!$A$2:$A$493<>""),--(('Rewards Dashboard'!$B$3="All")+('Employee Data'!$E$2:$E$493='Rewards Dashboard'!$B$3)>0),--(('Rewards Dashboard'!$D$3="All")+('Employee Data'!$C$2:$C$493='Rewards Dashboard'!$D$3)>0),--(('Rewards Dashboard'!$F$3="All")+('Employee Data'!$D$2:$D$493='Rewards Dashboard'!$F$3)>0),--('Employee Data'!$D$2:$D$493=A54),--('Employee Data'!$E$2:$E$493=B54))/SUMPRODUCT(--('Employee Data'!$A$2:$A$493<>""),--(('Rewards Dashboard'!$B$3="All")+('Employee Data'!$E$2:$E$493='Rewards Dashboard'!$B$3)>0),--(('Rewards Dashboard'!$D$3="All")+('Employee Data'!$C$2:$C$493='Rewards Dashboard'!$D$3)>0),--(('Rewards Dashboard'!$F$3="All")+('Employee Data'!$D$2:$D$493='Rewards Dashboard'!$F$3)>0),--('Employee Data'!$D$2:$D$493=A54),--('Employee Data'!$E$2:$E$493=B54)),0)} -> 122661.32 | D54: {=IFERROR(SUMPRODUCT('Employee Data'!$I$2:$I$493,--('Employee Data'!$A$2:$A$493<>""),--(('Rewards Dashboard'!$B$3="All")+('Employee Data'!$E$2:$E$493='Rewards Dashboard'!$B$3)>0),--(('Rewards Dashboard'!$D$3="All")+('Employee Data'!$C$2:$C$493='Rewards Dashboard'!$D$3)>0),--(('Rewards Dashboard'!$F$3="All")+('Employee Data'!$D$2:$D$493='Rewards Dashboard'!$F$3)>0),--('Employee Data'!$D$2:$D$493=A54),--('Employee Data'!$E$2:$E$493=B54))/SUMPRODUCT(--('Employee Data'!$A$2:$A$493<>""),--(('Rewards Dashboard'!$B$3="All")+('Employee Data'!$E$2:$E$493='Rewards Dashboard'!$B$3)>0),--(('Rewards Dashboard'!$D$3="All")+('Employee Data'!$C$2:$C$493='Rewards Dashboard'!$D$3)>0),--(('Rewards Dashboard'!$F$3="All")+('Employee Data'!$D$2:$D$493='Rewards Dashboard'!$F$3)>0),--('Employee Data'!$D$2:$D$493=A54),--('Employee Data'!$E$2:$E$493=B54)),0)} -> 5174 | E54: {=SUMPRODUCT(--('Employee Data'!$A$2:$A$493<>""),--(('Rewards Dashboard'!$B$3="All")+('Employee Data'!$E$2:$E$493='Rewards Dashboard'!$B$3)>0),--(('Rewards Dashboard'!$D$3="All")+('Employee Data'!$C$2:$C$493='Rewards Dashboard'!$D$3)>0),--(('Rewards Dashboard'!$F$3="All")+('Employee Data'!$D$2:$D$493='Rewards Dashboard'!$F$3)>0),--('Employee Data'!$D$2:$D$493=A54),--('Employee Data'!$E$2:$E$493=B54))} -> 25 | F54: {=IFERROR(SUMPRODUCT(--('Employee Data'!$I$2:$I$493>7000),--('Employee Data'!$A$2:$A$493<>""),--(('Rewards Dashboard'!$B$3="All")+('Employee Data'!$E$2:$E$493='Rewards Dashboard'!$B$3)>0),--(('Rewards Dashboard'!$D$3="All")+('Employee Data'!$C$2:$C$493='Rewards Dashboard'!$D$3)>0),--(('Rewards Dashboard'!$F$3="All")+('Employee Data'!$D$2:$D$493='Rewards Dashboard'!$F$3)>0),--('Employee Data'!$D$2:$D$493=A54),--('Employee Data'!$E$2:$E$493=B54))/E54,0)} -> 0.16 | H54: HR | I54: Bengaluru | J54: 131595.95 | K54: 5489.4737 | L54: 19 | M54: 0.26315789
A55: Finance | B55: Gurugram | C55: {=IFERROR(SUMPRODUCT('Employee Data'!$F$2:$F$493,--('Employee Data'!$A$2:$A$493<>""),--(('Rewards Dashboard'!$B$3="All")+('Employee Data'!$E$2:$E$493='Rewards Dashboard'!$B$3)>0),--(('Rewards Dashboard'!$D$3="All")+('Employee Data'!$C$2:$C$493='Rewards Dashboard'!$D$3)>0),--(('Rewards Dashboard'!$F$3="All")+('Employee Data'!$D$2:$D$493='Rewards Dashboard'!$F$3)>0),--('Employee Data'!$D$2:$D$493=A55),--('Employee Data'!$E$2:$E$493=B55))/SUMPRODUCT(--('Employee Data'!$A$2:$A$493<>""),--(('Rewards Dashboard'!$B$3="All")+('Employee Data'!$E$2:$E$493='Rewards Dashboard'!$B$3)>0),--(('Rewards Dashboard'!$D$3="All")+('Employee Data'!$C$2:$C$493='Rewards Dashboard'!$D$3)>0),--(('Rewards Dashboard'!$F$3="All")+('Employee Data'!$D$2:$D$493='Rewards Dashboard'!$F$3)>0),--('Employee Data'!$D$2:$D$493=A55),--('Employee Data'!$E$2:$E$493=B55)),0)} -> 113401.59 | D55: {=IFERROR(SUMPRODUCT('Employee Data'!$I$2:$I$493,--('Employee Data'!$A$2:$A$493<>""),--(('Rewards Dashboard'!$B$3="All")+('Employee Data'!$E$2:$E$493='Rewards Dashboard'!$B$3)>0),--(('Rewards Dashboard'!$D$3="All")+('Employee Data'!$C$2:$C$493='Rewards Dashboard'!$D$3)>0),--(('Rewards Dashboard'!$F$3="All")+('Employee Data'!$D$2:$D$493='Rewards Dashboard'!$F$3)>0),--('Employee Data'!$D$2:$D$493=A55),--('Employee Data'!$E$2:$E$493=B55))/SUMPRODUCT(--('Employee Data'!$A$2:$A$493<>""),--(('Rewards Dashboard'!$B$3="All")+('Employee Data'!$E$2:$E$493='Rewards Dashboard'!$B$3)>0),--(('Rewards Dashboard'!$D$3="All")+('Employee Data'!$C$2:$C$493='Rewards Dashboard'!$D$3)>0),--(('Rewards Dashboard'!$F$3="All")+('Employee Data'!$D$2:$D$493='Rewards Dashboard'!$F$3)>0),--('Employee Data'!$D$2:$D$493=A55),--('Employee Data'!$E$2:$E$493=B55)),0)} -> 5190.9091 | E55: {=SUMPRODUCT(--('Employee Data'!$A$2:$A$493<>""),--(('Rewards Dashboard'!$B$3="All")+('Employee Data'!$E$2:$E$493='Rewards Dashboard'!$B$3)>0),--(('Rewards Dashboard'!$D$3="All")+('Employee Data'!$C$2:$C$493='Rewards Dashboard'!$D$3)>0),--(('Rewards Dashboard'!$F$3="All")+('Employee Data'!$D$2:$D$493='Rewards Dashboard'!$F$3)>0),--('Employee Data'!$D$2:$D$493=A55),--('Employee Data'!$E$2:$E$493=B55))} -> 22 | F55: {=IFERROR(SUMPRODUCT(--('Employee Data'!$I$2:$I$493>7000),--('Employee Data'!$A$2:$A$493<>""),--(('Rewards Dashboard'!$B$3="All")+('Employee Data'!$E$2:$E$493='Rewards Dashboard'!$B$3)>0),--(('Rewards Dashboard'!$D$3="All")+('Employee Data'!$C$2:$C$493='Rewards Dashboard'!$D$3)>0),--(('Rewards Dashboard'!$F$3="All")+('Employee Data'!$D$2:$D$493='Rewards Dashboard'!$F$3)>0),--('Employee Data'!$D$2:$D$493=A55),--('Employee Data'!$E$2:$E$493=B55))/E55,0)} -> 0.22727273 | H55: Operations | I55: Gurugram | J55: 117910.11 | K55: 5490.7407 | L55: 27 | M55: 0.25925926
A56: HR | B56: Gurugram | C56: {=IFERROR(SUMPRODUCT('Employee Data'!$F$2:$F$493,--('Employee Data'!$A$2:$A$493<>""),--(('Rewards Dashboard'!$B$3="All")+('Employee Data'!$E$2:$E$493='Rewards Dashboard'!$B$3)>0),--(('Rewards Dashboard'!$D$3="All")+('Employee Data'!$C$2:$C$493='Rewards Dashboard'!$D$3)>0),--(('Rewards Dashboard'!$F$3="All")+('Employee Data'!$D$2:$D$493='Rewards Dashboard'!$F$3)>0),--('Employee Data'!$D$2:$D$493=A56),--('Employee Data'!$E$2:$E$493=B56))/SUMPRODUCT(--('Employee Data'!$A$2:$A$493<>""),--(('Rewards Dashboard'!$B$3="All")+('Employee Data'!$E$2:$E$493='Rewards Dashboard'!$B$3)>0),--(('Rewards Dashboard'!$D$3="All")+('Employee Data'!$C$2:$C$493='Rewards Dashboard'!$D$3)>0),--(('Rewards Dashboard'!$F$3="All")+('Employee Data'!$D$2:$D$493='Rewards Dashboard'!$F$3)>0),--('Employee Data'!$D$2:$D$493=A56),--('Employee Data'!$E$2:$E$493=B56)),0)} -> 117717.62 | D56: {=IFERROR(SUMPRODUCT('Employee Data'!$I$2:$I$493,--('Employee Data'!$A$2:$A$493<>""),--(('Rewards Dashboard'!$B$3="All")+('Employee Data'!$E$2:$E$493='Rewards Dashboard'!$B$3)>0),--(('Rewards Dashboard'!$D$3="All")+('Employee Data'!$C$2:$C$493='Rewards Dashboard'!$D$3)>0),--(('Rewards Dashboard'!$F$3="All")+('Employee Data'!$D$2:$D$493='Rewards Dashboard'!$F$3)>0),--('Employee Data'!$D$2:$D$493=A56),--('Employee Data'!$E$2:$E$493=B56))/SUMPRODUCT(--('Employee Data'!$A$2:$A$493<>""),--(('Rewards Dashboard'!$B$3="All")+('Employee Data'!$E$2:$E$493='Rewards Dashboard'!$B$3)>0),--(('Rewards Dashboard'!$D$3="All")+('Employee Data'!$C$2:$C$493='Rewards Dashboard'!$D$3)>0),--(('Rewards Dashboard'!$F$3="All")+('Employee Data'!$D$2:$D$493='Rewards Dashboard'!$F$3)>0),--('Employee Data'!$D$2:$D$493=A56),--('Employee Data'!$E$2:$E$493=B56)),0)} -> 5064.2857 | E56: {=SUMPRODUCT(--('Employee Data'!$A$2:$A$493<>""),--(('Rewards Dashboard'!$B$3="All")+('Employee Data'!$E$2:$E$493='Rewards Dashboard'!$B$3)>0),--(('Rewards Dashboard'!$D$3="All")+('Employee Data'!$C$2:$C$493='Rewards Dashboard'!$D$3)>0),--(('Rewards Dashboard'!$F$3="All")+('Employee Data'!$D$2:$D$493='Rewards Dashboard'!$F$3)>0),--('Employee Data'!$D$2:$D$493=A56),--('Employee Data'!$E$2:$E$493=B56))} -> 21 | F56: {=IFERROR(SUMPRODUCT(--('Employee Data'!$I$2:$I$493>7000),--('Employee Data'!$A$2:$A$493<>""),--(('Rewards Dashboard'!$B$3="All")+('Employee Data'!$E$2:$E$493='Rewards Dashboard'!$B$3)>0),--(('Rewards Dashboard'!$D$3="All")+('Employee Data'!$C$2:$C$493='Rewards Dashboard'!$D$3)>0),--(('Rewards Dashboard'!$F$3="All")+('Employee Data'!$D$2:$D$493='Rewards Dashboard'!$F$3)>0),--('Employee Data'!$D$2:$D$493=A56),--('Employee Data'!$E$2:$E$493=B56))/E56,0)} -> 0.19047619
A57: Operations | B57: Gurugram | C57: {=IFERROR(SUMPRODUCT('Employee Data'!$F$2:$F$493,--('Employee Data'!$A$2:$A$493<>""),--(('Rewards Dashboard'!$B$3="All")+('Employee Data'!$E$2:$E$493='Rewards Dashboard'!$B$3)>0),--(('Rewards Dashboard'!$D$3="All")+('Employee Data'!$C$2:$C$493='Rewards Dashboard'!$D$3)>0),--(('Rewards Dashboard'!$F$3="All")+('Employee Data'!$D$2:$D$493='Rewards Dashboard'!$F$3)>0),--('Employee Data'!$D$2:$D$493=A57),--('Employee Data'!$E$2:$E$493=B57))/SUMPRODUCT(--('Employee Data'!$A$2:$A$493<>""),--(('Rewards Dashboard'!$B$3="All")+('Employee Data'!$E$2:$E$493='Rewards Dashboard'!$B$3)>0),--(('Rewards Dashboard'!$D$3="All")+('Employee Data'!$C$2:$C$493='Rewards Dashboard'!$D$3)>0),--(('Rewards Dashboard'!$F$3="All")+('Employee Data'!$D$2:$D$493='Rewards Dashboard'!$F$3)>0),--('Employee Data'!$D$2:$D$493=A57),--('Employee Data'!$E$2:$E$493=B57)),0)} -> 117910.11 | D57: {=IFERROR(SUMPRODUCT('Employee Data'!$I$2:$I$493,--('Employee Data'!$A$2:$A$493<>""),--(('Rewards Dashboard'!$B$3="All")+('Employee Data'!$E$2:$E$493='Rewards Dashboard'!$B$3)>0),--(('Rewards Dashboard'!$D$3="All")+('Employee Data'!$C$2:$C$493='Rewards Dashboard'!$D$3)>0),--(('Rewards Dashboard'!$F$3="All")+('Employee Data'!$D$2:$D$493='Rewards Dashboard'!$F$3)>0),--('Employee Data'!$D$2:$D$493=A57),--('Employee Data'!$E$2:$E$493=B57))/SUMPRODUCT(--('Employee Data'!$A$2:$A$493<>""),--(('Rewards Dashboard'!$B$3="All")+('Employee Data'!$E$2:$E$493='Rewards Dashboard'!$B$3)>0),--(('Rewards Dashboard'!$D$3="All")+('Employee Data'!$C$2:$C$493='Rewards Dashboard'!$D$3)>0),--(('Rewards Dashboard'!$F$3="All")+('Employee Data'!$D$2:$D$493='Rewards Dashboard'!$F$3)>0),--('Employee Data'!$D$2:$D$493=A57),--('Employee Data'!$E$2:$E$493=B57)),0)} -> 5490.7407 | E57: {=SUMPRODUCT(--('Employee Data'!$A$2:$A$493<>""),--(('Rewards Dashboard'!$B$3="All")+('Employee Data'!$E$2:$E$493='Rewards Dashboard'!$B$3)>0),--(('Rewards Dashboard'!$D$3="All")+('Employee Data'!$C$2:$C$493='Rewards Dashboard'!$D$3)>0),--(('Rewards Dashboard'!$F$3="All")+('Employee Data'!$D$2:$D$493='Rewards Dashboard'!$F$3)>0),--('Employee Data'!$D$2:$D$493=A57),--('Employee Data'!$E$2:$E$493=B57))} -> 27 | F57: {=IFERROR(SUMPRODUCT(--('Employee Data'!$I$2:$I$493>7000),--('Employee Data'!$A$2:$A$493<>""),--(('Rewards Dashboard'!$B$3="All")+('Employee Data'!$E$2:$E$493='Rewards Dashboard'!$B$3)>0),--(('Rewards Dashboard'!$D$3="All")+('Employee Data'!$C$2:$C$493='Rewards Dashboard'!$D$3)>0),--(('Rewards Dashboard'!$F$3="All")+('Employee Data'!$D$2:$D$493='Rewards Dashboard'!$F$3)>0),--('Employee Data'!$D$2:$D$493=A57),--('Employee Data'!$E$2:$E$493=B57))/E57,0)} -> 0.25925926
A58: Sales | B58: Gurugram | C58: {=IFERROR(SUMPRODUCT('Employee Data'!$F$2:$F$493,--('Employee Data'!$A$2:$A$493<>""),--(('Rewards Dashboard'!$B$3="All")+('Employee Data'!$E$2:$E$493='Rewards Dashboard'!$B$3)>0),--(('Rewards Dashboard'!$D$3="All")+('Employee Data'!$C$2:$C$493='Rewards Dashboard'!$D$3)>0),--(('Rewards Dashboard'!$F$3="All")+('Employee Data'!$D$2:$D$493='Rewards Dashboard'!$F$3)>0),--('Employee Data'!$D$2:$D$493=A58),--('Employee Data'!$E$2:$E$493=B58))/SUMPRODUCT(--('Employee Data'!$A$2:$A$493<>""),--(('Rewards Dashboard'!$B$3="All")+('Employee Data'!$E$2:$E$493='Rewards Dashboard'!$B$3)>0),--(('Rewards Dashboard'!$D$3="All")+('Employee Data'!$C$2:$C$493='Rewards Dashboard'!$D$3)>0),--(('Rewards Dashboard'!$F$3="All")+('Employee Data'!$D$2:$D$493='Rewards Dashboard'!$F$3)>0),--('Employee Data'!$D$2:$D$493=A58),--('Employee Data'!$E$2:$E$493=B58)),0)} -> 134835.56 | D58: {=IFERROR(SUMPRODUCT('Employee Data'!$I$2:$I$493,--('Employee Data'!$A$2:$A$493<>""),--(('Rewards Dashboard'!$B$3="All")+('Employee Data'!$E$2:$E$493='Rewards Dashboard'!$B$3)>0),--(('Rewards Dashboard'!$D$3="All")+('Employee Data'!$C$2:$C$493='Rewards Dashboard'!$D$3)>0),--(('Rewards Dashboard'!$F$3="All")+('Employee Data'!$D$2:$D$493='Rewards Dashboard'!$F$3)>0),--('Employee Data'!$D$2:$D$493=A58),--('Employee Data'!$E$2:$E$493=B58))/SUMPRODUCT(--('Employee Data'!$A$2:$A$493<>""),--(('Rewards Dashboard'!$B$3="All")+('Employee Data'!$E$2:$E$493='Rewards Dashboard'!$B$3)>0),--(('Rewards Dashboard'!$D$3="All")+('Employee Data'!$C$2:$C$493='Rewards Dashboard'!$D$3)>0),--(('Rewards Dashboard'!$F$3="All")+('Employee Data'!$D$2:$D$493='Rewards Dashboard'!$F$3)>0),--('Employee Data'!$D$2:$D$493=A58),--('Employee Data'!$E$2:$E$493=B58)),0)} -> 6062 | E58: {=SUMPRODUCT(--('Employee Data'!$A$2:$A$493<>""),--(('Rewards Dashboard'!$B$3="All")+('Employee Data'!$E$2:$E$493='Rewards Dashboard'!$B$3)>0),--(('Rewards Dashboard'!$D$3="All")+('Employee Data'!$C$2:$C$493='Rewards Dashboard'!$D$3)>0),--(('Rewards Dashboard'!$F$3="All")+('Employee Data'!$D$2:$D$493='Rewards Dashboard'!$F$3)>0),--('Employee Data'!$D$2:$D$493=A58),--('Employee Data'!$E$2:$E$493=B58))} -> 25 | F58: {=IFERROR(SUMPRODUCT(--('Employee Data'!$I$2:$I$493>7000),--('Employee Data'!$A$2:$A$493<>""),--(('Rewards Dashboard'!$B$3="All")+('Employee Data'!$E$2:$E$493='Rewards Dashboard'!$B$3)>0),--(('Rewards Dashboard'!$D$3="All")+('Employee Data'!$C$2:$C$493='Rewards Dashboard'!$D$3)>0),--(('Rewards Dashboard'!$F$3="All")+('Employee Data'!$D$2:$D$493='Rewards Dashboard'!$F$3)>0),--('Employee Data'!$D$2:$D$493=A58),--('Employee Data'!$E$2:$E$493=B58))/E58,0)} -> 0.32
A59: Tech | B59: Gurugram | C59: {=IFERROR(SUMPRODUCT('Employee Data'!$F$2:$F$493,--('Employee Data'!$A$2:$A$493<>""),--(('Rewards Dashboard'!$B$3="All")+('Employee Data'!$E$2:$E$493='Rewards Dashboard'!$B$3)>0),--(('Rewards Dashboard'!$D$3="All")+('Employee Data'!$C$2:$C$493='Rewards Dashboard'!$D$3)>0),--(('Rewards Dashboard'!$F$3="All")+('Employee Data'!$D$2:$D$493='Rewards Dashboard'!$F$3)>0),--('Employee Data'!$D$2:$D$493=A59),--('Employee Data'!$E$2:$E$493=B59))/SUMPRODUCT(--('Employee Data'!$A$2:$A$493<>""),--(('Rewards Dashboard'!$B$3="All")+('Employee Data'!$E$2:$E$493='Rewards Dashboard'!$B$3)>0),--(('Rewards Dashboard'!$D$3="All")+('Employee Data'!$C$2:$C$493='Rewards Dashboard'!$D$3)>0),--(('Rewards Dashboard'!$F$3="All")+('Employee Data'!$D$2:$D$493='Rewards Dashboard'!$F$3)>0),--('Employee Data'!$D$2:$D$493=A59),--('Employee Data'!$E$2:$E$493=B59)),0)} -> 113808.76 | D59: {=IFERROR(SUMPRODUCT('Employee Data'!$I$2:$I$493,--('Employee Data'!$A$2:$A$493<>""),--(('Rewards Dashboard'!$B$3="All")+('Employee Data'!$E$2:$E$493='Rewards Dashboard'!$B$3)>0),--(('Rewards Dashboard'!$D$3="All")+('Employee Data'!$C$2:$C$493='Rewards Dashboard'!$D$3)>0),--(('Rewards Dashboard'!$F$3="All")+('Employee Data'!$D$2:$D$493='Rewards Dashboard'!$F$3)>0),--('Employee Data'!$D$2:$D$493=A59),--('Employee Data'!$E$2:$E$493=B59))/SUMPRODUCT(--('Employee Data'!$A$2:$A$493<>""),--(('Rewards Dashboard'!$B$3="All")+('Employee Data'!$E$2:$E$493='Rewards Dashboard'!$B$3)>0),--(('Rewards Dashboard'!$D$3="All")+('Employee Data'!$C$2:$C$493='Rewards Dashboard'!$D$3)>0),--(('Rewards Dashboard'!$F$3="All")+('Employee Data'!$D$2:$D$493='Rewards Dashboard'!$F$3)>0),--('Employee Data'!$D$2:$D$493=A59),--('Employee Data'!$E$2:$E$493=B59)),0)} -> 5066 | E59: {=SUMPRODUCT(--('Employee Data'!$A$2:$A$493<>""),--(('Rewards Dashboard'!$B$3="All")+('Employee Data'!$E$2:$E$493='Rewards Dashboard'!$B$3)>0),--(('Rewards Dashboard'!$D$3="All")+('Employee Data'!$C$2:$C$493='Rewards Dashboard'!$D$3)>0),--(('Rewards Dashboard'!$F$3="All")+('Employee Data'!$D$2:$D$493='Rewards Dashboard'!$F$3)>0),--('Employee Data'!$D$2:$D$493=A59),--('Employee Data'!$E$2:$E$493=B59))} -> 25 | F59: {=IFERROR(SUMPRODUCT(--('Employee Data'!$I$2:$I$493>7000),--('Employee Data'!$A$2:$A$493<>""),--(('Rewards Dashboard'!$B$3="All")+('Employee Data'!$E$2:$E$493='Rewards Dashboard'!$B$3)>0),--(('Rewards Dashboard'!$D$3="All")+('Employee Data'!$C$2:$C$493='Rewards Dashboard'!$D$3)>0),--(('Rewards Dashboard'!$F$3="All")+('Employee Data'!$D$2:$D$493='Rewards Dashboard'!$F$3)>0),--('Employee Data'!$D$2:$D$493=A59),--('Employee Data'!$E$2:$E$493=B59))/E59,0)} -> 0.2
A60: Finance | B60: Hyderabad | C60: {=IFERROR(SUMPRODUCT('Employee Data'!$F$2:$F$493,--('Employee Data'!$A$2:$A$493<>""),--(('Rewards Dashboard'!$B$3="All")+('Employee Data'!$E$2:$E$493='Rewards Dashboard'!$B$3)>0),--(('Rewards Dashboard'!$D$3="All")+('Employee Data'!$C$2:$C$493='Rewards Dashboard'!$D$3)>0),--(('Rewards Dashboard'!$F$3="All")+('Employee Data'!$D$2:$D$493='Rewards Dashboard'!$F$3)>0),--('Employee Data'!$D$2:$D$493=A60),--('Employee Data'!$E$2:$E$493=B60))/SUMPRODUCT(--('Employee Data'!$A$2:$A$493<>""),--(('Rewards Dashboard'!$B$3="All")+('Employee Data'!$E$2:$E$493='Rewards Dashboard'!$B$3)>0),--(('Rewards Dashboard'!$D$3="All")+('Employee Data'!$C$2:$C$493='Rewards Dashboard'!$D$3)>0),--(('Rewards Dashboard'!$F$3="All")+('Employee Data'!$D$2:$D$493='Rewards Dashboard'!$F$3)>0),--('Employee Data'!$D$2:$D$493=A60),--('Employee Data'!$E$2:$E$493=B60)),0)} -> 128885.24 | D60: {=IFERROR(SUMPRODUCT('Employee Data'!$I$2:$I$493,--('Employee Data'!$A$2:$A$493<>""),--(('Rewards Dashboard'!$B$3="All")+('Employee Data'!$E$2:$E$493='Rewards Dashboard'!$B$3)>0),--(('Rewards Dashboard'!$D$3="All")+('Employee Data'!$C$2:$C$493='Rewards Dashboard'!$D$3)>0),--(('Rewards Dashboard'!$F$3="All")+('Employee Data'!$D$2:$D$493='Rewards Dashboard'!$F$3)>0),--('Employee Data'!$D$2:$D$493=A60),--('Employee Data'!$E$2:$E$493=B60))/SUMPRODUCT(--('Employee Data'!$A$2:$A$493<>""),--(('Rewards Dashboard'!$B$3="All")+('Employee Data'!$E$2:$E$493='Rewards Dashboard'!$B$3)>0),--(('Rewards Dashboard'!$D$3="All")+('Employee Data'!$C$2:$C$493='Rewards Dashboard'!$D$3)>0),--(('Rewards Dashboard'!$F$3="All")+('Employee Data'!$D$2:$D$493='Rewards Dashboard'!$F$3)>0),--('Employee Data'!$D$2:$D$493=A60),--('Employee Data'!$E$2:$E$493=B60)),0)} -> 5944.8276 | E60: {=SUMPRODUCT(--('Employee Data'!$A$2:$A$493<>""),--(('Rewards Dashboard'!$B$3="All")+('Employee Data'!$E$2:$E$493='Rewards Dashboard'!$B$3)>0),--(('Rewards Dashboard'!$D$3="All")+('Employee Data'!$C$2:$C$493='Rewards Dashboard'!$D$3)>0),--(('Rewards Dashboard'!$F$3="All")+('Employee Data'!$D$2:$D$493='Rewards Dashboard'!$F$3)>0),--('Employee Data'!$D$2:$D$493=A60),--('Employee Data'!$E$2:$E$493=B60))} -> 29 | F60: {=IFERROR(SUMPRODUCT(--('Employee Data'!$I$2:$I$493>7000),--('Employee Data'!$A$2:$A$493<>""),--(('Rewards Dashboard'!$B$3="All")+('Employee Data'!$E$2:$E$493='Rewards Dashboard'!$B$3)>0),--(('Rewards Dashboard'!$D$3="All")+('Employee Data'!$C$2:$C$493='Rewards Dashboard'!$D$3)>0),--(('Rewards Dashboard'!$F$3="All")+('Employee Data'!$D$2:$D$493='Rewards Dashboard'!$F$3)>0),--('Employee Data'!$D$2:$D$493=A60),--('Employee Data'!$E$2:$E$493=B60))/E60,0)} -> 0.34482759
...

Sheet Basic Analysis
A1: Count of Department | B1: Column Labels | I1: Count of Department | J1: Column Labels | P1: Count of Insurance tier | Q1: Salary Band | W1: Max of Monthly Base Salary (INR) | X1: Column Labels
A2: Row Labels | B2: Finance | C2: HR | D2: Operations | E2: Sales | F2: Tech | G2: Grand Total | I2: Row Labels | J2: Bengaluru | K2: Gurugram | L2: Hyderabad | M2: Noida | N2: Grand Total | P2: Insurance Tier | Q2: Junior | R2: Lead | S2: Mid | T2: Senior | U2: Grand Total | W2: Row Labels | X2: Junior | Y2: Lead | Z2: Mid | AA2: Senior | AB2: Grand Total
A3: Junior | I3: Junior | P3: Bronze | Q3: 54 | R3: 2 | S3: 1 | T3: 2 | U3: 59 | W3: Finance | X3: 77431 | Y3: 230431 | Z3: 112943 | AA3: 151206 | AB3: 230431
A4: Female | B4: 7 | C4: 11 | D4: 14 | E4: 12 | F4: 11 | G4: 55 | I4: Female | J4: 13 | K4: 11 | L4: 21 | M4: 10 | N4: 55 | P4: Gold | R4: 122 | T4: 94 | U4: 216 | W4: HR | X4: 77592 | Y4: 226495 | Z4: 111621 | AA4: 152558 | AB4: 226495
A5: Male | B5: 12 | C5: 11 | D5: 13 | E5: 14 | F5: 18 | G5: 68 | I5: Male | J5: 16 | K5: 14 | L5: 16 | M5: 22 | N5: 68 | P5: Silver | Q5: 69 | S5: 122 | T5: 26 | U5: 217 | W5: Operations | X5: 77183 | Y5: 233542 | Z5: 112449 | AA5: 152788 | AB5: 233542
A6: Lead | I6: Lead | P6: Grand Total | Q6: 123 | R6: 124 | S6: 123 | T6: 122 | U6: 492 | W6: Sales | X6: 78895 | Y6: 230880 | Z6: 112838 | AA6: 152013 | AB6: 230880
A7: Female | B7: 8 | C7: 13 | D7: 12 | E7: 12 | F7: 6 | G7: 51 | I7: Female | J7: 17 | K7: 13 | L7: 12 | M7: 9 | N7: 51 | W7: Tech | X7: 78635 | Y7: 215780 | Z7: 111986 | AA7: 152988 | AB7: 215780
A8: Male | B8: 13 | C8: 9 | D8: 13 | E8: 18 | F8: 18 | G8: 71 | I8: Male | J8: 12 | K8: 18 | L8: 20 | M8: 21 | N8: 71 | P8: Max of Monthly Premiums | Q8: Column Labels | W8: Grand Total | X8: 78895 | Y8: 233542 | Z8: 112943 | AA8: 152988 | AB8: 233542
A9: Transgender | B9: 2 | G9: 2 | I9: Transgender | L9: 1 | M9: 1 | N9: 2 | P9: Row Labels | Q9: Junior | R9: Lead | S9: Mid | T9: Senior | U9: Grand Total
A10: Mid | I10: Mid | P10: Bronze | Q10: 1500 | R10: 9500 | S10: 9500 | T10: 9500 | U10: 9500 | W10: Min of Monthly Base Salary (INR) | X10: Column Labels
A11: Female | B11: 11 | C11: 11 | D11: 12 | E11: 16 | F11: 8 | G11: 58 | I11: Female | J11: 12 | K11: 11 | L11: 16 | M11: 19 | N11: 58 | P11: Gold | R11: 9000 | T11: 9000 | U11: 9000 | W11: Row Labels | X11: Junior | Y11: Lead | Z11: Mid | AA11: Senior | AB11: Grand Total
A12: Male | B12: 13 | C12: 16 | D12: 11 | E12: 13 | F12: 12 | G12: 65 | I12: Male | J12: 16 | K12: 21 | L12: 16 | M12: 12 | N12: 65 | P12: Silver | Q12: 4200 | S12: 4200 | T12: 4200 | U12: 4200 | W12: Finance | X12: 40601 | Y12: 156954 | Z12: 79394 | AA12: 113244 | AB12: 40601
A13: Senior | I13: Senior | P13: Grand Total | Q13: 4200 | R13: 9500 | S13: 9500 | T13: 9500 | U13: 9500 | W13: HR | X13: 45515 | Y13: 154178 | Z13: 81071 | AA13: 113535 | AB13: 45515
A14: Female | B14: 18 | C14: 8 | D14: 9 | E14: 15 | F14: 10 | G14: 60 | I14: Female | J14: 9 | K14: 21 | L14: 19 | M14: 11 | N14: 60 | W14: Operations | X14: 37393 | Y14: 155897 | Z14: 79993 | AA14: 114498 | AB14: 37393
A15: Male | B15: 13 | C15: 9 | D15: 13 | E15: 9 | F15: 17 | G15: 61 | I15: Male | J15: 14 | K15: 11 | L15: 19 | M15: 17 | N15: 61 | P15: Min of Monthly Premiums | Q15: Column Labels | W15: Sales | X15: 37078 | Y15: 159056 | Z15: 79153 | AA15: 117304 | AB15: 37078
A16: Transgender | F16: 1 | G16: 1 | I16: Transgender | J16: 1 | N16: 1 | P16: Row Labels | Q16: Junior | R16: Lead | S16: Mid | T16: Senior | U16: Grand Total | W16: Tech | X16: 38296 | Y16: 153444 | Z16: 79816 | AA16: 113887 | AB16: 38296
A17: Grand Total | B17: 97 | C17: 88 | D17: 97 | E17: 109 | F17: 101 | G17: 492 | I17: Grand Total | J17: 110 | K17: 120 | L17: 140 | M17: 122 | N17: 492 | P17: Bronze | Q17: 1500 | R17: 9500 | S17: 9500 | T17: 9500 | U17: 1500 | W17: Grand Total | X17: 37078 | Y17: 153444 | Z17: 79153 | AA17: 113244 | AB17: 37078
P18: Gold | R18: 6750 | T18: 6750 | U18: 6750
P19: Silver | Q19: 2800 | S19: 2800 | T19: 2800 | U19: 2800
A20: Insurance Tier | B20: Count of Insurance tier | P20: Grand Total | Q20: 1500 | R20: 6750 | S20: 2800 | T20: 2800 | U20: 1500
A21: Bronze | B21: 59
A22: Gold | B22: 216 | P22: Count of Monthly Premiums | Q22: Column Labels
A23: Silver | B23: 217 | P23: Row Labels | Q23: Junior | R23: Lead | S23: Mid | T23: Senior | U23: Grand Total
A24: Grand Total | B24: 492 | P24: Bronze
P25: Individual | Q25: 54 | U25: 54
P26: Parents Included | R26: 2 | S26: 1 | T26: 2 | U26: 5
P27: Gold
P28: Family Floater | R28: 59 | T28: 48 | U28: 107
P29: Parents Included | R29: 63 | T29: 46 | U29: 109
P30: Silver
P31: Family Floater | Q31: 35 | S31: 58 | T31: 8 | U31: 101
P32: Individual | Q32: 34 | S32: 64 | T32: 18 | U32: 116
P33: Grand Total | Q33: 123 | R33: 124 | S33: 123 | T33: 122 | U33: 492

Sheet Rewards & Benefits Allocation
A1: Row Labels | B1: Headcount | C1: Total Monthly Premium Cost | D1: Average Salary | E1: High-Cost Employee % | H1: Average of Monthly Premiums | I1: Locations
A2: Bengaluru | H2: Department | I2: Bengaluru | J2: Gurugram | K2: Hyderabad | L2: Noida | M2: Grand Total
A3: Finance | B3: 22 | C3: 108400 | D3: 115477.86 | E3: 0.18181818 | H3: Finance | I3: 4927.2727 | J3: 5190.9091 | K3: 5944.8276 | L3: 5785.4167 | M3: 5503.6082
A4: HR | B4: 19 | C4: 104300 | D4: 131595.95 | E4: 0.26315789 | H4: HR | I4: 5489.4737 | J4: 5064.2857 | K4: 4819.2308 | L4: 4577.2727 | M4: 4961.9318
A5: Operations | B5: 19 | C5: 79650 | D5: 102408.47 | E5: 0.21052632 | H5: Operations | I5: 4192.1053 | J5: 5490.7407 | K5: 5475 | L5: 5140 | M5: 5141.7526
A6: Sales | B6: 25 | C6: 135750 | D6: 125256.52 | E6: 0.2 | H6: Sales | I6: 5430 | J6: 6062 | K6: 5268.5714 | L6: 5293.75 | M6: 5493.1193
A7: Tech | B7: 25 | C7: 129350 | D7: 122661.32 | E7: 0.16 | H7: Tech | I7: 5174 | J7: 5066 | K7: 4591.6667 | L7: 5511.1111 | M7: 5099.0099
A8: Gurugram | H8: Grand Total | I8: 5067.7273 | J8: 5391.6667 | K8: 5247.5 | L8: 5277.8689 | M8: 5250
A9: Finance | B9: 22 | C9: 114200 | D9: 113401.59 | E9: 0.22727273
A10: HR | B10: 21 | C10: 106350 | D10: 117717.62 | E10: 0.19047619
A11: Operations | B11: 27 | C11: 148250 | D11: 117910.11 | E11: 0.25925926
A12: Sales | B12: 25 | C12: 151550 | D12: 134835.56 | E12: 0.32
A13: Tech | B13: 25 | C13: 126650 | D13: 113808.76 | E13: 0.2
A14: Hyderabad
A15: Finance | B15: 29 | C15: 172400 | D15: 128885.24 | E15: 0.34482759
A16: HR | B16: 26 | C16: 125300 | D16: 116479.5 | E16: 0.19230769
A17: Operations | B17: 26 | C17: 142350 | D17: 130724.81 | E17: 0.30769231
A18: Sales | B18: 35 | C18: 184400 | D18: 117752.26 | E18: 0.22857143
A19: Tech | B19: 24 | C19: 110200 | D19: 99810.75 | E19: 0.25
A20: Noida
A21: Finance | B21: 24 | C21: 138850 | D21: 126815 | E21: 0.25
A22: HR | B22: 22 | C22: 100700 | D22: 99674 | E22: 0.18181818
A23: Operations | B23: 25 | C23: 128500 | D23: 116921 | E23: 0.16
A24: Sales | B24: 24 | C24: 127050 | D24: 110101.08 | E24: 0.29166667
A25: Tech | B25: 27 | C25: 148800 | D25: 124199.26 | E25: 0.22222222
A26: Grand Total | B26: 492 | C26: 2583000 | D26: 118675.04 | E26: 0.23373984

Sheet Gender Pay Equity
A1: Gender Pay Gap | B1: Column Labels
A2: Row Labels | B2: Junior | C2: Lead | D2: Mid | E2: Senior | F2: Grand Total
A3: Finance | B3: 4285.9762 | C3: -6018.2308 | D3: 2288.6573 | E3: -2005.8419 | F3: -2435.8913
A4: HR | B4: -1292 | C4: 7213.8803 | D4: -5557.2955 | E4: -6347.6389 | F4: -9700.6636
A5: Operations | B5: 2094.3297 | C5: 13906.872 | D5: 1276.8788 | E5: 989.68376 | F5: 8769.1106
A6: Sales | B6: -5698.7619 | C6: -2950.1389 | D6: -4477.6538 | E6: -4772.1111 | F6: 1035.6825
A7: Tech | B7: -6402.2929 | C7: 3260.1667 | D7: -4871.0417 | E7: 5366.3 | F7: 8851.244
A8: Grand Total | B8: -2229.5479 | C8: 2672.5515 | D8: -2277.3732 | E8: -1553.5495 | F8: 1047.4824
A10: Average of Monthly Base Salary (INR) | B10: Column Labels | E10: Each band's gap is under 3% of that band's average, and the direction flips (women ahead in three bands, men ahead in one). This pattern is consistent with normal variation rather than a systematic gap — no band shows a one-sided, consistent disadvantage for either gender. | H10: Average of Monthly Base Salary (INR)
A11: Row Labels | B11: Female | C11: Male | D11: Gap (M-F) | H11: Salary Band | I11: Female | J11: Male | K11: Gap (M-F)
A12: Junior | B12: 62039.327 | C12: 59809.779 | D12: =B12-C12 -> 2229.5479 | H12: Junior | I12: 62039.327 | J12: 59809.779 | K12: 2229.5479
A13: Lead | B13: 184793.39 | C13: 187465.94 | D13: =B13-C13 -> -2672.5515 | H13: Lead | I13: 184793.39 | J13: 187465.94 | K13: -2672.5515
A14: Mid | B14: 95928.466 | C14: 93651.092 | D14: =B14-C14 -> 2277.3732 | H14: Mid | I14: 95928.466 | J14: 93651.092 | K14: 2277.3732
A15: Senior | B15: 132606.52 | C15: 131052.97 | D15: =B15-C15 -> 1553.5495 | H15: Senior | I15: 132606.52 | J15: 131052.97 | K15: 1553.5495
A16: Grand Total | B16: 117664.59 | C16: 118712.07 | D16: =B16-C16 -> -1047.4824 | H16: Grand Total | I16: 117664.59 | J16: 118712.07 | K16: -1047.4824
A18: Note: The Transgender group is too small for standalone statistical comparison and is excluded from the gender pay analysis below — noted here as a scope limitation, not an omission.

Sheet Vendor Map Data
A1: Internal Department | B1: Vendor Survey Job Code | C1: Vendor Global Group Name | D1: Industry Peer Segment
A2: Tech | B2: IN-TECH-04 | C2: High-Value Technical Core | D2: Technology / Energy
A3: Operations | B3: IN-OPS-02 | C3: Core Operations Specialist | D3: Industrial Operations
A4: Sales | B4: IN-SLS-01 | C4: Field Sales Execution | D4: Commercial & Retail
A5: Finance | B5: IN-FIN-03 | C5: Corporate Finance Core | D5: Shared Services
A6: HR | B6: IN-HR-02 | C6: Corporate Talent Admin | D6: Shared Services

Sheet Query_Audit_Exceptions
A1: Employee ID | B1: Full Name | C1: Gender | D1: Department | E1: Location | F1: Monthly Base Salary (INR) | G1: Corporate Benefit Plan | H1: Insurance tier | I1: Monthly Premiums | J1: Salary Bracket | K1: Salary Tier | L1: Vendor Survey Job Code | M1: Vendor Global Group Name

Sheet Employee Data
A1: Employee ID | B1: Full Name | C1: Gender | D1: Department | E1: Location | F1: Monthly Base Salary (INR) | G1: Corporate Benefit Plan | H1: Insurance tier | I1: Monthly Premiums | J1: Salary Bracket | K1: Salary Tier | L1: Vendor Survey Job Code | M1: Vendor Global Group Name | O1: Min | P1: =MIN(F:F) -> 37078 | Q1: Max | R1: =MAX(F:F) -> 233542
A2: Emp1085 | B2: Indira Joshi | C2: Male | D2: HR | E2: Gurugram | F2: 88815 | G2: Individual | H2: Silver | I2: 2800 | J2: Between 50k and 200k | K2: Mid | L2: IN-HR-02 | M2: Corporate Talent Admin | O2: Range of Salary | P2: =R1-P1 -> 196464
A3: Emp1307 | B3: Rajkumar Devi | C3: Male | D3: Finance | E3: Bengaluru | F3: 88549 | G3: Individual | H3: Silver | I3: 2800 | J3: Between 50k and 200k | K3: Mid | L3: IN-FIN-03 | M3: Corporate Finance Core | O3: IQR | P3: =_xlfn.QUARTILE.INC(Indian_Employee_Data[Monthly Base Salary (INR)],1) - _xlfn.QUARTILE.INC(Indian_Employee_Data[Monthly Base Salary (INR)],) -> 42010.5
A4: Emp1122 | B4: Renchamo Kikon | C4: Male | D4: Sales | E4: Hyderabad | F4: 87960 | G4: Individual | H4: Silver | I4: 2800 | J4: Between 50k and 200k | K4: Mid | L4: IN-SLS-01 | M4: Field Sales Execution | O4: Outlier check | P4: Lower bound | Q4: Upper Bound
A5: Emp1166 | B5: Sachin Verma | C5: Male | D5: Tech | E5: Gurugram | F5: 88290 | G5: Family Floater | H5: Silver | I5: 4200 | J5: Between 50k and 200k | K5: Mid | L5: IN-TECH-04 | M5: High-Value Technical Core | P5: =_xlfn.QUARTILE.INC(Indian_Employee_Data[Monthly Base Salary (INR)],1) - (1.5*$P$3) -> 16072.75 | Q5: =_xlfn.QUARTILE.INC(Indian_Employee_Data[Monthly Base Salary (INR)],3) - (1.5*$P$3) -> 90611.75
A6: Emp1330 | B6: Sngi Kharkongor | C6: Male | D6: HR | E6: Noida | F6: 92535 | G6: Family Floater | H6: Silver | I6: 4200 | J6: Between 50k and 200k | K6: Mid | L6: IN-HR-02 | M6: Corporate Talent Admin | P6: No Low Outliers | Q6: High Outliers Exist
A7: Emp1133 | B7: Subhalata Koloi | C7: Male | D7: Finance | E7: Bengaluru | F7: 90307 | G7: Family Floater | H7: Silver | I7: 4200 | J7: Between 50k and 200k | K7: Mid | L7: IN-FIN-03 | M7: Corporate Finance Core
A8: Emp1281 | B8: Chidambaram Reddy | C8: Male | D8: Tech | E8: Hyderabad | F8: 90352 | G8: Individual | H8: Silver | I8: 2800 | J8: Between 50k and 200k | K8: Mid | L8: IN-TECH-04 | M8: High-Value Technical Core
A9: Emp1194 | B9: Kersi Vakil | C9: Male | D9: Sales | E9: Noida | F9: 90477 | G9: Family Floater | H9: Silver | I9: 4200 | J9: Between 50k and 200k | K9: Mid | L9: IN-SLS-01 | M9: Field Sales Execution
A10: Emp1394 | B10: Aspi Contractor | C10: Male | D10: HR | E10: Gurugram | F10: 90691 | G10: Family Floater | H10: Silver | I10: 4200 | J10: Between 50k and 200k | K10: Mid | L10: IN-HR-02 | M10: Corporate Talent Admin
A11: Emp1180 | B11: Vanlalhruaii Khiangte | C11: Male | D11: Tech | E11: Noida | F11: 90723 | G11: Family Floater | H11: Silver | I11: 4200 | J11: Between 50k and 200k | K11: Mid | L11: IN-TECH-04 | M11: High-Value Technical Core
A12: Emp1063 | B12: Mark D'Souza | C12: Male | D12: Sales | E12: Gurugram | F12: 92631 | G12: Individual | H12: Silver | I12: 2800 | J12: Between 50k and 200k | K12: Mid | L12: IN-SLS-01 | M12: Field Sales Execution
A13: Emp1253 | B13: Kalpana Raman | C13: Male | D13: HR | E13: Gurugram | F13: 87831 | G13: Individual | H13: Silver | I13: 2800 | J13: Between 50k and 200k | K13: Mid | L13: IN-HR-02 | M13: Corporate Talent Admin
A14: Emp1323 | B14: Zubin Irani | C14: Male | D14: HR | E14: Bengaluru | F14: 83499 | G14: Individual | H14: Silver | I14: 2800 | J14: Between 50k and 200k | K14: Mid | L14: IN-HR-02 | M14: Corporate Talent Admin
A15: Emp1224 | B15: Gyati Yein | C15: Male | D15: Sales | E15: Hyderabad | F15: 81804 | G15: Individual | H15: Silver | I15: 2800 | J15: Between 50k and 200k | K15: Mid | L15: IN-SLS-01 | M15: Field Sales Execution
A16: Emp1492 | B16: Xavier Mondal | C16: Male | D16: Finance | E16: Hyderabad | F16: 83204 | G16: Individual | H16: Silver | I16: 2800 | J16: Between 50k and 200k | K16: Mid | L16: IN-FIN-03 | M16: Corporate Finance Core
